<robot name="onshape">
<link name="body">
<collision>
<origin xyz="-1.7347234759768070944e-18 -6.9388939039072283776e-18 2.6020852139652106416e-18" rpy="0 -0 2.0943951023931957067" />
<geometry>
<mesh filename="package:///motor.stl"/>
</geometry>
</collision>
<visual>
<origin xyz="-1.7347234759768070944e-18 -6.9388939039072283776e-18 2.6020852139652106416e-18" rpy="0 -0 2.0943951023931957067" />
<geometry>
<mesh filename="package:///motor.stl"/>
</geometry>
<material name="motor_material">
<color rgba="0.64705882352941179736 0.64705882352941179736 0.64705882352941179736 1.0"/>
</material>
</visual>
<collision>
<origin xyz="0 6.9388939039072283776e-18 0" rpy="0 -0 -2.0943951023931952626" />
<geometry>
<mesh filename="package:///motor.stl"/>
</geometry>
</collision>
<visual>
<origin xyz="0 6.9388939039072283776e-18 0" rpy="0 -0 -2.0943951023931952626" />
<geometry>
<mesh filename="package:///motor.stl"/>
</geometry>
<material name="motor_material">
<color rgba="0.64705882352941179736 0.64705882352941179736 0.64705882352941179736 1.0"/>
</material>
</visual>
<collision>
<origin xyz="0 0 0" rpy="0 -0 0" />
<geometry>
<mesh filename="package:///motor.stl"/>
</geometry>
</collision>
<visual>
<origin xyz="0 0 0" rpy="0 -0 0" />
<geometry>
<mesh filename="package:///motor.stl"/>
</geometry>
<material name="motor_material">
<color rgba="0.64705882352941179736 0.64705882352941179736 0.64705882352941179736 1.0"/>
</material>
</visual>
<collision>
<origin xyz="0 0 0" rpy="0 -0 0" />
<geometry>
<mesh filename="package:///plate.stl"/>
</geometry>
</collision>
<visual>
<origin xyz="0 0 0" rpy="0 -0 0" />
<geometry>
<mesh filename="package:///plate.stl"/>
</geometry>
<material name="plate_material">
<color rgba="0.68235294117647060652 0.33333333333333331483 0.73725490196078435901 1.0"/>
</material>
</visual>
<collision>
<origin xyz="0 0 0.022999999999999999611" rpy="0 -0 0" />
<geometry>
<mesh filename="package:///plate.stl"/>
</geometry>
</collision>
<visual>
<origin xyz="0 0 0.022999999999999999611" rpy="0 -0 0" />
<geometry>
<mesh filename="package:///plate.stl"/>
</geometry>
<material name="plate_material">
<color rgba="0.68235294117647060652 0.33333333333333331483 0.73725490196078435901 1.0"/>
</material>
</visual>
<inertial>
<origin xyz="0.00041313742631781947808 0.00023852500429690035727 0.0129603621972746684" rpy="0 0 0"/>
<mass value="0.55184045573988327327" />
<inertia ixx="0.00061573183967726478893" ixy="-4.5433878869427543235e-06"  ixz="-9.0368619367301650838e-09" iyy="0.00062097809211638342608" iyz="-5.2174346717752650079e-09" izz="0.0011894065910678657157" />
</inertial>
</link>

<link name="base">
<inertial>
<origin xyz="0 0 0" rpy="0 0 0" />
<mass value="1e-9" />
<inertia ixx="0" ixy="0" ixz="0" iyy="0" iyz="0" izz="0" />
</inertial>
</link>
<joint name="body_frame" type="fixed">
<origin xyz="0.0041869852016127150768 0.002417357033244084321 0.014499999999999997266" rpy="0 -0 0.52359877559829937077" />
<parent link="body" />
<child link="base" />
<axis xyz="0 0 0"/>
</joint>

<link name="wheel">
<collision>
<origin xyz="-1.0820518625265934609e-17 0.013000000000000001138 0.075000000000000011102" rpy="1.570796326794896558 1.0471975511965980754 0" />
<geometry>
<mesh filename="package:///wheel.stl"/>
</geometry>
</collision>
<visual>
<origin xyz="-1.0820518625265934609e-17 0.013000000000000001138 0.075000000000000011102" rpy="1.570796326794896558 1.0471975511965980754 0" />
<geometry>
<mesh filename="package:///wheel.stl"/>
</geometry>
<material name="wheel_material">
<color rgba="0.94117647058823528106 0.87450980392156862919 0.67843137254901964006 1.0"/>
</material>
</visual>
<inertial>
<origin xyz="-9.2850727106963404367e-11 -1.4381200032914653875e-09 -0.0025000000554400020336" rpy="0 0 0"/>
<mass value="0.01924908488748922411" />
<inertia ixx="6.8765144932724304568e-06" ixy="4.74141453805302909e-13"  ixz="-1.4288918118653907291e-14" iyy="6.8765142522306696936e-06" iyz="2.2762036673241546206e-14" izz="1.3673643547259725222e-05" />
</inertial>
</link>

<link name="passivewheel">
<!-- Shapes for passivewheel -->
<collision>
<origin xyz="-9.7144514654701199309e-20 1.3877787807814456755e-17 0.0019999999999999939701" rpy="3.141592653589793116 -2.7755575615628913511e-17 -2.7755575615628913511e-17" />
<geometry>
<cylinder length="0.0030000000000000000625" radius="0.0060000000000000001249" />
</geometry>
</collision>
<!-- Shapes for passivewheel -->
<visual>
<origin xyz="-9.7144514654701199309e-20 1.3877787807814456755e-17 0.0019999999999999939701" rpy="3.141592653589793116 -2.7755575615628913511e-17 -2.7755575615628913511e-17" />
<geometry>
<cylinder length="0.0030000000000000000625" radius="0.0060000000000000001249" />
</geometry>
<material name="passivewheel_material">
<color rgba="0.30196078431372547213 0.29019607843137257275 0.26274509803921569651 1.0"/>
</material>
</visual>
<inertial>
<origin xyz="-8.4000511047209577878e-20 1.3489002723506598987e-17 0.0019999999999999935364" rpy="0 0 0"/>
<mass value="0.0028590609658248017193" />
<inertia ixx="2.7747274432609138953e-08" ixy="-5.3024232598138370053e-71"  ixz="3.1490841707672236165e-24" iyy="2.7747274432609138953e-08" iyz="-2.1375722681956916097e-41" izz="4.8977394258054644615e-08" />
</inertial>
</link>

<joint name="w1_1_passive" type="revolute">
<origin xyz="-0.013490250321650828005 -0.035046585372318354856 -0.0025000000000000160982" rpy="1.570796326794896558 1.3942429024899487544 1.2566370614359179125" />
<parent link="wheel" />
<child link="passivewheel" />
<axis xyz="0 0 1"/>
<limit effort="1" velocity="20" />
<joint_properties friction="0.0"/>
</joint>

<link name="passivewheel_2">
<!-- Shapes for passivewheel -->
<collision>
<origin xyz="-1.3877787807814456755e-17 0 -0.0020000000000000026437" rpy="3.141592653589793116 5.5511151231257913303e-17 7.3955709864469856757e-32" />
<geometry>
<cylinder length="0.0030000000000000000625" radius="0.0060000000000000001249" />
</geometry>
</collision>
<!-- Shapes for passivewheel -->
<visual>
<origin xyz="-1.3877787807814456755e-17 0 -0.0020000000000000026437" rpy="3.141592653589793116 5.5511151231257913303e-17 7.3955709864469856757e-32" />
<geometry>
<cylinder length="0.0030000000000000000625" radius="0.0060000000000000001249" />
</geometry>
<material name="passivewheel_material">
<color rgba="0.30196078431372547213 0.29019607843137257275 0.26274509803921569651 1.0"/>
</material>
</visual>
<inertial>
<origin xyz="-1.3864643804206964592e-17 -3.8878508430785584243e-19 -0.0020000000000000030774" rpy="0 0 0"/>
<mass value="0.0028590609658248017193" />
<inertia ixx="2.7747274432609138953e-08" ixy="2.7360925032904852604e-39"  ixz="-1.5402831472837860559e-24" iyy="2.7747274432609138953e-08" iyz="-1.1391273354965187936e-55" izz="4.8977394258054644615e-08" />
</inertial>
</link>

<joint name="w1_2_passive" type="revolute">
<origin xyz="-0.0020000000000000039448 -0.037499999999999991673 -0.0025000000000000160982" rpy="3.1415926535897926719 1.570796326794896336 0" />
<parent link="wheel" />
<child link="passivewheel_2" />
<axis xyz="0 0 1"/>
<limit effort="1" velocity="20" />
<joint_properties friction="0.0"/>
</joint>

<link name="passivewheel_3">
<!-- Shapes for passivewheel -->
<collision>
<origin xyz="1.3877787807814456755e-17 0 0.0019999999999999931027" rpy="0 -1.3877787807814456755e-17 0" />
<geometry>
<cylinder length="0.0030000000000000000625" radius="0.0060000000000000001249" />
</geometry>
</collision>
<!-- Shapes for passivewheel -->
<visual>
<origin xyz="1.3877787807814456755e-17 0 0.0019999999999999931027" rpy="0 -1.3877787807814456755e-17 0" />
<geometry>
<cylinder length="0.0030000000000000000625" radius="0.0060000000000000001249" />
</geometry>
<material name="passivewheel_material">
<color rgba="0.30196078431372547213 0.29019607843137257275 0.26274509803921569651 1.0"/>
</material>
</visual>
<inertial>
<origin xyz="1.3890931811421947378e-17 3.8878508430785598687e-19 0.0019999999999999935364" rpy="0 0 0"/>
<mass value="0.0028590609658248017193" />
<inertia ixx="2.7747274432609138953e-08" ixy="-7.7014157364188999738e-25"  ixz="3.8507078682094490686e-25" iyy="2.7747274432609152187e-08" iyz="0" izz="4.8977394258054644615e-08" />
</inertial>
</link>

<joint name="w1_3_passive" type="revolute">
<origin xyz="0.009686024256470226676 -0.036282653349818151656 -0.0025000000000000022204" rpy="-1.5707963267948970021 1.3942429024899487544 -1.2566370614359163582" />
<parent link="wheel" />
<child link="passivewheel_3" />
<axis xyz="0 0 1"/>
<limit effort="1" velocity="20" />
<joint_properties friction="0.0"/>
</joint>

<link name="passivewheel_4">
<!-- Shapes for passivewheel -->
<collision>
<origin xyz="-1.3988810110276972508e-17 3.4694469519536141888e-18 -0.0020000000000000017764" rpy="3.141592653589793116 -0 2.7755575615628919674e-17" />
<geometry>
<cylinder length="0.0030000000000000000625" radius="0.0060000000000000001249" />
</geometry>
</collision>
<!-- Shapes for passivewheel -->
<visual>
<origin xyz="-1.3988810110276972508e-17 3.4694469519536141888e-18 -0.0020000000000000017764" rpy="3.141592653589793116 -0 2.7755575615628919674e-17" />
<geometry>
<cylinder length="0.0030000000000000000625" radius="0.0060000000000000001249" />
</geometry>
<material name="passivewheel_material">
<color rgba="0.30196078431372547213 0.29019607843137257275 0.26274509803921569651 1.0"/>
</material>
</visual>
<inertial>
<origin xyz="-1.3975666106669481886e-17 3.0806618676457579612e-18 -0.00200000000000000221" rpy="0 0 0"/>
<mass value="0.0028590609658248017193" />
<inertia ixx="2.7747274432609125718e-08" ixy="1.5402831472837796274e-24"  ixz="2.7187915395718101128e-24" iyy="2.7747274432609152187e-08" iyz="-1.5402831472837799948e-24" izz="4.8977394258054644615e-08" />
</inertial>
</link>

<joint name="w1_4_passive" type="revolute">
<origin xyz="0.020423912972217832945 -0.031513707793645477639 -0.0025000000000000022204" rpy="1.5707963267948961139 1.2436334312925148016 -0.94247779607693760173" />
<parent link="wheel" />
<child link="passivewheel_4" />
<axis xyz="0 0 1"/>
<limit effort="1" velocity="20" />
<joint_properties friction="0.0"/>
</joint>

<link name="passivewheel_5">
<!-- Shapes for passivewheel -->
<collision>
<origin xyz="-1.3711254354120683126e-17 2.6020852139652106416e-18 -0.001999999999999999608" rpy="3.141592653589793116 -0 0" />
<geometry>
<cylinder length="0.0030000000000000000625" radius="0.0060000000000000001249" />
</geometry>
</collision>
<!-- Shapes for passivewheel -->
<visual>
<origin xyz="-1.3711254354120683126e-17 2.6020852139652106416e-18 -0.001999999999999999608" rpy="3.141592653589793116 -0 0" />
<geometry>
<cylinder length="0.0030000000000000000625" radius="0.0060000000000000001249" />
</geometry>
<material name="passivewheel_material">
<color rgba="0.30196078431372547213 0.29019607843137257275 0.26274509803921569651 1.0"/>
</material>
</visual>
<inertial>
<origin xyz="-1.3698110350513190963e-17 2.2133001296573547992e-18 -0.0020000000000000000416" rpy="0 0 0"/>
<mass value="0.0028590609658248017193" />
<inertia ixx="2.7747274432609152187e-08" ixy="7.7014157364188981371e-25"  ixz="-4.0781873093577142508e-24" iyy="2.7747274432609138953e-08" iyz="0" izz="4.8977394258054618145e-08" />
</inertial>
</link>

<joint name="w1_5_passive" type="revolute">
<origin xyz="0.029162566784475572185 -0.023659980949717641929 -0.0025000000000000022204" rpy="1.5707963267948961139 1.1338247319171002037 -0.62831853071795851218" />
<parent link="wheel" />
<child link="passivewheel_5" />
<axis xyz="0 0 1"/>
<limit effort="1" velocity="20" />
<joint_properties friction="0.0"/>
</joint>

<link name="passivewheel_6">
<!-- Shapes for passivewheel -->
<collision>
<origin xyz="0 -8.6736173798840354721e-19 -0.0019999999999999978732" rpy="3.141592653589793116 -0 0" />
<geometry>
<cylinder length="0.0030000000000000000625" radius="0.0060000000000000001249" />
</geometry>
</collision>
<!-- Shapes for passivewheel -->
<visual>
<origin xyz="0 -8.6736173798840354721e-19 -0.0019999999999999978732" rpy="3.141592653589793116 -0 0" />
<geometry>
<cylinder length="0.0030000000000000000625" radius="0.0060000000000000001249" />
</geometry>
<material name="passivewheel_material">
<color rgba="0.30196078431372547213 0.29019607843137257275 0.26274509803921569651 1.0"/>
</material>
</visual>
<inertial>
<origin xyz="1.3144003607491675598e-20 -1.2561468222962595822e-18 -0.0019999999999999983069" rpy="0 0 0"/>
<mass value="0.0028590609658248017193" />
<inertia ixx="2.7747274432609138953e-08" ixy="0"  ixz="0" iyy="2.7747274432609132335e-08" iyz="0" izz="4.897739425805463138e-08" />
</inertial>
</link>

<joint name="w1_6_passive" type="revolute">
<origin xyz="0.035046585372318361795 -0.013490250321650838414 -0.0025000000000000160982" rpy="1.5707963267948958919 1.068649938797565202 -0.31415926535897914507" />
<parent link="wheel" />
<child link="passivewheel_6" />
<axis xyz="0 0 1"/>
<limit effort="1" velocity="20" />
<joint_properties friction="0.0"/>
</joint>

<link name="passivewheel_7">
<!-- Shapes for passivewheel -->
<collision>
<origin xyz="-1.9721522630525295546e-34 -1.7347234759768070944e-18 -0.0020000000000000000416" rpy="-3.9443045261050590271e-31 -9.8607613152626475676e-32 -2.4651903288145233369e-32" />
<geometry>
<cylinder length="0.0030000000000000000625" radius="0.0060000000000000001249" />
</geometry>
</collision>
<!-- Shapes for passivewheel -->
<visual>
<origin xyz="-1.9721522630525295546e-34 -1.7347234759768070944e-18 -0.0020000000000000000416" rpy="-3.9443045261050590271e-31 -9.8607613152626475676e-32 -2.4651903288145233369e-32" />
<geometry>
<cylinder length="0.0030000000000000000625" radius="0.0060000000000000001249" />
</geometry>
<material name="passivewheel_material">
<color rgba="0.30196078431372547213 0.29019607843137257275 0.26274509803921569651 1.0"/>
</material>
</visual>
<inertial>
<origin xyz="1.3144003607491478492e-20 -1.345938391668951252e-18 -0.001999999999999999608" rpy="0 0 0"/>
<mass value="0.0028590609658248017193" />
<inertia ixx="2.7747274432609138953e-08" ixy="1.1858925207528818512e-51"  ixz="-2.0934514429314363421e-39" iyy="2.7747274432609138953e-08" iyz="-1.0944370013161941042e-38" izz="4.8977394258054644615e-08" />
</inertial>
</link>

<joint name="w1_7_passive" type="revolute">
<origin xyz="0.03750000000000001249 -0.0020000000000000035111 -0.002500000000000029976" rpy="1.5707963267948961139 1.0471975511965985195 -1.3322676295501712824e-15" />
<parent link="wheel" />
<child link="passivewheel_7" />
<axis xyz="0 0 1"/>
<limit effort="1" velocity="20" />
<joint_properties friction="0.0"/>
</joint>

<link name="passivewheel_8">
<!-- Shapes for passivewheel -->
<collision>
<origin xyz="-1.3933298959045714632e-17 0 0.0019999999999999983069" rpy="3.141592653589793116 -0 6.9388939039072299184e-18" />
<geometry>
<cylinder length="0.0030000000000000000625" radius="0.0060000000000000001249" />
</geometry>
</collision>
<!-- Shapes for passivewheel -->
<visual>
<origin xyz="-1.3933298959045714632e-17 0 0.0019999999999999983069" rpy="3.141592653589793116 -0 6.9388939039072299184e-18" />
<geometry>
<cylinder length="0.0030000000000000000625" radius="0.0060000000000000001249" />
</geometry>
<material name="passivewheel_material">
<color rgba="0.30196078431372547213 0.29019607843137257275 0.26274509803921569651 1.0"/>
</material>
</visual>
<inertial>
<origin xyz="-1.3920154955438224009e-17 -3.8878508430785584243e-19 0.0019999999999999978732" rpy="0 0 0"/>
<mass value="0.0028590609658248017193" />
<inertia ixx="2.7747274432609132335e-08" ixy="1.9253539341047243047e-25"  ixz="1.3593957697859050564e-24" iyy="2.7747274432609138953e-08" iyz="0" izz="4.8977394258054644615e-08" />
</inertial>
</link>

<joint name="w1_8_passive" type="revolute">
<origin xyz="0.036282653349818151656 0.0096860242564702162676 -0.0025000000000000160982" rpy="-1.5707963267948972241 1.0686499387975658681 0.31415926535897825689" />
<parent link="wheel" />
<child link="passivewheel_8" />
<axis xyz="0 0 1"/>
<limit effort="1" velocity="20" />
<joint_properties friction="0.0"/>
</joint>

<link name="passivewheel_9">
<!-- Shapes for passivewheel -->
<collision>
<origin xyz="-5.5511151231257828177e-20 -2.2204460492503131271e-19 -0.0020000000000000035111" rpy="0 8.3266726846886740532e-17 0" />
<geometry>
<cylinder length="0.0030000000000000000625" radius="0.0060000000000000001249" />
</geometry>
</collision>
<!-- Shapes for passivewheel -->
<visual>
<origin xyz="-5.5511151231257828177e-20 -2.2204460492503131271e-19 -0.0020000000000000035111" rpy="0 8.3266726846886740532e-17 0" />
<geometry>
<cylinder length="0.0030000000000000000625" radius="0.0060000000000000001249" />
</geometry>
<material name="passivewheel_material">
<color rgba="0.30196078431372547213 0.29019607843137257275 0.26274509803921569651 1.0"/>
</material>
</visual>
<inertial>
<origin xyz="-4.2367147623766152578e-20 1.6674047938282448157e-19 -0.0020000000000000030774" rpy="0 0 0"/>
<mass value="0.0028590609658248017193" />
<inertia ixx="2.7747274432609138953e-08" ixy="7.7014157364188999738e-25"  ixz="-3.6698204907115746812e-24" iyy="2.7747274432609138953e-08" iyz="-5.4375830791436202255e-24" izz="4.8977394258054644615e-08" />
</inertial>
</link>

<joint name="w1_9_passive" type="revolute">
<origin xyz="0.031513707793645484578 0.020423912972217836415 -0.002500000000000029976" rpy="1.5707963267948958919 1.1338247319171008698 0.62831853071795773502" />
<parent link="wheel" />
<child link="passivewheel_9" />
<axis xyz="0 0 1"/>
<limit effort="1" velocity="20" />
<joint_properties friction="0.0"/>
</joint>

<link name="passivewheel_10">
<!-- Shapes for passivewheel -->
<collision>
<origin xyz="2.7533531010703882005e-17 2.8215277336762768377e-18 -0.0019999999999999978732" rpy="-3.141592653589793116 2.7755575615628907348e-17 0" />
<geometry>
<cylinder length="0.0030000000000000000625" radius="0.0060000000000000001249" />
</geometry>
</collision>
<!-- Shapes for passivewheel -->
<visual>
<origin xyz="2.7533531010703882005e-17 2.8215277336762768377e-18 -0.0019999999999999978732" rpy="-3.141592653589793116 2.7755575615628907348e-17 0" />
<geometry>
<cylinder length="0.0030000000000000000625" radius="0.0060000000000000001249" />
</geometry>
<material name="passivewheel_material">
<color rgba="0.30196078431372547213 0.29019607843137257275 0.26274509803921569651 1.0"/>
</material>
</visual>
<inertial>
<origin xyz="2.7546675014311369546e-17 2.4327426493684213804e-18 -0.0019999999999999983069" rpy="0 0 0"/>
<mass value="0.0028590609658248017193" />
<inertia ixx="2.7747274432609152187e-08" ixy="-7.7014157364189008922e-25"  ixz="4.6674415055017296771e-24" iyy="2.7747274432609138953e-08" iyz="-1.178508392288030118e-24" izz="4.897739425805463138e-08" />
</inertial>
</link>

<joint name="w1_10_passive" type="revolute">
<origin xyz="0.023659980949717641929 0.029162566784475561776 -0.0025000000000000022204" rpy="1.57079632679489678 1.2436334312925150236 0.94247779607693804582" />
<parent link="wheel" />
<child link="passivewheel_10" />
<axis xyz="0 0 1"/>
<limit effort="1" velocity="20" />
<joint_properties friction="0.0"/>
</joint>

<link name="passivewheel_11">
<!-- Shapes for passivewheel -->
<collision>
<origin xyz="1.3877787807814457044e-20 3.4694469519536141888e-18 -0.0019999999999999939701" rpy="3.141592653589793116 -3.4694469519536141888e-17 2.7755575615628913511e-17" />
<geometry>
<cylinder length="0.0030000000000000000625" radius="0.0060000000000000001249" />
</geometry>
</collision>
<!-- Shapes for passivewheel -->
<visual>
<origin xyz="1.3877787807814457044e-20 3.4694469519536141888e-18 -0.0019999999999999939701" rpy="3.141592653589793116 -3.4694469519536141888e-17 2.7755575615628913511e-17" />
<geometry>
<cylinder length="0.0030000000000000000625" radius="0.0060000000000000001249" />
</geometry>
<material name="passivewheel_material">
<color rgba="0.30196078431372547213 0.29019607843137257275 0.26274509803921569651 1.0"/>
</material>
</visual>
<inertial>
<origin xyz="2.7021791415306135652e-20 3.0806618676457579612e-18 -0.0019999999999999944038" rpy="0 0 0"/>
<mass value="0.0028590609658248017193" />
<inertia ixx="2.7747274432609138953e-08" ixy="7.7014157364188981371e-25"  ixz="6.2282802460588595713e-25" iyy="2.7747274432609138953e-08" iyz="2.6719653352446145121e-41" izz="4.8977394258054644615e-08" />
</inertial>
</link>

<joint name="w1_11_passive" type="revolute">
<origin xyz="0.013490250321650848822 0.035046585372318347917 -0.0025000000000000022204" rpy="1.5707963267948972241 1.3942429024899489765 1.2566370614359181346" />
<parent link="wheel" />
<child link="passivewheel_11" />
<axis xyz="0 0 1"/>
<limit effort="1" velocity="20" />
<joint_properties friction="0.0"/>
</joint>

<link name="passivewheel_12">
<!-- Shapes for passivewheel -->
<collision>
<origin xyz="2.7533531010703882005e-17 4.9303806576313238865e-35 -0.0020000000000000013427" rpy="-3.141592653589793116 2.6810927945557190439e-33 -6.1629758220391547298e-33" />
<geometry>
<cylinder length="0.0030000000000000000625" radius="0.0060000000000000001249" />
</geometry>
</collision>
<!-- Shapes for passivewheel -->
<visual>
<origin xyz="2.7533531010703882005e-17 4.9303806576313238865e-35 -0.0020000000000000013427" rpy="-3.141592653589793116 2.6810927945557190439e-33 -6.1629758220391547298e-33" />
<geometry>
<cylinder length="0.0030000000000000000625" radius="0.0060000000000000001249" />
</geometry>
<material name="passivewheel_material">
<color rgba="0.30196078431372547213 0.29019607843137257275 0.26274509803921569651 1.0"/>
</material>
</visual>
<inertial>
<origin xyz="2.7546675014311369546e-17 -3.8878508430785574613e-19 -0.0020000000000000017764" rpy="0 0 0"/>
<mass value="0.0028590609658248017193" />
<inertia ixx="2.7747274432609138953e-08" ixy="-1.7100578145565547151e-40"  ixz="5.4375830791436187561e-24" iyy="2.7747274432609138953e-08" iyz="-8.6537442364416957994e-40" izz="4.897739425805463138e-08" />
</inertial>
</link>

<joint name="w1_12_passive" type="revolute">
<origin xyz="0.0020000000000000204246 0.037499999999999991673 -0.0025000000000000160982" rpy="1.4808442108026812057e-16 1.570796326794896558 0" />
<parent link="wheel" />
<child link="passivewheel_12" />
<axis xyz="0 0 1"/>
<limit effort="1" velocity="20" />
<joint_properties friction="0.0"/>
</joint>

<link name="passivewheel_13">
<!-- Shapes for passivewheel -->
<collision>
<origin xyz="4.1633363423443371133e-20 0 -0.0020000000000000030774" rpy="3.141592653589793116 8.3266726846886740532e-17 2.7755575615628913511e-17" />
<geometry>
<cylinder length="0.0030000000000000000625" radius="0.0060000000000000001249" />
</geometry>
</collision>
<!-- Shapes for passivewheel -->
<visual>
<origin xyz="4.1633363423443371133e-20 0 -0.0020000000000000030774" rpy="3.141592653589793116 8.3266726846886740532e-17 2.7755575615628913511e-17" />
<geometry>
<cylinder length="0.0030000000000000000625" radius="0.0060000000000000001249" />
</geometry>
<material name="passivewheel_material">
<color rgba="0.30196078431372547213 0.29019607843137257275 0.26274509803921569651 1.0"/>
</material>
</visual>
<inertial>
<origin xyz="5.4777367030935064787e-20 -3.8878508430785584243e-19 -0.0020000000000000035111" rpy="0 0 0"/>
<mass value="0.0028590609658248017193" />
<inertia ixx="2.7747274432609138953e-08" ixy="7.7014157364188981371e-25"  ixz="-3.3299715482650983712e-24" iyy="2.7747274432609138953e-08" iyz="-6.412716804587074829e-41" izz="4.8977394258054644615e-08" />
</inertial>
</link>

<joint name="w1_13_passive" type="revolute">
<origin xyz="-0.0096860242564702023899 0.036282653349818144717 -0.0025000000000000160982" rpy="-1.5707963267948970021 1.3942429024899489765 -1.2566370614359185787" />
<parent link="wheel" />
<child link="passivewheel_13" />
<axis xyz="0 0 1"/>
<limit effort="1" velocity="20" />
<joint_properties friction="0.0"/>
</joint>

<link name="passivewheel_14">
<!-- Shapes for passivewheel -->
<collision>
<origin xyz="5.5511151231257828177e-20 -6.7168492989821968723e-18 -0.0020000000000000074142" rpy="5.5511151231257839347e-17 1.3877787807814456755e-16 2.7755575615628913511e-17" />
<geometry>
<cylinder length="0.0030000000000000000625" radius="0.0060000000000000001249" />
</geometry>
</collision>
<!-- Shapes for passivewheel -->
<visual>
<origin xyz="5.5511151231257828177e-20 -6.7168492989821968723e-18 -0.0020000000000000074142" rpy="5.5511151231257839347e-17 1.3877787807814456755e-16 2.7755575615628913511e-17" />
<geometry>
<cylinder length="0.0030000000000000000625" radius="0.0060000000000000001249" />
</geometry>
<material name="passivewheel_material">
<color rgba="0.30196078431372547213 0.29019607843137257275 0.26274509803921569651 1.0"/>
</material>
</visual>
<inertial>
<origin xyz="6.8655154838749521831e-20 -6.3280642146743406447e-18 -0.0020000000000000069805" rpy="0 0 0"/>
<mass value="0.0028590609658248017193" />
<inertia ixx="2.7747274432609138953e-08" ixy="1.5402831472837798111e-24"  ixz="-2.4913120984235441959e-24" iyy="2.7747274432609138953e-08" iyz="6.9778662264273991182e-24" izz="4.897739425805463138e-08" />
</inertial>
</link>

<joint name="w1_14_passive" type="revolute">
<origin xyz="-0.020423912972217815598 0.031513707793645470701 -0.0025000000000000160982" rpy="-1.5707963267948970021 1.2436334312925148016 -0.94247779607693882298" />
<parent link="wheel" />
<child link="passivewheel_14" />
<axis xyz="0 0 1"/>
<limit effort="1" velocity="20" />
<joint_properties friction="0.0"/>
</joint>

<link name="passivewheel_15">
<!-- Shapes for passivewheel -->
<collision>
<origin xyz="5.5511151231257828177e-20 0 -0.0020000000000000004753" rpy="5.5511151231257839347e-17 -0 0" />
<geometry>
<cylinder length="0.0030000000000000000625" radius="0.0060000000000000001249" />
</geometry>
</collision>
<!-- Shapes for passivewheel -->
<visual>
<origin xyz="5.5511151231257828177e-20 0 -0.0020000000000000004753" rpy="5.5511151231257839347e-17 -0 0" />
<geometry>
<cylinder length="0.0030000000000000000625" radius="0.0060000000000000001249" />
</geometry>
<material name="passivewheel_material">
<color rgba="0.30196078431372547213 0.29019607843137257275 0.26274509803921569651 1.0"/>
</material>
</visual>
<inertial>
<origin xyz="6.8655154838749533868e-20 3.8878508430785584243e-19 -0.0020000000000000000416" rpy="0 0 0"/>
<mass value="0.0028590609658248017193" />
<inertia ixx="2.7747274432609152187e-08" ixy="7.7014157364188981371e-25"  ixz="1.3593957697859048727e-24" iyy="2.7747274432609138953e-08" iyz="1.5402831472837796274e-24" izz="4.897739425805463138e-08" />
</inertial>
</link>

<joint name="w1_15_passive" type="revolute">
<origin xyz="-0.029162566784475561776 0.023659980949717641929 -0.0025000000000000160982" rpy="-1.570796326794896558 1.1338247319171002037 -0.62831853071795873422" />
<parent link="wheel" />
<child link="passivewheel_15" />
<axis xyz="0 0 1"/>
<limit effort="1" velocity="20" />
<joint_properties friction="0.0"/>
</joint>

<link name="passivewheel_16">
<!-- Shapes for passivewheel -->
<collision>
<origin xyz="6.9388939039072283776e-18 -1.365574320288942525e-17 -0.0020000000000000017764" rpy="0 2.7755575615628913511e-17 -6.9388939039072283776e-18" />
<geometry>
<cylinder length="0.0030000000000000000625" radius="0.0060000000000000001249" />
</geometry>
</collision>
<!-- Shapes for passivewheel -->
<visual>
<origin xyz="6.9388939039072283776e-18 -1.365574320288942525e-17 -0.0020000000000000017764" rpy="0 2.7755575615628913511e-17 -6.9388939039072283776e-18" />
<geometry>
<cylinder length="0.0030000000000000000625" radius="0.0060000000000000001249" />
</geometry>
<material name="passivewheel_material">
<color rgba="0.30196078431372547213 0.29019607843137257275 0.26274509803921569651 1.0"/>
</material>
</visual>
<inertial>
<origin xyz="6.9520379075147205407e-18 -1.3266958118581567482e-17 -0.0020000000000000013427" rpy="0 0 0"/>
<mass value="0.0028590609658248017193" />
<inertia ixx="2.7747274432609138953e-08" ixy="-1.9253539341047245343e-25"  ixz="-7.7014157364188981371e-25" iyy="2.7747274432609132335e-08" iyz="5.4375830791436202255e-24" izz="4.8977394258054644615e-08" />
</inertial>
</link>

<joint name="w1_16_passive" type="revolute">
<origin xyz="-0.035046585372318347917 0.013490250321650843618 -0.0025000000000000160982" rpy="-1.57079632679489678 1.068649938797565202 -0.31415926535897920058" />
<parent link="wheel" />
<child link="passivewheel_16" />
<axis xyz="0 0 1"/>
<limit effort="1" velocity="20" />
<joint_properties friction="0.0"/>
</joint>

<link name="passivewheel_17">
<!-- Shapes for passivewheel -->
<collision>
<origin xyz="0 1.3877787807814456755e-17 0.0020000000000000000416" rpy="-3.141592653589793116 -0 -4.622231866529037618e-33" />
<geometry>
<cylinder length="0.0030000000000000000625" radius="0.0060000000000000001249" />
</geometry>
</collision>
<!-- Shapes for passivewheel -->
<visual>
<origin xyz="0 1.3877787807814456755e-17 0.0020000000000000000416" rpy="-3.141592653589793116 -0 -4.622231866529037618e-33" />
<geometry>
<cylinder length="0.0030000000000000000625" radius="0.0060000000000000001249" />
</geometry>
<material name="passivewheel_material">
<color rgba="0.30196078431372547213 0.29019607843137257275 0.26274509803921569651 1.0"/>
</material>
</visual>
<inertial>
<origin xyz="1.3144003607491675598e-20 1.3489002723506598987e-17 0.001999999999999999608" rpy="0 0 0"/>
<mass value="0.0028590609658248017193" />
<inertia ixx="2.7747274432609138953e-08" ixy="3.4201156291132949936e-40"  ixz="2.3185898923883018276e-71" iyy="2.7747274432609138953e-08" iyz="1.3680462516452426302e-39" izz="4.8977394258054644615e-08" />
</inertial>
</link>

<joint name="w1_17_passive" type="revolute">
<origin xyz="-0.037499999999999977796 0.00200000000000001045 -0.0025000000000000160982" rpy="1.570796326794896558 1.0471975511965980754 -1.1102230246251671407e-16" />
<parent link="wheel" />
<child link="passivewheel_17" />
<axis xyz="0 0 1"/>
<limit effort="1" velocity="20" />
<joint_properties friction="0.0"/>
</joint>

<link name="passivewheel_18">
<!-- Shapes for passivewheel -->
<collision>
<origin xyz="6.9388939039072283776e-18 0 -0.0019999999999999987406" rpy="3.141592653589793116 2.7755575615628919674e-17 0" />
<geometry>
<cylinder length="0.0030000000000000000625" radius="0.0060000000000000001249" />
</geometry>
</collision>
<!-- Shapes for passivewheel -->
<visual>
<origin xyz="6.9388939039072283776e-18 0 -0.0019999999999999987406" rpy="3.141592653589793116 2.7755575615628919674e-17 0" />
<geometry>
<cylinder length="0.0030000000000000000625" radius="0.0060000000000000001249" />
</geometry>
<material name="passivewheel_material">
<color rgba="0.30196078431372547213 0.29019607843137257275 0.26274509803921569651 1.0"/>
</material>
</visual>
<inertial>
<origin xyz="6.9520379075147205407e-18 -3.8878508430785574613e-19 -0.0019999999999999991743" rpy="0 0 0"/>
<mass value="0.0028590609658248017193" />
<inertia ixx="2.7747274432609132335e-08" ixy="0"  ixz="-7.7014157364188972188e-25" iyy="2.7747274432609132335e-08" iyz="0" izz="4.8977394258054671085e-08" />
</inertial>
</link>

<joint name="w1_18_passive" type="revolute">
<origin xyz="-0.036282653349818130839 -0.0096860242564702127982 -0.0024999999999999883427" rpy="-1.5707963267948938935 1.0686499387975656461 0.31415926535897814587" />
<parent link="wheel" />
<child link="passivewheel_18" />
<axis xyz="0 0 1"/>
<limit effort="1" velocity="20" />
<joint_properties friction="0.0"/>
</joint>

<link name="passivewheel_19">
<!-- Shapes for passivewheel -->
<collision>
<origin xyz="6.8833827526759705013e-18 -1.1102230246251565635e-19 -0.0019999999999999931027" rpy="-3.141592653589793116 -0 -2.7755575615628913511e-17" />
<geometry>
<cylinder length="0.0030000000000000000625" radius="0.0060000000000000001249" />
</geometry>
</collision>
<!-- Shapes for passivewheel -->
<visual>
<origin xyz="6.8833827526759705013e-18 -1.1102230246251565635e-19 -0.0019999999999999931027" rpy="-3.141592653589793116 -0 -2.7755575615628913511e-17" />
<geometry>
<cylinder length="0.0030000000000000000625" radius="0.0060000000000000001249" />
</geometry>
<material name="passivewheel_material">
<color rgba="0.30196078431372547213 0.29019607843137257275 0.26274509803921569651 1.0"/>
</material>
</visual>
<inertial>
<origin xyz="6.8965267562834626644e-18 -4.9980738677037159508e-19 -0.0019999999999999935364" rpy="0 0 0"/>
<mass value="0.0028590609658248017193" />
<inertia ixx="2.7747274432609138953e-08" ixy="2.5913261647569995835e-40"  ixz="1.3593957697859050564e-24" iyy="2.7747274432609152187e-08" iyz="4.2590746868555901075e-24" izz="4.8977394258054644615e-08" />
</inertial>
</link>

<joint name="w1_19_passive" type="revolute">
<origin xyz="-0.031513707793645470701 -0.020423912972217829476 -0.0025000000000000160982" rpy="-1.5707963267948938935 1.1338247319171006477 0.62831853071795706889" />
<parent link="wheel" />
<child link="passivewheel_19" />
<axis xyz="0 0 1"/>
<limit effort="1" velocity="20" />
<joint_properties friction="0.0"/>
</joint>

<link name="passivewheel_20">
<!-- Shapes for passivewheel -->
<collision>
<origin xyz="-5.5511151231257828177e-20 -2.2204460492503131271e-19 -0.0019999999999999974395" rpy="3.141592653589793116 -2.7755575615628913511e-17 0" />
<geometry>
<cylinder length="0.0030000000000000000625" radius="0.0060000000000000001249" />
</geometry>
</collision>
<!-- Shapes for passivewheel -->
<visual>
<origin xyz="-5.5511151231257828177e-20 -2.2204460492503131271e-19 -0.0019999999999999974395" rpy="3.141592653589793116 -2.7755575615628913511e-17 0" />
<geometry>
<cylinder length="0.0030000000000000000625" radius="0.0060000000000000001249" />
</geometry>
<material name="passivewheel_material">
<color rgba="0.30196078431372547213 0.29019607843137257275 0.26274509803921569651 1.0"/>
</material>
</visual>
<inertial>
<origin xyz="-4.2367147623766152578e-20 -6.1082968923288715513e-19 -0.0019999999999999978732" rpy="0 0 0"/>
<mass value="0.0028590609658248017193" />
<inertia ixx="2.7747274432609138953e-08" ixy="-7.7014157364188963004e-25"  ixz="2.1295373434277950538e-24" iyy="2.7747274432609138953e-08" iyz="5.4375830791436202255e-24" izz="4.8977394258054644615e-08" />
</inertial>
</link>

<joint name="w1_20_passive" type="revolute">
<origin xyz="-0.023659980949717652338 -0.029162566784475575654 -0.0025000000000000160982" rpy="-1.5707963267948930053 1.2436334312925152457 0.94247779607693582538" />
<parent link="wheel" />
<child link="passivewheel_20" />
<axis xyz="0 0 1"/>
<limit effort="1" velocity="20" />
<joint_properties friction="0.0"/>
</joint>

<joint name="wheel_1" type="revolute">
<origin xyz="0.069282032302755147679 -0.039999999999999986955 0.012999999999999999403" rpy="-1.570796326794896558 -0 1.0471975511965980754" />
<parent link="body" />
<child link="wheel" />
<axis xyz="0 0 1"/>
<limit effort="1" velocity="20" />
<joint_properties friction="0.0"/>
</joint>

<link name="wheel_2">
<collision>
<origin xyz="-3.9486462178061634448e-17 -0.013000000000000001138 -0.079999999999999987788" rpy="-1.570796326794896558 -1.0471975511965978534 0" />
<geometry>
<mesh filename="package:///wheel.stl"/>
</geometry>
</collision>
<visual>
<origin xyz="-3.9486462178061634448e-17 -0.013000000000000001138 -0.079999999999999987788" rpy="-1.570796326794896558 -1.0471975511965978534 0" />
<geometry>
<mesh filename="package:///wheel.stl"/>
</geometry>
<material name="wheel_material">
<color rgba="0.94117647058823528106 0.87450980392156862919 0.67843137254901964006 1.0"/>
</material>
</visual>
<inertial>
<origin xyz="-9.2850740984751212181e-11 1.4381200032914653875e-09 -0.0024999999445599815906" rpy="0 0 0"/>
<mass value="0.01924908488748922411" />
<inertia ixx="6.8765144932724296098e-06" ixy="-4.74141453805302909e-13"  ixz="1.42889198127198018e-14" iyy="6.8765142522306696936e-06" iyz="2.2762036673241546206e-14" izz="1.3673643547259721834e-05" />
</inertial>
</link>

<link name="passivewheel_21">
<!-- Shapes for passivewheel -->
<collision>
<origin xyz="1.3850032232198827817e-17 1.1102230246251565635e-19 0.0020000000000000039448" rpy="3.141592653589793116 4.1633363423443370266e-17 -2.7755575615628913511e-17" />
<geometry>
<cylinder length="0.0030000000000000000625" radius="0.0060000000000000001249" />
</geometry>
</collision>
<!-- Shapes for passivewheel -->
<visual>
<origin xyz="1.3850032232198827817e-17 1.1102230246251565635e-19 0.0020000000000000039448" rpy="3.141592653589793116 4.1633363423443370266e-17 -2.7755575615628913511e-17" />
<geometry>
<cylinder length="0.0030000000000000000625" radius="0.0060000000000000001249" />
</geometry>
<material name="passivewheel_material">
<color rgba="0.30196078431372547213 0.29019607843137257275 0.26274509803921569651 1.0"/>
</material>
</visual>
<inertial>
<origin xyz="1.386317623580631998e-17 -2.7776278184534008978e-19 0.0020000000000000035111" rpy="0 0 0"/>
<mass value="0.0028590609658248017193" />
<inertia ixx="2.7747274432609138953e-08" ixy="-7.7014157364188981371e-25"  ixz="-4.7551447556988228421e-25" iyy="2.7747274432609132335e-08" iyz="-2.7187915395718097454e-24" izz="4.897739425805463138e-08" />
</inertial>
</link>

<joint name="w3_1_passive" type="revolute">
<origin xyz="-0.013490250321650838414 0.035046585372318354856 -0.0024999999999999605871" rpy="1.570796326794896336 -1.3942429024899474221 1.8849555921538712067" />
<parent link="wheel_2" />
<child link="passivewheel_21" />
<axis xyz="0 0 1"/>
<limit effort="1" velocity="20" />
<joint_properties friction="0.0"/>
</joint>

<link name="passivewheel_22">
<!-- Shapes for passivewheel -->
<collision>
<origin xyz="-9.3987885136122752564e-50 -2.6274346206090320627e-49 -0.0020000000000000017764" rpy="3.141592653589793116 -2.1561582527688154085e-31 0" />
<geometry>
<cylinder length="0.0030000000000000000625" radius="0.0060000000000000001249" />
</geometry>
</collision>
<!-- Shapes for passivewheel -->
<visual>
<origin xyz="-9.3987885136122752564e-50 -2.6274346206090320627e-49 -0.0020000000000000017764" rpy="3.141592653589793116 -2.1561582527688154085e-31 0" />
<geometry>
<cylinder length="0.0030000000000000000625" radius="0.0060000000000000001249" />
</geometry>
<material name="passivewheel_material">
<color rgba="0.30196078431372547213 0.29019607843137257275 0.26274509803921569651 1.0"/>
</material>
</visual>
<inertial>
<origin xyz="1.3144003607491675598e-20 -3.8878508430785584243e-19 -0.00200000000000000221" rpy="0 0 0"/>
<mass value="0.0028590609658248017193" />
<inertia ixx="2.7747274432609138953e-08" ixy="-2.7360925032904852604e-39"  ixz="5.9827514759711366955e-39" iyy="2.7747274432609138953e-08" iyz="6.4342450650415391044e-54" izz="4.8977394258054644615e-08" />
</inertial>
</link>

<joint name="w3_2_passive" type="revolute">
<origin xyz="-0.0020000000000000134857 0.037499999999999991673 -0.0024999999999999605871" rpy="9.8607613152626344305e-32 -1.570796326794896336 0" />
<parent link="wheel_2" />
<child link="passivewheel_22" />
<axis xyz="0 0 1"/>
<limit effort="1" velocity="20" />
<joint_properties friction="0.0"/>
</joint>

<link name="passivewheel_23">
<!-- Shapes for passivewheel -->
<collision>
<origin xyz="-3.3306690738754696906e-19 6.9388939039072283776e-18 0.0020000000000000013427" rpy="0 -4.1633363423443370266e-17 -5.5511151231257827021e-17" />
<geometry>
<cylinder length="0.0030000000000000000625" radius="0.0060000000000000001249" />
</geometry>
</collision>
<!-- Shapes for passivewheel -->
<visual>
<origin xyz="-3.3306690738754696906e-19 6.9388939039072283776e-18 0.0020000000000000013427" rpy="0 -4.1633363423443370266e-17 -5.5511151231257827021e-17" />
<geometry>
<cylinder length="0.0030000000000000000625" radius="0.0060000000000000001249" />
</geometry>
<material name="passivewheel_material">
<color rgba="0.30196078431372547213 0.29019607843137257275 0.26274509803921569651 1.0"/>
</material>
</visual>
<inertial>
<origin xyz="-3.1992290378005538374e-19 7.3276789882150846053e-18 0.0020000000000000017764" rpy="0 0 0"/>
<mass value="0.0028590609658248017193" />
<inertia ixx="2.7747274432609138953e-08" ixy="-7.7014157364188981371e-25"  ixz="-7.0011622582525930463e-24" iyy="2.7747274432609138953e-08" iyz="-6.412716804587074829e-41" izz="4.897739425805463138e-08" />
</inertial>
</link>

<joint name="w3_3_passive" type="revolute">
<origin xyz="0.0096860242564702232065 0.036282653349818151656 -0.0024999999999999744649" rpy="-1.5707963267948958919 -1.3942429024899476442 -1.8849555921538694303" />
<parent link="wheel_2" />
<child link="passivewheel_23" />
<axis xyz="0 0 1"/>
<limit effort="1" velocity="20" />
<joint_properties friction="0.0"/>
</joint>

<link name="passivewheel_24">
<!-- Shapes for passivewheel -->
<collision>
<origin xyz="0 3.3584246494910984362e-18 -0.0019999999999999948375" rpy="3.141592653589793116 -0 -2.7755575615628919674e-17" />
<geometry>
<cylinder length="0.0030000000000000000625" radius="0.0060000000000000001249" />
</geometry>
</collision>
<!-- Shapes for passivewheel -->
<visual>
<origin xyz="0 3.3584246494910984362e-18 -0.0019999999999999948375" rpy="3.141592653589793116 -0 -2.7755575615628919674e-17" />
<geometry>
<cylinder length="0.0030000000000000000625" radius="0.0060000000000000001249" />
</geometry>
<material name="passivewheel_material">
<color rgba="0.30196078431372547213 0.29019607843137257275 0.26274509803921569651 1.0"/>
</material>
</visual>
<inertial>
<origin xyz="1.3144003607491674094e-20 2.9696395651832422086e-18 -0.0019999999999999952711" rpy="0 0 0"/>
<mass value="0.0028590609658248017193" />
<inertia ixx="2.7747274432609132335e-08" ixy="-7.7014157364188972188e-25"  ixz="0" iyy="2.7747274432609138953e-08" iyz="2.7187915395718101128e-24" izz="4.8977394258054644615e-08" />
</inertial>
</link>

<joint name="w3_4_passive" type="revolute">
<origin xyz="0.020423912972217819067 0.031513707793645477639 -0.0024999999999999605871" rpy="1.570796326794896336 -1.2436334312925134693 -2.1991148575128427467" />
<parent link="wheel_2" />
<child link="passivewheel_24" />
<axis xyz="0 0 1"/>
<limit effort="1" velocity="20" />
<joint_properties friction="0.0"/>
</joint>

<link name="passivewheel_25">
<!-- Shapes for passivewheel -->
<collision>
<origin xyz="-5.5511151231257828177e-20 -7.5633943552588789085e-19 -0.0020000000000000017764" rpy="3.141592653589793116 -0 -2.7755575615628913511e-17" />
<geometry>
<cylinder length="0.0030000000000000000625" radius="0.0060000000000000001249" />
</geometry>
</collision>
<!-- Shapes for passivewheel -->
<visual>
<origin xyz="-5.5511151231257828177e-20 -7.5633943552588789085e-19 -0.0020000000000000017764" rpy="3.141592653589793116 -0 -2.7755575615628913511e-17" />
<geometry>
<cylinder length="0.0030000000000000000625" radius="0.0060000000000000001249" />
</geometry>
<material name="passivewheel_material">
<color rgba="0.30196078431372547213 0.29019607843137257275 0.26274509803921569651 1.0"/>
</material>
</visual>
<inertial>
<origin xyz="-4.2367147623766170634e-20 -1.145124519833743637e-18 -0.00200000000000000221" rpy="0 0 0"/>
<mass value="0.0028590609658248017193" />
<inertia ixx="2.7747274432609138953e-08" ixy="-7.7014157364188990555e-25"  ixz="1.3593957697859050564e-24" iyy="2.7747274432609132335e-08" iyz="-2.7187915395718101128e-24" izz="4.8977394258054644615e-08" />
</inertial>
</link>

<joint name="w3_5_passive" type="revolute">
<origin xyz="0.029162566784475572185 0.023659980949717641929 -0.0024999999999999744649" rpy="1.57079632679489678 -1.1338247319170993155 -2.5132741228718233906" />
<parent link="wheel_2" />
<child link="passivewheel_25" />
<axis xyz="0 0 1"/>
<limit effort="1" velocity="20" />
<joint_properties friction="0.0"/>
</joint>

<link name="passivewheel_26">
<!-- Shapes for passivewheel -->
<collision>
<origin xyz="-1.3933298959045714632e-17 -4.336808689942017736e-19 -0.0020000000000000017764" rpy="-3.141592653589793116 -0 0" />
<geometry>
<cylinder length="0.0030000000000000000625" radius="0.0060000000000000001249" />
</geometry>
</collision>
<!-- Shapes for passivewheel -->
<visual>
<origin xyz="-1.3933298959045714632e-17 -4.336808689942017736e-19 -0.0020000000000000017764" rpy="-3.141592653589793116 -0 0" />
<geometry>
<cylinder length="0.0030000000000000000625" radius="0.0060000000000000001249" />
</geometry>
<material name="passivewheel_material">
<color rgba="0.30196078431372547213 0.29019607843137257275 0.26274509803921569651 1.0"/>
</material>
</visual>
<inertial>
<origin xyz="-1.3920154955438224009e-17 -8.2246595330205771233e-19 -0.00200000000000000221" rpy="0 0 0"/>
<mass value="0.0028590609658248017193" />
<inertia ixx="2.7747274432609152187e-08" ixy="0"  ixz="1.3593957697859050564e-24" iyy="2.7747274432609132335e-08" iyz="1.5402831472837794438e-24" izz="4.8977394258054644615e-08" />
</inertial>
</link>

<joint name="w3_6_passive" type="revolute">
<origin xyz="0.03504658537231833404 0.013490250321650838414 -0.0024999999999999605871" rpy="1.570796326794896336 -1.0686499387975645359 -2.8274333882308080312" />
<parent link="wheel_2" />
<child link="passivewheel_26" />
<axis xyz="0 0 1"/>
<limit effort="1" velocity="20" />
<joint_properties friction="0.0"/>
</joint>

<link name="passivewheel_27">
<!-- Shapes for passivewheel -->
<collision>
<origin xyz="-1.9721522630525295546e-34 -1.7347234759768070944e-18 -0.0020000000000000000416" rpy="-3.9443045261050590271e-31 -9.8607613152626475676e-32 -2.4651903288145233369e-32" />
<geometry>
<cylinder length="0.0030000000000000000625" radius="0.0060000000000000001249" />
</geometry>
</collision>
<!-- Shapes for passivewheel -->
<visual>
<origin xyz="-1.9721522630525295546e-34 -1.7347234759768070944e-18 -0.0020000000000000000416" rpy="-3.9443045261050590271e-31 -9.8607613152626475676e-32 -2.4651903288145233369e-32" />
<geometry>
<cylinder length="0.0030000000000000000625" radius="0.0060000000000000001249" />
</geometry>
<material name="passivewheel_material">
<color rgba="0.30196078431372547213 0.29019607843137257275 0.26274509803921569651 1.0"/>
</material>
</visual>
<inertial>
<origin xyz="1.3144003607491478492e-20 -1.345938391668951252e-18 -0.001999999999999999608" rpy="0 0 0"/>
<mass value="0.0028590609658248017193" />
<inertia ixx="2.7747274432609138953e-08" ixy="1.1858925207528818512e-51"  ixz="-2.0934514429314363421e-39" iyy="2.7747274432609138953e-08" iyz="-1.0944370013161941042e-38" izz="4.8977394258054644615e-08" />
</inertial>
</link>

<joint name="w3_7_passive" type="revolute">
<origin xyz="0.037499999999999984734 0.0020000000000000052458 -0.0024999999999999605871" rpy="1.5707963267948938935 -1.0471975511965967431 3.1415926535897917837" />
<parent link="wheel_2" />
<child link="passivewheel_27" />
<axis xyz="0 0 1"/>
<limit effort="1" velocity="20" />
<joint_properties friction="0.0"/>
</joint>

<link name="passivewheel_28">
<!-- Shapes for passivewheel -->
<collision>
<origin xyz="1.3877787807814456755e-17 1.1102230246251565635e-19 0.0020000000000000000416" rpy="3.141592653589793116 -0 0" />
<geometry>
<cylinder length="0.0030000000000000000625" radius="0.0060000000000000001249" />
</geometry>
</collision>
<!-- Shapes for passivewheel -->
<visual>
<origin xyz="1.3877787807814456755e-17 1.1102230246251565635e-19 0.0020000000000000000416" rpy="3.141592653589793116 -0 0" />
<geometry>
<cylinder length="0.0030000000000000000625" radius="0.0060000000000000001249" />
</geometry>
<material name="passivewheel_material">
<color rgba="0.30196078431372547213 0.29019607843137257275 0.26274509803921569651 1.0"/>
</material>
</visual>
<inertial>
<origin xyz="1.3890931811421947378e-17 -2.7776278184534018607e-19 0.001999999999999999608" rpy="0 0 0"/>
<mass value="0.0028590609658248017193" />
<inertia ixx="2.7747274432609138953e-08" ixy="-1.9253539341047245343e-25"  ixz="0" iyy="2.7747274432609138953e-08" iyz="-2.7187915395718101128e-24" izz="4.8977394258054644615e-08" />
</inertial>
</link>

<joint name="w3_8_passive" type="revolute">
<origin xyz="0.036282653349818137778 -0.0096860242564702162676 -0.0024999999999999744649" rpy="-1.5707963267948970021 -1.0686499387975643138 2.827433388230806699" />
<parent link="wheel_2" />
<child link="passivewheel_28" />
<axis xyz="0 0 1"/>
<limit effort="1" velocity="20" />
<joint_properties friction="0.0"/>
</joint>

<link name="passivewheel_29">
<!-- Shapes for passivewheel -->
<collision>
<origin xyz="1.3877787807814456755e-17 0 -0.0020000000000000017764" rpy="0 2.7755575615628913511e-17 0" />
<geometry>
<cylinder length="0.0030000000000000000625" radius="0.0060000000000000001249" />
</geometry>
</collision>
<!-- Shapes for passivewheel -->
<visual>
<origin xyz="1.3877787807814456755e-17 0 -0.0020000000000000017764" rpy="0 2.7755575615628913511e-17 0" />
<geometry>
<cylinder length="0.0030000000000000000625" radius="0.0060000000000000001249" />
</geometry>
<material name="passivewheel_material">
<color rgba="0.30196078431372547213 0.29019607843137257275 0.26274509803921569651 1.0"/>
</material>
</visual>
<inertial>
<origin xyz="1.3890931811421947378e-17 3.8878508430785584243e-19 -0.0020000000000000013427" rpy="0 0 0"/>
<mass value="0.0028590609658248017193" />
<inertia ixx="2.7747274432609138953e-08" ixy="7.7014157364188981371e-25"  ixz="-7.7014157364188981371e-25" iyy="2.7747274432609138953e-08" iyz="0" izz="4.8977394258054644615e-08" />
</inertial>
</link>

<joint name="w3_9_passive" type="revolute">
<origin xyz="0.031513707793645470701 -0.020423912972217836415 -0.0024999999999999467093" rpy="1.570796326794896336 -1.1338247319170990934 2.5132741228718216142" />
<parent link="wheel_2" />
<child link="passivewheel_29" />
<axis xyz="0 0 1"/>
<limit effort="1" velocity="20" />
<joint_properties friction="0.0"/>
</joint>

<link name="passivewheel_30">
<!-- Shapes for passivewheel -->
<collision>
<origin xyz="-5.5511151231257828177e-20 4.0063438677684357873e-18 -0.0019999999999999965722" rpy="-3.141592653589793116 5.5511151231257827021e-17 -8.3266726846886740532e-17" />
<geometry>
<cylinder length="0.0030000000000000000625" radius="0.0060000000000000001249" />
</geometry>
</collision>
<!-- Shapes for passivewheel -->
<visual>
<origin xyz="-5.5511151231257828177e-20 4.0063438677684357873e-18 -0.0019999999999999965722" rpy="-3.141592653589793116 5.5511151231257827021e-17 -8.3266726846886740532e-17" />
<geometry>
<cylinder length="0.0030000000000000000625" radius="0.0060000000000000001249" />
</geometry>
<material name="passivewheel_material">
<color rgba="0.30196078431372547213 0.29019607843137257275 0.26274509803921569651 1.0"/>
</material>
</visual>
<inertial>
<origin xyz="-4.2367147623766176652e-20 3.6175587834605795597e-18 -0.0019999999999999970059" rpy="0 0 0"/>
<mass value="0.0028590609658248017193" />
<inertia ixx="2.7747274432609138953e-08" ixy="-1.5402831472837794438e-24"  ixz="-1.8088737749787457105e-25" iyy="2.7747274432609138953e-08" iyz="6.9778662264274005876e-24" izz="4.8977394258054644615e-08" />
</inertial>
</link>

<joint name="w3_10_passive" type="revolute">
<origin xyz="0.02365998094971763499 -0.029162566784475561776 -0.0024999999999999883427" rpy="1.570796326794896336 -1.2436334312925132473 2.199114857512844079" />
<parent link="wheel_2" />
<child link="passivewheel_30" />
<axis xyz="0 0 1"/>
<limit effort="1" velocity="20" />
<joint_properties friction="0.0"/>
</joint>

<link name="passivewheel_31">
<!-- Shapes for passivewheel -->
<collision>
<origin xyz="1.3863910020006642286e-17 1.7347234759768070944e-18 -0.0019999999999999939701" rpy="3.141592653589793116 3.4694469519536148051e-17 0" />
<geometry>
<cylinder length="0.0030000000000000000625" radius="0.0060000000000000001249" />
</geometry>
</collision>
<!-- Shapes for passivewheel -->
<visual>
<origin xyz="1.3863910020006642286e-17 1.7347234759768070944e-18 -0.0019999999999999939701" rpy="3.141592653589793116 3.4694469519536148051e-17 0" />
<geometry>
<cylinder length="0.0030000000000000000625" radius="0.0060000000000000001249" />
</geometry>
<material name="passivewheel_material">
<color rgba="0.30196078431372547213 0.29019607843137257275 0.26274509803921569651 1.0"/>
</material>
</visual>
<inertial>
<origin xyz="1.3877054023614134449e-17 1.345938391668951252e-18 -0.0019999999999999944038" rpy="0 0 0"/>
<mass value="0.0028590609658248017193" />
<inertia ixx="2.7747274432609132335e-08" ixy="-7.7014157364188981371e-25"  ixz="-6.2282802460588577346e-25" iyy="2.7747274432609138953e-08" iyz="0" izz="4.8977394258054644615e-08" />
</inertial>
</link>

<joint name="w3_11_passive" type="revolute">
<origin xyz="0.013490250321650852292 -0.035046585372318347917 -0.0024999999999999744649" rpy="1.5707963267948943376 -1.3942429024899476442 1.8849555921538716508" />
<parent link="wheel_2" />
<child link="passivewheel_31" />
<axis xyz="0 0 1"/>
<limit effort="1" velocity="20" />
<joint_properties friction="0.0"/>
</joint>

<link name="passivewheel_32">
<!-- Shapes for passivewheel -->
<collision>
<origin xyz="1.4099832412739488261e-17 0 -0.0020000000000000074142" rpy="3.141592653589793116 -5.9357594720593726362e-33 0" />
<geometry>
<cylinder length="0.0030000000000000000625" radius="0.0060000000000000001249" />
</geometry>
</collision>
<!-- Shapes for passivewheel -->
<visual>
<origin xyz="1.4099832412739488261e-17 0 -0.0020000000000000074142" rpy="3.141592653589793116 -5.9357594720593726362e-33 0" />
<geometry>
<cylinder length="0.0030000000000000000625" radius="0.0060000000000000001249" />
</geometry>
<material name="passivewheel_material">
<color rgba="0.30196078431372547213 0.29019607843137257275 0.26274509803921569651 1.0"/>
</material>
</visual>
<inertial>
<origin xyz="1.4112976416346978883e-17 -3.8878508430785584243e-19 -0.0020000000000000078479" rpy="0 0 0"/>
<mass value="0.0028590609658248017193" />
<inertia ixx="2.7747274432609138953e-08" ixy="-2.1375722681956916097e-41"  ixz="-5.4375830791436194908e-24" iyy="2.7747274432609138953e-08" iyz="-3.4201156291131065755e-40" izz="4.897739425805463138e-08" />
</inertial>
</link>

<joint name="w3_12_passive" type="revolute">
<origin xyz="0.0020000000000000108837 -0.037499999999999991673 -0.0024999999999999744649" rpy="-3.141592653589793116 -1.570796326794896336 0" />
<parent link="wheel_2" />
<child link="passivewheel_32" />
<axis xyz="0 0 1"/>
<limit effort="1" velocity="20" />
<joint_properties friction="0.0"/>
</joint>

<link name="passivewheel_33">
<!-- Shapes for passivewheel -->
<collision>
<origin xyz="-1.3905543383430085693e-17 0 -0.0020000000000000061132" rpy="3.141592653589793116 -2.7755575615628913511e-17 0" />
<geometry>
<cylinder length="0.0030000000000000000625" radius="0.0060000000000000001249" />
</geometry>
</collision>
<!-- Shapes for passivewheel -->
<visual>
<origin xyz="-1.3905543383430085693e-17 0 -0.0020000000000000061132" rpy="3.141592653589793116 -2.7755575615628913511e-17 0" />
<geometry>
<cylinder length="0.0030000000000000000625" radius="0.0060000000000000001249" />
</geometry>
<material name="passivewheel_material">
<color rgba="0.30196078431372547213 0.29019607843137257275 0.26274509803921569651 1.0"/>
</material>
</visual>
<inertial>
<origin xyz="-1.3892399379822595071e-17 -3.8878508430785574613e-19 -0.0020000000000000065468" rpy="0 0 0"/>
<mass value="0.0028590609658248017193" />
<inertia ixx="2.7747274432609138953e-08" ixy="0"  ixz="1.4498394585348424337e-24" iyy="2.7747274432609132335e-08" iyz="0" izz="4.8977394258054644615e-08" />
</inertial>
</link>

<joint name="w3_13_passive" type="revolute">
<origin xyz="-0.0096860242564702127982 -0.036282653349818144717 -0.0024999999999999744649" rpy="-1.5707963267948956698 -1.3942429024899478662 -1.8849555921538712067" />
<parent link="wheel_2" />
<child link="passivewheel_33" />
<axis xyz="0 0 1"/>
<limit effort="1" velocity="20" />
<joint_properties friction="0.0"/>
</joint>

<link name="passivewheel_34">
<!-- Shapes for passivewheel -->
<collision>
<origin xyz="1.3877787807814456755e-17 0 -0.00200000000000000221" rpy="-5.5511151231257839347e-17 -5.5511151231257827021e-17 -2.7755575615628913511e-17" />
<geometry>
<cylinder length="0.0030000000000000000625" radius="0.0060000000000000001249" />
</geometry>
</collision>
<!-- Shapes for passivewheel -->
<visual>
<origin xyz="1.3877787807814456755e-17 0 -0.00200000000000000221" rpy="-5.5511151231257839347e-17 -5.5511151231257827021e-17 -2.7755575615628913511e-17" />
<geometry>
<cylinder length="0.0030000000000000000625" radius="0.0060000000000000001249" />
</geometry>
<material name="passivewheel_material">
<color rgba="0.30196078431372547213 0.29019607843137257275 0.26274509803921569651 1.0"/>
</material>
</visual>
<inertial>
<origin xyz="1.3890931811421947378e-17 3.8878508430785584243e-19 -0.0020000000000000017764" rpy="0 0 0"/>
<mass value="0.0028590609658248017193" />
<inertia ixx="2.7747274432609138953e-08" ixy="-2.3104247209256694411e-24"  ixz="1.5402831472837796274e-24" iyy="2.7747274432609138953e-08" iyz="-1.5402831472837796274e-24" izz="4.897739425805463138e-08" />
</inertial>
</link>

<joint name="w3_14_passive" type="revolute">
<origin xyz="-0.020423912972217815598 -0.031513707793645470701 -0.0024999999999999744649" rpy="-1.570796326794896336 -1.2436334312925139134 -2.1991148575128436349" />
<parent link="wheel_2" />
<child link="passivewheel_34" />
<axis xyz="0 0 1"/>
<limit effort="1" velocity="20" />
<joint_properties friction="0.0"/>
</joint>

<link name="passivewheel_35">
<!-- Shapes for passivewheel -->
<collision>
<origin xyz="-1.1102230246251565635e-19 6.7168492989821968723e-18 -0.0019999999999999965722" rpy="1.1102230246251565404e-16 -0 -2.7755575615628913511e-17" />
<geometry>
<cylinder length="0.0030000000000000000625" radius="0.0060000000000000001249" />
</geometry>
</collision>
<!-- Shapes for passivewheel -->
<visual>
<origin xyz="-1.1102230246251565635e-19 6.7168492989821968723e-18 -0.0019999999999999965722" rpy="1.1102230246251565404e-16 -0 -2.7755575615628913511e-17" />
<geometry>
<cylinder length="0.0030000000000000000625" radius="0.0060000000000000001249" />
</geometry>
<material name="passivewheel_material">
<color rgba="0.30196078431372547213 0.29019607843137257275 0.26274509803921569651 1.0"/>
</material>
</visual>
<inertial>
<origin xyz="-9.7878298855023998811e-20 7.1056343832900531e-18 -0.0019999999999999961385" rpy="0 0 0"/>
<mass value="0.0028590609658248017193" />
<inertia ixx="2.7747274432609138953e-08" ixy="-7.701415736418895382e-25"  ixz="-2.7187915395718101128e-24" iyy="2.7747274432609138953e-08" iyz="-2.3570167845760609707e-24" izz="4.8977394258054644615e-08" />
</inertial>
</link>

<joint name="w3_15_passive" type="revolute">
<origin xyz="-0.02916256678447559994 -0.023659980949717641929 -0.0024999999999999605871" rpy="-1.57079632679489678 -1.1338247319170995375 -2.5132741228718225024" />
<parent link="wheel_2" />
<child link="passivewheel_35" />
<axis xyz="0 0 1"/>
<limit effort="1" velocity="20" />
<joint_properties friction="0.0"/>
</joint>

<link name="passivewheel_36">
<!-- Shapes for passivewheel -->
<collision>
<origin xyz="-5.5511151231257828177e-20 -2.2204460492503131271e-19 -0.0020000000000000004753" rpy="0 5.5511151231257827021e-17 -1.3877787807814456755e-17" />
<geometry>
<cylinder length="0.0030000000000000000625" radius="0.0060000000000000001249" />
</geometry>
</collision>
<!-- Shapes for passivewheel -->
<visual>
<origin xyz="-5.5511151231257828177e-20 -2.2204460492503131271e-19 -0.0020000000000000004753" rpy="0 5.5511151231257827021e-17 -1.3877787807814456755e-17" />
<geometry>
<cylinder length="0.0030000000000000000625" radius="0.0060000000000000001249" />
</geometry>
<material name="passivewheel_material">
<color rgba="0.30196078431372547213 0.29019607843137257275 0.26274509803921569651 1.0"/>
</material>
</visual>
<inertial>
<origin xyz="-4.2367147623766170634e-20 1.6674047938282448157e-19 -0.0020000000000000000416" rpy="0 0 0"/>
<mass value="0.0028590609658248017193" />
<inertia ixx="2.7747274432609138953e-08" ixy="-3.850707868209447691e-25"  ixz="-2.8996789170696845001e-24" iyy="2.7747274432609138953e-08" iyz="-5.4375830791436194908e-24" izz="4.897739425805463138e-08" />
</inertial>
</link>

<joint name="w3_16_passive" type="revolute">
<origin xyz="-0.035046585372318361795 -0.013490250321650843618 -0.0024999999999999605871" rpy="-1.570796326794896336 -1.0686499387975645359 -2.8274333882308080312" />
<parent link="wheel_2" />
<child link="passivewheel_36" />
<axis xyz="0 0 1"/>
<limit effort="1" velocity="20" />
<joint_properties friction="0.0"/>
</joint>

<link name="passivewheel_37">
<!-- Shapes for passivewheel -->
<collision>
<origin xyz="0 1.3877787807814456755e-17 0.0020000000000000000416" rpy="-3.141592653589793116 -0 -4.622231866529037618e-33" />
<geometry>
<cylinder length="0.0030000000000000000625" radius="0.0060000000000000001249" />
</geometry>
</collision>
<!-- Shapes for passivewheel -->
<visual>
<origin xyz="0 1.3877787807814456755e-17 0.0020000000000000000416" rpy="-3.141592653589793116 -0 -4.622231866529037618e-33" />
<geometry>
<cylinder length="0.0030000000000000000625" radius="0.0060000000000000001249" />
</geometry>
<material name="passivewheel_material">
<color rgba="0.30196078431372547213 0.29019607843137257275 0.26274509803921569651 1.0"/>
</material>
</visual>
<inertial>
<origin xyz="1.3144003607491675598e-20 1.3489002723506598987e-17 0.001999999999999999608" rpy="0 0 0"/>
<mass value="0.0028590609658248017193" />
<inertia ixx="2.7747274432609138953e-08" ixy="3.4201156291132949936e-40"  ixz="2.3185898923883018276e-71" iyy="2.7747274432609138953e-08" iyz="1.3680462516452426302e-39" izz="4.8977394258054644615e-08" />
</inertial>
</link>

<joint name="w3_17_passive" type="revolute">
<origin xyz="-0.037499999999999991673 -0.00200000000000001045 -0.0024999999999999744649" rpy="1.5707963267948978903 -1.0471975511965974093 3.141592653589793116" />
<parent link="wheel_2" />
<child link="passivewheel_37" />
<axis xyz="0 0 1"/>
<limit effort="1" velocity="20" />
<joint_properties friction="0.0"/>
</joint>

<link name="passivewheel_38">
<!-- Shapes for passivewheel -->
<collision>
<origin xyz="0 2.2204460492503131271e-19 -0.0019999999999999970059" rpy="3.141592653589793116 2.7755575615628919674e-17 0" />
<geometry>
<cylinder length="0.0030000000000000000625" radius="0.0060000000000000001249" />
</geometry>
</collision>
<!-- Shapes for passivewheel -->
<visual>
<origin xyz="0 2.2204460492503131271e-19 -0.0019999999999999970059" rpy="3.141592653589793116 2.7755575615628919674e-17 0" />
<geometry>
<cylinder length="0.0030000000000000000625" radius="0.0060000000000000001249" />
</geometry>
<material name="passivewheel_material">
<color rgba="0.30196078431372547213 0.29019607843137257275 0.26274509803921569651 1.0"/>
</material>
</visual>
<inertial>
<origin xyz="1.3144003607491671085e-20 -1.6674047938282448157e-19 -0.0019999999999999974395" rpy="0 0 0"/>
<mass value="0.0028590609658248017193" />
<inertia ixx="2.7747274432609132335e-08" ixy="1.9253539341047245343e-25"  ixz="-7.7014157364188972188e-25" iyy="2.7747274432609138953e-08" iyz="-5.4375830791436216949e-24" izz="4.8977394258054671085e-08" />
</inertial>
</link>

<joint name="w3_18_passive" type="revolute">
<origin xyz="-0.036282653349818130839 0.0096860242564702127982 -0.0024999999999999883427" rpy="-1.570796326794896336 -1.0686499387975638697 2.827433388230806699" />
<parent link="wheel_2" />
<child link="passivewheel_38" />
<axis xyz="0 0 1"/>
<limit effort="1" velocity="20" />
<joint_properties friction="0.0"/>
</joint>

<link name="passivewheel_39">
<!-- Shapes for passivewheel -->
<collision>
<origin xyz="0 -1.1102230246251565635e-19 -0.0019999999999999965722" rpy="-3.141592653589793116 5.5511151231257814695e-17 2.7755575615628907348e-17" />
<geometry>
<cylinder length="0.0030000000000000000625" radius="0.0060000000000000001249" />
</geometry>
</collision>
<!-- Shapes for passivewheel -->
<visual>
<origin xyz="0 -1.1102230246251565635e-19 -0.0019999999999999965722" rpy="-3.141592653589793116 5.5511151231257814695e-17 2.7755575615628907348e-17" />
<geometry>
<cylinder length="0.0030000000000000000625" radius="0.0060000000000000001249" />
</geometry>
<material name="passivewheel_material">
<color rgba="0.30196078431372547213 0.29019607843137257275 0.26274509803921569651 1.0"/>
</material>
</visual>
<inertial>
<origin xyz="1.3144003607491690645e-20 -4.9980738677037149878e-19 -0.0019999999999999970059" rpy="0 0 0"/>
<mass value="0.0028590609658248017193" />
<inertia ixx="2.7747274432609152187e-08" ixy="1.8367099231598242312e-40"  ixz="-1.5402831472837799948e-24" iyy="2.7747274432609138953e-08" iyz="4.2590746868555901075e-24" izz="4.8977394258054644615e-08" />
</inertial>
</link>

<joint name="w3_19_passive" type="revolute">
<origin xyz="-0.031513707793645484578 0.020423912972217829476 -0.0024999999999999744649" rpy="-1.570796326794896558 -1.1338247319170982053 2.5132741228718211701" />
<parent link="wheel_2" />
<child link="passivewheel_39" />
<axis xyz="0 0 1"/>
<limit effort="1" velocity="20" />
<joint_properties friction="0.0"/>
</joint>

<link name="passivewheel_40">
<!-- Shapes for passivewheel -->
<collision>
<origin xyz="5.5511151231257828177e-20 -2.2204460492503131271e-19 -0.0020000000000000061132" rpy="3.141592653589793116 -2.7755575615628913511e-17 0" />
<geometry>
<cylinder length="0.0030000000000000000625" radius="0.0060000000000000001249" />
</geometry>
</collision>
<!-- Shapes for passivewheel -->
<visual>
<origin xyz="5.5511151231257828177e-20 -2.2204460492503131271e-19 -0.0020000000000000061132" rpy="3.141592653589793116 -2.7755575615628913511e-17 0" />
<geometry>
<cylinder length="0.0030000000000000000625" radius="0.0060000000000000001249" />
</geometry>
<material name="passivewheel_material">
<color rgba="0.30196078431372547213 0.29019607843137257275 0.26274509803921569651 1.0"/>
</material>
</visual>
<inertial>
<origin xyz="6.865515483874948572e-20 -6.1082968923288715513e-19 -0.0020000000000000065468" rpy="0 0 0"/>
<mass value="0.0028590609658248017193" />
<inertia ixx="2.7747274432609138953e-08" ixy="1.5402831472837794438e-24"  ixz="-5.892541961440153345e-25" iyy="2.7747274432609138953e-08" iyz="3.8972999318598405981e-24" izz="4.8977394258054644615e-08" />
</inertial>
</link>

<joint name="w3_20_passive" type="revolute">
<origin xyz="-0.023659980949717669685 0.029162566784475582593 -0.0024999999999999467093" rpy="-1.570796326794896558 -1.243633431292512137 2.1991148575128400822" />
<parent link="wheel_2" />
<child link="passivewheel_40" />
<axis xyz="0 0 1"/>
<limit effort="1" velocity="20" />
<joint_properties friction="0.0"/>
</joint>

<joint name="wheel_3" type="revolute">
<origin xyz="-0.069282032302755092168 -0.040000000000000063283 0.012999999999999999403" rpy="1.570796326794896558 -0 2.0943951023931961508" />
<parent link="body" />
<child link="wheel_2" />
<axis xyz="0 0 1"/>
<limit effort="1" velocity="20" />
<joint_properties friction="0.0"/>
</joint>

<link name="wheel_3">
<collision>
<origin xyz="-1.1102230246251547532e-17 0.013000000000000001138 0.07500000000000002498" rpy="1.570796326794896558 1.0471975511965980754 0" />
<geometry>
<mesh filename="package:///wheel.stl"/>
</geometry>
</collision>
<visual>
<origin xyz="-1.1102230246251547532e-17 0.013000000000000001138 0.07500000000000002498" rpy="1.570796326794896558 1.0471975511965980754 0" />
<geometry>
<mesh filename="package:///wheel.stl"/>
</geometry>
<material name="wheel_material">
<color rgba="0.94117647058823528106 0.87450980392156862919 0.67843137254901964006 1.0"/>
</material>
</visual>
<inertial>
<origin xyz="-9.285072016806950046e-11 -1.4381200032914653875e-09 -0.0025000000554399950947" rpy="0 0 0"/>
<mass value="0.01924908488748922411" />
<inertia ixx="6.8765144932724313039e-06" ixy="4.74141453805302909e-13"  ixz="-1.4288918542170380918e-14" iyy="6.8765142522306696936e-06" iyz="2.276203667324157145e-14" izz="1.3673643547259726916e-05" />
</inertial>
</link>

<link name="passivewheel_41">
<!-- Shapes for passivewheel -->
<collision>
<origin xyz="-2.7755575615628914088e-20 -7.0499162063697441303e-18 0.0019999999999999991743" rpy="3.141592653589793116 -6.9388939039072268369e-18 0" />
<geometry>
<cylinder length="0.0030000000000000000625" radius="0.0060000000000000001249" />
</geometry>
</collision>
<!-- Shapes for passivewheel -->
<visual>
<origin xyz="-2.7755575615628914088e-20 -7.0499162063697441303e-18 0.0019999999999999991743" rpy="3.141592653589793116 -6.9388939039072268369e-18 0" />
<geometry>
<cylinder length="0.0030000000000000000625" radius="0.0060000000000000001249" />
</geometry>
<material name="passivewheel_material">
<color rgba="0.30196078431372547213 0.29019607843137257275 0.26274509803921569651 1.0"/>
</material>
</visual>
<inertial>
<origin xyz="-1.4611572008137241499e-20 -7.4387012906776003579e-18 0.0019999999999999987406" rpy="0 0 0"/>
<mass value="0.0028590609658248017193" />
<inertia ixx="2.7747274432609152187e-08" ixy="3.7730812079858762519e-41"  ixz="8.7223327830342507345e-25" iyy="2.7747274432609138953e-08" iyz="2.7187915395718101128e-24" izz="4.8977394258054644615e-08" />
</inertial>
</link>

<joint name="w2_1_passive" type="revolute">
<origin xyz="-0.013490250321650822801 -0.035046585372318347917 -0.0025000000000000022204" rpy="-1.5707963267948952257 -1.3942429024899474221 -1.8849555921538756476" />
<parent link="wheel_3" />
<child link="passivewheel_41" />
<axis xyz="0 0 1"/>
<limit effort="1" velocity="20" />
<joint_properties friction="0.0"/>
</joint>

<link name="passivewheel_42">
<!-- Shapes for passivewheel -->
<collision>
<origin xyz="0 0 -0.0020000000000000000416" rpy="3.141592653589793116 3.8334010273658741125e-32 0" />
<geometry>
<cylinder length="0.0030000000000000000625" radius="0.0060000000000000001249" />
</geometry>
</collision>
<!-- Shapes for passivewheel -->
<visual>
<origin xyz="0 0 -0.0020000000000000000416" rpy="3.141592653589793116 3.8334010273658741125e-32 0" />
<geometry>
<cylinder length="0.0030000000000000000625" radius="0.0060000000000000001249" />
</geometry>
<material name="passivewheel_material">
<color rgba="0.30196078431372547213 0.29019607843137257275 0.26274509803921569651 1.0"/>
</material>
</visual>
<inertial>
<origin xyz="1.3144003607491675598e-20 -3.8878508430785584243e-19 -0.0020000000000000004753" rpy="0 0 0"/>
<mass value="0.0028590609658248017193" />
<inertia ixx="2.7747274432609138953e-08" ixy="0"  ixz="-1.0636643031656672429e-39" iyy="2.7747274432609138953e-08" iyz="0" izz="4.8977394258054644615e-08" />
</inertial>
</link>

<joint name="w2_2_passive" type="revolute">
<origin xyz="-0.00200000000000000221 -0.037499999999999984734 -0.0025000000000000022204" rpy="-0 -1.5707963267948961139 0" />
<parent link="wheel_3" />
<child link="passivewheel_42" />
<axis xyz="0 0 1"/>
<limit effort="1" velocity="20" />
<joint_properties friction="0.0"/>
</joint>

<link name="passivewheel_43">
<!-- Shapes for passivewheel -->
<collision>
<origin xyz="0 1.7347234759768070944e-18 0.0020000000000000004753" rpy="5.5511151231257827021e-17 -0 5.5511151231257814695e-17" />
<geometry>
<cylinder length="0.0030000000000000000625" radius="0.0060000000000000001249" />
</geometry>
</collision>
<!-- Shapes for passivewheel -->
<visual>
<origin xyz="0 1.7347234759768070944e-18 0.0020000000000000004753" rpy="5.5511151231257827021e-17 -0 5.5511151231257814695e-17" />
<geometry>
<cylinder length="0.0030000000000000000625" radius="0.0060000000000000001249" />
</geometry>
<material name="passivewheel_material">
<color rgba="0.30196078431372547213 0.29019607843137257275 0.26274509803921569651 1.0"/>
</material>
</visual>
<inertial>
<origin xyz="1.3144003607491668075e-20 2.1235085602846629368e-18 0.002000000000000000909" rpy="0 0 0"/>
<mass value="0.0028590609658248017193" />
<inertia ixx="2.7747274432609152187e-08" ixy="7.7014157364188999738e-25"  ixz="-4.2751445363913832193e-41" iyy="2.7747274432609152187e-08" iyz="1.5402831472837799948e-24" izz="4.8977394258054644615e-08" />
</inertial>
</link>

<joint name="w2_3_passive" type="revolute">
<origin xyz="0.0096860242564702284107 -0.036282653349818144717 -0.0025000000000000160982" rpy="1.5707963267948947816 -1.3942429024899469781 1.8849555921538736492" />
<parent link="wheel_3" />
<child link="passivewheel_43" />
<axis xyz="0 0 1"/>
<limit effort="1" velocity="20" />
<joint_properties friction="0.0"/>
</joint>

<link name="passivewheel_44">
<!-- Shapes for passivewheel -->
<collision>
<origin xyz="2.7811086766860171387e-17 -2.7079033459997957758e-18 -0.0019999999999999952711" rpy="-3.141592653589793116 2.7755575615628913511e-17 8.3266726846886740532e-17" />
<geometry>
<cylinder length="0.0030000000000000000625" radius="0.0060000000000000001249" />
</geometry>
</collision>
<!-- Shapes for passivewheel -->
<visual>
<origin xyz="2.7811086766860171387e-17 -2.7079033459997957758e-18 -0.0019999999999999952711" rpy="-3.141592653589793116 2.7755575615628913511e-17 8.3266726846886740532e-17" />
<geometry>
<cylinder length="0.0030000000000000000625" radius="0.0060000000000000001249" />
</geometry>
<material name="passivewheel_material">
<color rgba="0.30196078431372547213 0.29019607843137257275 0.26274509803921569651 1.0"/>
</material>
</visual>
<inertial>
<origin xyz="2.7824230770467662009e-17 -3.0966884303076516182e-18 -0.0019999999999999957048" rpy="0 0 0"/>
<mass value="0.0028590609658248017193" />
<inertia ixx="2.7747274432609138953e-08" ixy="3.8507078682094490686e-24"  ixz="-2.1295373434277943191e-24" iyy="2.7747274432609138953e-08" iyz="3.6177475499574987678e-25" izz="4.8977394258054618145e-08" />
</inertial>
</link>

<joint name="w2_4_passive" type="revolute">
<origin xyz="0.020423912972217843353 -0.031513707793645470701 -0.0025000000000000022204" rpy="-1.5707963267948972241 -1.2436334312925123591 2.1991148575128507403" />
<parent link="wheel_3" />
<child link="passivewheel_44" />
<axis xyz="0 0 1"/>
<limit effort="1" velocity="20" />
<joint_properties friction="0.0"/>
</joint>

<link name="passivewheel_45">
<!-- Shapes for passivewheel -->
<collision>
<origin xyz="-1.3766765505351941003e-17 3.3306690738754696906e-19 -0.0020000000000000000416" rpy="-3.141592653589793116 -0 -2.7755575615628913511e-17" />
<geometry>
<cylinder length="0.0030000000000000000625" radius="0.0060000000000000001249" />
</geometry>
</collision>
<!-- Shapes for passivewheel -->
<visual>
<origin xyz="-1.3766765505351941003e-17 3.3306690738754696906e-19 -0.0020000000000000000416" rpy="-3.141592653589793116 -0 -2.7755575615628913511e-17" />
<geometry>
<cylinder length="0.0030000000000000000625" radius="0.0060000000000000001249" />
</geometry>
<material name="passivewheel_material">
<color rgba="0.30196078431372547213 0.29019607843137257275 0.26274509803921569651 1.0"/>
</material>
</visual>
<inertial>
<origin xyz="-1.375362150174444884e-17 -5.571817692030877707e-20 -0.0020000000000000004753" rpy="0 0 0"/>
<mass value="0.0028590609658248017193" />
<inertia ixx="2.7747274432609138953e-08" ixy="-2.3104247209256690738e-24"  ixz="-2.7187915395718101128e-24" iyy="2.7747274432609138953e-08" iyz="-5.0758083241478707161e-24" izz="4.8977394258054644615e-08" />
</inertial>
</link>

<joint name="w2_5_passive" type="revolute">
<origin xyz="0.029162566784475579124 -0.023659980949717641929 -0.0025000000000000022204" rpy="-1.5707963267948972241 -1.1338247319170977612 2.5132741228718300519" />
<parent link="wheel_3" />
<child link="passivewheel_45" />
<axis xyz="0 0 1"/>
<limit effort="1" velocity="20" />
<joint_properties friction="0.0"/>
</joint>

<link name="passivewheel_46">
<!-- Shapes for passivewheel -->
<collision>
<origin xyz="1.3877787807814456755e-17 1.1102230246251565635e-19 -0.0020000000000000000416" rpy="3.141592653589793116 -0 0" />
<geometry>
<cylinder length="0.0030000000000000000625" radius="0.0060000000000000001249" />
</geometry>
</collision>
<!-- Shapes for passivewheel -->
<visual>
<origin xyz="1.3877787807814456755e-17 1.1102230246251565635e-19 -0.0020000000000000000416" rpy="3.141592653589793116 -0 0" />
<geometry>
<cylinder length="0.0030000000000000000625" radius="0.0060000000000000001249" />
</geometry>
<material name="passivewheel_material">
<color rgba="0.30196078431372547213 0.29019607843137257275 0.26274509803921569651 1.0"/>
</material>
</visual>
<inertial>
<origin xyz="1.3890931811421947378e-17 -2.7776278184534008978e-19 -0.0020000000000000004753" rpy="0 0 0"/>
<mass value="0.0028590609658248017193" />
<inertia ixx="2.7747274432609138953e-08" ixy="9.6267696705236208347e-25"  ixz="0" iyy="2.7747274432609132335e-08" iyz="-2.7187915395718101128e-24" izz="4.8977394258054644615e-08" />
</inertial>
</link>

<joint name="w2_6_passive" type="revolute">
<origin xyz="0.035046585372318361795 -0.013490250321650834944 -0.0024999999999999883427" rpy="-1.57079632679489678 -1.0686499387975618713 2.8274333882308106958" />
<parent link="wheel_3" />
<child link="passivewheel_46" />
<axis xyz="0 0 1"/>
<limit effort="1" velocity="20" />
<joint_properties friction="0.0"/>
</joint>

<link name="passivewheel_47">
<!-- Shapes for passivewheel -->
<collision>
<origin xyz="3.9443045261050591092e-34 -6.9388939039072283776e-18 -0.0020000000000000000416" rpy="7.8886090522101180541e-31 -1.3558546808486142595e-31 1.014159159662424555e-31" />
<geometry>
<cylinder length="0.0030000000000000000625" radius="0.0060000000000000001249" />
</geometry>
</collision>
<!-- Shapes for passivewheel -->
<visual>
<origin xyz="3.9443045261050591092e-34 -6.9388939039072283776e-18 -0.0020000000000000000416" rpy="7.8886090522101180541e-31 -1.3558546808486142595e-31 1.014159159662424555e-31" />
<geometry>
<cylinder length="0.0030000000000000000625" radius="0.0060000000000000001249" />
</geometry>
<material name="passivewheel_material">
<color rgba="0.30196078431372547213 0.29019607843137257275 0.26274509803921569651 1.0"/>
</material>
</visual>
<inertial>
<origin xyz="1.3144003607492045738e-20 -6.5501088195993736908e-18 -0.001999999999999999608" rpy="0 0 0"/>
<mass value="0.0028590609658248017193" />
<inertia ixx="2.7747274432609125718e-08" ixy="-1.540283147283945115e-24"  ixz="1.3421215084468257175e-38" iyy="2.7747274432609138953e-08" iyz="1.2229652133880037573e-38" izz="4.8977394258054644615e-08" />
</inertial>
</link>

<joint name="w2_7_passive" type="revolute">
<origin xyz="0.03750000000000001249 -0.0020000000000000000416 -0.0025000000000000160982" rpy="-1.5707963267948947816 -0.39309481042651911453 -3.141592653589793116" />
<parent link="wheel_3" />
<child link="passivewheel_47" />
<axis xyz="0 0 1"/>
<limit effort="1" velocity="20" />
<joint_properties friction="0.0"/>
</joint>

<link name="passivewheel_48">
<!-- Shapes for passivewheel -->
<collision>
<origin xyz="-1.3822276656583198879e-17 -7.4835970753639459039e-18 0.0020000000000000017764" rpy="3.141592653589793116 2.7755575615628919674e-17 4.8572257327350604807e-17" />
<geometry>
<cylinder length="0.0030000000000000000625" radius="0.0060000000000000001249" />
</geometry>
</collision>
<!-- Shapes for passivewheel -->
<visual>
<origin xyz="-1.3822276656583198879e-17 -7.4835970753639459039e-18 0.0020000000000000017764" rpy="3.141592653589793116 2.7755575615628919674e-17 4.8572257327350604807e-17" />
<geometry>
<cylinder length="0.0030000000000000000625" radius="0.0060000000000000001249" />
</geometry>
<material name="passivewheel_material">
<color rgba="0.30196078431372547213 0.29019607843137257275 0.26274509803921569651 1.0"/>
</material>
</visual>
<inertial>
<origin xyz="-1.3809132652975706716e-17 -7.8723821596718021315e-18 0.0020000000000000013427" rpy="0 0 0"/>
<mass value="0.0028590609658248017193" />
<inertia ixx="2.7747274432609132335e-08" ixy="-2.5913261647569995835e-40"  ixz="-2.1295373434277946864e-24" iyy="2.7747274432609138953e-08" iyz="1.1785083922880304853e-24" izz="4.8977394258054644615e-08" />
</inertial>
</link>

<joint name="w2_8_passive" type="revolute">
<origin xyz="0.036282653349818137778 0.0096860242564702145329 -0.0024999999999999883427" rpy="1.570796326794896558 -1.0686499387975689768 -2.8274333882308089194" />
<parent link="wheel_3" />
<child link="passivewheel_48" />
<axis xyz="0 0 1"/>
<limit effort="1" velocity="20" />
<joint_properties friction="0.0"/>
</joint>

<link name="passivewheel_49">
<!-- Shapes for passivewheel -->
<collision>
<origin xyz="-1.1102230246251565635e-19 3.2474023470285826835e-18 -0.0020000000000000074142" rpy="0 -2.7755575615628913511e-17 -2.7755575615628913511e-17" />
<geometry>
<cylinder length="0.0030000000000000000625" radius="0.0060000000000000001249" />
</geometry>
</collision>
<!-- Shapes for passivewheel -->
<visual>
<origin xyz="-1.1102230246251565635e-19 3.2474023470285826835e-18 -0.0020000000000000074142" rpy="0 -2.7755575615628913511e-17 -2.7755575615628913511e-17" />
<geometry>
<cylinder length="0.0030000000000000000625" radius="0.0060000000000000001249" />
</geometry>
<material name="passivewheel_material">
<color rgba="0.30196078431372547213 0.29019607843137257275 0.26274509803921569651 1.0"/>
</material>
</visual>
<inertial>
<origin xyz="-9.7878298855023974736e-20 3.6361874313364389111e-18 -0.0020000000000000069805" rpy="0 0 0"/>
<mass value="0.0028590609658248017193" />
<inertia ixx="2.7747274432609138953e-08" ixy="7.7014157364189008922e-25"  ixz="-1.9486499659299199317e-24" iyy="2.7747274432609138953e-08" iyz="-5.4375830791436194908e-24" izz="4.897739425805463138e-08" />
</inertial>
</link>

<joint name="w2_9_passive" type="revolute">
<origin xyz="0.031513707793645477639 0.020423912972217836415 -0.0025000000000000160982" rpy="-1.570796326794896558 -1.1338247319171015359 -2.5132741228718282755" />
<parent link="wheel_3" />
<child link="passivewheel_49" />
<axis xyz="0 0 1"/>
<limit effort="1" velocity="20" />
<joint_properties friction="0.0"/>
</joint>

<link name="passivewheel_50">
<!-- Shapes for passivewheel -->
<collision>
<origin xyz="1.3877787807814456755e-17 1.0519363158323358319e-17 -0.0020000000000000000416" rpy="-3.141592653589793116 2.7755575615628913511e-17 -2.7755575615628913511e-17" />
<geometry>
<cylinder length="0.0030000000000000000625" radius="0.0060000000000000001249" />
</geometry>
</collision>
<!-- Shapes for passivewheel -->
<visual>
<origin xyz="1.3877787807814456755e-17 1.0519363158323358319e-17 -0.0020000000000000000416" rpy="-3.141592653589793116 2.7755575615628913511e-17 -2.7755575615628913511e-17" />
<geometry>
<cylinder length="0.0030000000000000000625" radius="0.0060000000000000001249" />
</geometry>
<material name="passivewheel_material">
<color rgba="0.30196078431372547213 0.29019607843137257275 0.26274509803921569651 1.0"/>
</material>
</visual>
<inertial>
<origin xyz="1.3890931811421947378e-17 1.0130578074015502092e-17 -0.0020000000000000004753" rpy="0 0 0"/>
<mass value="0.0028590609658248017193" />
<inertia ixx="2.7747274432609138953e-08" ixy="-1.5402831472837796274e-24"  ixz="-7.7014157364188981371e-25" iyy="2.7747274432609132335e-08" iyz="-1.178508392288030669e-24" izz="4.8977394258054644615e-08" />
</inertial>
</link>

<joint name="w2_10_passive" type="revolute">
<origin xyz="0.023659980949717641929 0.029162566784475568715 -0.0025000000000000022204" rpy="-1.570796326794896558 -1.2436334312925130252 -2.1991148575128507403" />
<parent link="wheel_3" />
<child link="passivewheel_50" />
<axis xyz="0 0 1"/>
<limit effort="1" velocity="20" />
<joint_properties friction="0.0"/>
</joint>

<link name="passivewheel_51">
<!-- Shapes for passivewheel -->
<collision>
<origin xyz="-1.3933298959045714632e-17 -7.1609385088322598829e-18 -0.0020000000000000000416" rpy="3.141592653589793116 1.3877787807814456755e-17 2.7755575615628913511e-17" />
<geometry>
<cylinder length="0.0030000000000000000625" radius="0.0060000000000000001249" />
</geometry>
</collision>
<!-- Shapes for passivewheel -->
<visual>
<origin xyz="-1.3933298959045714632e-17 -7.1609385088322598829e-18 -0.0020000000000000000416" rpy="3.141592653589793116 1.3877787807814456755e-17 2.7755575615628913511e-17" />
<geometry>
<cylinder length="0.0030000000000000000625" radius="0.0060000000000000001249" />
</geometry>
<material name="passivewheel_material">
<color rgba="0.30196078431372547213 0.29019607843137257275 0.26274509803921569651 1.0"/>
</material>
</visual>
<inertial>
<origin xyz="-1.3920154955438224009e-17 -7.5497235931401161106e-18 -0.0020000000000000004753" rpy="0 0 0"/>
<mass value="0.0028590609658248017193" />
<inertia ixx="2.7747274432609138953e-08" ixy="7.7014157364188999738e-25"  ixz="9.7432498296495996585e-25" iyy="2.7747274432609138953e-08" iyz="5.4375830791436194908e-24" izz="4.897739425805463138e-08" />
</inertial>
</link>

<joint name="w2_11_passive" type="revolute">
<origin xyz="0.013490250321650854026 0.035046585372318354856 -0.0024999999999999883427" rpy="-1.5707963267948956698 -1.3942429024899476442 -1.8849555921538738712" />
<parent link="wheel_3" />
<child link="passivewheel_51" />
<axis xyz="0 0 1"/>
<limit effort="1" velocity="20" />
<joint_properties friction="0.0"/>
</joint>

<link name="passivewheel_52">
<!-- Shapes for passivewheel -->
<collision>
<origin xyz="-3.9466641416538033013e-35 0 -0.0020000000000000000416" rpy="3.141592653589793116 -1.3044059530804947457e-32 0" />
<geometry>
<cylinder length="0.0030000000000000000625" radius="0.0060000000000000001249" />
</geometry>
</collision>
<!-- Shapes for passivewheel -->
<visual>
<origin xyz="-3.9466641416538033013e-35 0 -0.0020000000000000000416" rpy="3.141592653589793116 -1.3044059530804947457e-32 0" />
<geometry>
<cylinder length="0.0030000000000000000625" radius="0.0060000000000000001249" />
</geometry>
<material name="passivewheel_material">
<color rgba="0.30196078431372547213 0.29019607843137257275 0.26274509803921569651 1.0"/>
</material>
</visual>
<inertial>
<origin xyz="1.3144003607491636478e-20 -3.8878508430785584243e-19 -0.0020000000000000004753" rpy="0 0 0"/>
<mass value="0.0028590609658248017193" />
<inertia ixx="2.7747274432609138953e-08" ixy="0"  ixz="1.328423727866061323e-39" iyy="2.7747274432609138953e-08" iyz="0" izz="4.8977394258054644615e-08" />
</inertial>
</link>

<joint name="w2_12_passive" type="revolute">
<origin xyz="0.002000000000000011751 0.037499999999999991673 -0.0025000000000000022204" rpy="3.141592653589793116 -1.570796326794896336 0" />
<parent link="wheel_3" />
<child link="passivewheel_52" />
<axis xyz="0 0 1"/>
<limit effort="1" velocity="20" />
<joint_properties friction="0.0"/>
</joint>

<link name="passivewheel_53">
<!-- Shapes for passivewheel -->
<collision>
<origin xyz="-1.3891665595622269684e-17 1.3988810110276972508e-17 -0.0020000000000000035111" rpy="-3.141592653589793116 -0 0" />
<geometry>
<cylinder length="0.0030000000000000000625" radius="0.0060000000000000001249" />
</geometry>
</collision>
<!-- Shapes for passivewheel -->
<visual>
<origin xyz="-1.3891665595622269684e-17 1.3988810110276972508e-17 -0.0020000000000000035111" rpy="-3.141592653589793116 -0 0" />
<geometry>
<cylinder length="0.0030000000000000000625" radius="0.0060000000000000001249" />
</geometry>
<material name="passivewheel_material">
<color rgba="0.30196078431372547213 0.29019607843137257275 0.26274509803921569651 1.0"/>
</material>
</visual>
<inertial>
<origin xyz="-1.3878521592014779061e-17 1.360002502596911474e-17 -0.0020000000000000039448" rpy="0 0 0"/>
<mass value="0.0028590609658248017193" />
<inertia ixx="2.7747274432609138953e-08" ixy="1.5402831472837794438e-24"  ixz="3.3984894244647635593e-25" iyy="2.7747274432609132335e-08" iyz="-1.178508392288030669e-24" izz="4.8977394258054644615e-08" />
</inertial>
</link>

<joint name="w2_13_passive" type="revolute">
<origin xyz="-0.0096860242564702023899 0.036282653349818151656 -0.0025000000000000022204" rpy="1.5707963267948961139 -1.3942429024899476442 1.8849555921538740932" />
<parent link="wheel_3" />
<child link="passivewheel_53" />
<axis xyz="0 0 1"/>
<limit effort="1" velocity="20" />
<joint_properties friction="0.0"/>
</joint>

<link name="passivewheel_54">
<!-- Shapes for passivewheel -->
<collision>
<origin xyz="1.3822276656583198879e-17 2.2204460492503131271e-19 -0.0020000000000000048121" rpy="1.1102230246251562939e-16 2.7755575615628919674e-17 0" />
<geometry>
<cylinder length="0.0030000000000000000625" radius="0.0060000000000000001249" />
</geometry>
</collision>
<!-- Shapes for passivewheel -->
<visual>
<origin xyz="1.3822276656583198879e-17 2.2204460492503131271e-19 -0.0020000000000000048121" rpy="1.1102230246251562939e-16 2.7755575615628919674e-17 0" />
<geometry>
<cylinder length="0.0030000000000000000625" radius="0.0060000000000000001249" />
</geometry>
<material name="passivewheel_material">
<color rgba="0.30196078431372547213 0.29019607843137257275 0.26274509803921569651 1.0"/>
</material>
</visual>
<inertial>
<origin xyz="1.3835420660190691042e-17 6.1082968923288715513e-19 -0.0020000000000000043784" rpy="0 0 0"/>
<mass value="0.0028590609658248017193" />
<inertia ixx="2.7747274432609132335e-08" ixy="-1.5402831472837798111e-24"  ixz="-2.1295373434277954211e-24" iyy="2.7747274432609138953e-08" iyz="8.518149373711180215e-24" izz="4.8977394258054671085e-08" />
</inertial>
</link>

<joint name="w2_14_passive" type="revolute">
<origin xyz="-0.020423912972217812128 0.031513707793645477639 -0.0025000000000000022204" rpy="1.57079632679489678 -1.2436334312925132473 2.1991148575128502962" />
<parent link="wheel_3" />
<child link="passivewheel_54" />
<axis xyz="0 0 1"/>
<limit effort="1" velocity="20" />
<joint_properties friction="0.0"/>
</joint>

<link name="passivewheel_55">
<!-- Shapes for passivewheel -->
<collision>
<origin xyz="1.3822276656583198879e-17 -1.3877787807814456755e-17 -0.0019999999999999987406" rpy="0 2.7755575615628919674e-17 2.7755575615628919674e-17" />
<geometry>
<cylinder length="0.0030000000000000000625" radius="0.0060000000000000001249" />
</geometry>
</collision>
<!-- Shapes for passivewheel -->
<visual>
<origin xyz="1.3822276656583198879e-17 -1.3877787807814456755e-17 -0.0019999999999999987406" rpy="0 2.7755575615628919674e-17 2.7755575615628919674e-17" />
<geometry>
<cylinder length="0.0030000000000000000625" radius="0.0060000000000000001249" />
</geometry>
<material name="passivewheel_material">
<color rgba="0.30196078431372547213 0.29019607843137257275 0.26274509803921569651 1.0"/>
</material>
</visual>
<inertial>
<origin xyz="1.3835420660190691042e-17 -1.3489002723506598987e-17 -0.0019999999999999983069" rpy="0 0 0"/>
<mass value="0.0028590609658248017193" />
<inertia ixx="2.7747274432609132335e-08" ixy="0"  ixz="-2.1295373434277946864e-24" iyy="2.7747274432609132335e-08" iyz="-2.1375722681956916097e-41" izz="4.897739425805463138e-08" />
</inertial>
</link>

<joint name="w2_15_passive" type="revolute">
<origin xyz="-0.029162566784475568715 0.023659980949717641929 -0.0025000000000000022204" rpy="1.570796326794896336 -1.1338247319170990934 2.5132741228718296078" />
<parent link="wheel_3" />
<child link="passivewheel_55" />
<axis xyz="0 0 1"/>
<limit effort="1" velocity="20" />
<joint_properties friction="0.0"/>
</joint>

<link name="passivewheel_56">
<!-- Shapes for passivewheel -->
<collision>
<origin xyz="-6.9388939039072283776e-18 1.365574320288942525e-17 -0.0020000000000000000416" rpy="-5.5511151231257827021e-17 -0 1.3877787807814456755e-17" />
<geometry>
<cylinder length="0.0030000000000000000625" radius="0.0060000000000000001249" />
</geometry>
</collision>
<!-- Shapes for passivewheel -->
<visual>
<origin xyz="-6.9388939039072283776e-18 1.365574320288942525e-17 -0.0020000000000000000416" rpy="-5.5511151231257827021e-17 -0 1.3877787807814456755e-17" />
<geometry>
<cylinder length="0.0030000000000000000625" radius="0.0060000000000000001249" />
</geometry>
<material name="passivewheel_material">
<color rgba="0.30196078431372547213 0.29019607843137257275 0.26274509803921569651 1.0"/>
</material>
</visual>
<inertial>
<origin xyz="-6.9257499002997362145e-18 1.4044528287197281478e-17 -0.001999999999999999608" rpy="0 0 0"/>
<mass value="0.0028590609658248017193" />
<inertia ixx="2.7747274432609138953e-08" ixy="9.183549615799121156e-41"  ixz="2.1375722681956916097e-41" iyy="2.7747274432609125718e-08" iyz="-6.9778662264273991182e-24" izz="4.8977394258054644615e-08" />
</inertial>
</link>

<joint name="w2_16_passive" type="revolute">
<origin xyz="-0.035046585372318361795 0.013490250321650847087 -0.0025000000000000160982" rpy="1.57079632679489678 -1.06864993879756498 2.8274333882308102517" />
<parent link="wheel_3" />
<child link="passivewheel_56" />
<axis xyz="0 0 1"/>
<limit effort="1" velocity="20" />
<joint_properties friction="0.0"/>
</joint>

<link name="passivewheel_57">
<!-- Shapes for passivewheel -->
<collision>
<origin xyz="4.336808689942019662e-19 9.8607613152626477729e-35 0.0020000000000000000416" rpy="3.141592653589793116 4.9303806576313237838e-32 5.5511151231257728414e-17" />
<geometry>
<cylinder length="0.0030000000000000000625" radius="0.0060000000000000001249" />
</geometry>
</collision>
<!-- Shapes for passivewheel -->
<visual>
<origin xyz="4.336808689942019662e-19 9.8607613152626477729e-35 0.0020000000000000000416" rpy="3.141592653589793116 4.9303806576313237838e-32 5.5511151231257728414e-17" />
<geometry>
<cylinder length="0.0030000000000000000625" radius="0.0060000000000000001249" />
</geometry>
<material name="passivewheel_material">
<color rgba="0.30196078431372547213 0.29019607843137257275 0.26274509803921569651 1.0"/>
</material>
</visual>
<inertial>
<origin xyz="4.4682487260169364781e-19 -3.8878508430785569798e-19 0.001999999999999999608" rpy="0 0 0"/>
<mass value="0.0028590609658248017193" />
<inertia ixx="2.7747274432609138953e-08" ixy="3.080566294567535745e-24"  ixz="-6.1975901978671648852e-39" iyy="2.7747274432609132335e-08" iyz="-2.4147719731109608012e-39" izz="4.8977394258054644615e-08" />
</inertial>
</link>

<joint name="w2_17_passive" type="revolute">
<origin xyz="-0.037499999999999998612 0.0020000000000000139194 -0.0025000000000000022204" rpy="-1.5707963267948972241 -0.39309481042651972516 -3.141592653589793116" />
<parent link="wheel_3" />
<child link="passivewheel_57" />
<axis xyz="0 0 1"/>
<limit effort="1" velocity="20" />
<joint_properties friction="0.0"/>
</joint>

<link name="passivewheel_58">
<!-- Shapes for passivewheel -->
<collision>
<origin xyz="0 -1.1102230246251565635e-19 -0.0020000000000000000416" rpy="3.141592653589793116 -2.7755575615628913511e-17 -4.8572257327350598644e-17" />
<geometry>
<cylinder length="0.0030000000000000000625" radius="0.0060000000000000001249" />
</geometry>
</collision>
<!-- Shapes for passivewheel -->
<visual>
<origin xyz="0 -1.1102230246251565635e-19 -0.0020000000000000000416" rpy="3.141592653589793116 -2.7755575615628913511e-17 -4.8572257327350598644e-17" />
<geometry>
<cylinder length="0.0030000000000000000625" radius="0.0060000000000000001249" />
</geometry>
<material name="passivewheel_material">
<color rgba="0.30196078431372547213 0.29019607843137257275 0.26274509803921569651 1.0"/>
</material>
</visual>
<inertial>
<origin xyz="1.3144003607491684626e-20 -4.9980738677037149878e-19 -0.0020000000000000004753" rpy="0 0 0"/>
<mass value="0.0028590609658248017193" />
<inertia ixx="2.7747274432609138953e-08" ixy="-1.9253539341047245343e-24"  ixz="7.7014157364188981371e-25" iyy="2.7747274432609132335e-08" iyz="1.178508392288030669e-24" izz="4.8977394258054644615e-08" />
</inertial>
</link>

<joint name="w2_18_passive" type="revolute">
<origin xyz="-0.0362826533498181239 -0.0096860242564702110635 -0.0024999999999999883427" rpy="1.57079632679489678 -1.0686499387975578745 -2.8274333882308093635" />
<parent link="wheel_3" />
<child link="passivewheel_58" />
<axis xyz="0 0 1"/>
<limit effort="1" velocity="20" />
<joint_properties friction="0.0"/>
</joint>

<link name="passivewheel_59">
<!-- Shapes for passivewheel -->
<collision>
<origin xyz="-1.3877787807814456755e-17 1.3877787807814456755e-17 -0.0020000000000000052458" rpy="3.141592653589793116 -2.7755575615628913511e-17 2.7755575615628913511e-17" />
<geometry>
<cylinder length="0.0030000000000000000625" radius="0.0060000000000000001249" />
</geometry>
</collision>
<!-- Shapes for passivewheel -->
<visual>
<origin xyz="-1.3877787807814456755e-17 1.3877787807814456755e-17 -0.0020000000000000052458" rpy="3.141592653589793116 -2.7755575615628913511e-17 2.7755575615628913511e-17" />
<geometry>
<cylinder length="0.0030000000000000000625" radius="0.0060000000000000001249" />
</geometry>
<material name="passivewheel_material">
<color rgba="0.30196078431372547213 0.29019607843137257275 0.26274509803921569651 1.0"/>
</material>
</visual>
<inertial>
<origin xyz="-1.3864643804206964592e-17 1.3489002723506598987e-17 -0.0020000000000000056795" rpy="0 0 0"/>
<mass value="0.0028590609658248017193" />
<inertia ixx="2.7747274432609138953e-08" ixy="2.3104247209256694411e-24"  ixz="7.7014157364188972188e-25" iyy="2.7747274432609138953e-08" iyz="-1.5402831472837796274e-24" izz="4.8977394258054644615e-08" />
</inertial>
</link>

<joint name="w2_19_passive" type="revolute">
<origin xyz="-0.031513707793645477639 -0.020423912972217826006 -0.0024999999999999883427" rpy="1.5707963267948970021 -1.1338247319170962069 -2.5132741228718282755" />
<parent link="wheel_3" />
<child link="passivewheel_59" />
<axis xyz="0 0 1"/>
<limit effort="1" velocity="20" />
<joint_properties friction="0.0"/>
</joint>

<link name="passivewheel_60">
<!-- Shapes for passivewheel -->
<collision>
<origin xyz="-2.7811086766860171387e-17 1.3766765505351941003e-17 -0.0020000000000000017764" rpy="3.141592653589793116 2.7755575615628913511e-17 -8.3266726846886740532e-17" />
<geometry>
<cylinder length="0.0030000000000000000625" radius="0.0060000000000000001249" />
</geometry>
</collision>
<!-- Shapes for passivewheel -->
<visual>
<origin xyz="-2.7811086766860171387e-17 1.3766765505351941003e-17 -0.0020000000000000017764" rpy="3.141592653589793116 2.7755575615628913511e-17 -8.3266726846886740532e-17" />
<geometry>
<cylinder length="0.0030000000000000000625" radius="0.0060000000000000001249" />
</geometry>
<material name="passivewheel_material">
<color rgba="0.30196078431372547213 0.29019607843137257275 0.26274509803921569651 1.0"/>
</material>
</visual>
<inertial>
<origin xyz="-2.7797942763252680765e-17 1.3377980421044083234e-17 -0.00200000000000000221" rpy="0 0 0"/>
<mass value="0.0028590609658248017193" />
<inertia ixx="2.7747274432609138953e-08" ixy="-2.3104247209256694411e-24"  ixz="5.8925419614401524266e-25" iyy="2.7747274432609138953e-08" iyz="2.7187915395718101128e-24" izz="4.8977394258054644615e-08" />
</inertial>
</link>

<joint name="w2_20_passive" type="revolute">
<origin xyz="-0.023659980949717645399 -0.029162566784475568715 -0.0025000000000000160982" rpy="1.5707963267948972241 -1.2436334312925112489 -2.1991148575128480758" />
<parent link="wheel_3" />
<child link="passivewheel_60" />
<axis xyz="0 0 1"/>
<limit effort="1" velocity="20" />
<joint_properties friction="0.0"/>
</joint>

<joint name="wheel_2" type="revolute">
<origin xyz="-6.5919492087118669588e-17 0.080000000000000182077 0.013000000000000034098" rpy="1.570796326794896558 -0 6.1062266354383451951e-16" />
<parent link="body" />
<child link="wheel_3" />
<axis xyz="0 0 1"/>
<limit effort="1" velocity="20" />
<joint_properties friction="0.0"/>
</joint>


</robot>
