<robot name="onshape">
<link name="body">
<!-- Shapes for body -->
<collision>
<origin xyz="0 0 0.0011000000000000000663" rpy="0 -0 0" />
<geometry>
<box size="0.02999999999999999889 0.02999999999999999889 0.0020000000000000000416" />
</geometry>
</collision>
<!-- Shapes for horn -->
<!-- Shapes for motor -->
<collision>
<origin xyz="0.040499999999999994338 8.6620525567123032496e-18 0.01430000000000000368" rpy="0 -0 -1.570796326794896336" />
<geometry>
<box size="0.020000000000000000416 0.02999999999999999889 0.021999999999999998723" />
</geometry>
</collision>
<!-- Shapes for motor -->
<collision>
<origin xyz="-0.040500000000000008216 -2.2447321777708132752e-18 0.014300000000000000211" rpy="1.4554650149047266776e-17 3.6115130309995309768e-16 1.57079632679489678" />
<geometry>
<box size="0.020000000000000000416 0.02999999999999999889 0.021999999999999998723" />
</geometry>
</collision>
<!-- Shapes for horn -->
<!-- Shapes for horn -->
<!-- Shapes for motor -->
<collision>
<origin xyz="-2.8796409701214538009e-18 0.04049999999999998046 0.01430000000000000368" rpy="0 -0 8.326672684688658276e-16" />
<geometry>
<box size="0.020000000000000000416 0.02999999999999999889 0.021999999999999998723" />
</geometry>
</collision>
<!-- Shapes for body -->
<collision>
<origin xyz="0 3.4694469519536141888e-18 0.027500000000000000139" rpy="3.141592653589793116 -0 0" />
<geometry>
<box size="0.02999999999999999889 0.02999999999999999889 0.0020000000000000000416" />
</geometry>
</collision>
<!-- Shapes for motor -->
<collision>
<origin xyz="-2.480011791041389871e-18 -0.040500000000000001277 0.014300000000000005415" rpy="0 -0 -3.141592653589793116" />
<geometry>
<box size="0.020000000000000000416 0.02999999999999999889 0.021999999999999998723" />
</geometry>
</collision>
<!-- Shapes for horn -->
<visual>
<origin xyz="0 0 0" rpy="0 -0 0" />
<geometry>
<mesh filename="package:///body_visual.stl"/>
</geometry>
<material name="body_material">
<color rgba="0.54644525242796082587 0.49070311698568169767 0.42460182362935083855 1.0"/>
</material>
</visual>
<inertial>
<origin xyz="-3.7001636451421611404e-18 1.7176611635261148532e-18 0.014338409612449544081" rpy="0 0 0"/>
<mass value="0.080873577571338770009" />
<inertia ixx="7.3740766846903802638e-05" ixy="-7.5837321945226471285e-21"  ixz="-2.1186003433394039088e-21" iyy="7.3740766846903775533e-05" iyz="1.6940658945086006781e-21" izz="0.00013587762638326352253" />
</inertial>
</link>

<link name="trunk">
<inertial>
<origin xyz="0 0 0" rpy="0 0 0" />
<mass value="1e-9" />
<inertia ixx="0" ixy="0" ixz="0" iyy="0" iyz="0" izz="0" />
</inertial>
</link>
<joint name="trunk_frame" type="fixed">
<origin xyz="-2.3453422050995402063e-18 3.9750852821390819187e-18 0.028600000000000000422" rpy="0 -0 3.141592653589793116" />
<parent link="body" />
<child link="trunk" />
<axis xyz="0 0 0"/>
</joint>

<link name="doubleu">
<!-- Shapes for u -->
<collision>
<origin xyz="-5.6118304447849848422e-20 -0.019099999999999988515 -0.01615000000000000116" rpy="1.570796326794896558 -0 -8.6736173798800430193e-19" />
<geometry>
<box size="0.020000000000000000416 0.02999999999999999889 0.0020000000000000000416" />
</geometry>
</collision>
<!-- Shapes for u -->
<collision>
<origin xyz="-3.42764011618257312e-18 -0.021499999999999980932 -0.016149999999999990752" rpy="-1.57079632679489678 -1.570796326794896336 0" />
<geometry>
<box size="0.020000000000000000416 0.02999999999999999889 0.0020000000000000000416" />
</geometry>
</collision>
<visual>
<origin xyz="0 0 0" rpy="0 -0 0" />
<geometry>
<mesh filename="package:///doubleu_visual.stl"/>
</geometry>
<material name="doubleu_material">
<color rgba="0.97254901960784312376 0.52941176470588235947 0.0039215686274509803377 1.0"/>
</material>
</visual>
<inertial>
<origin xyz="1.4408014362285453874e-18 -0.020299999999999988193 -0.016149999999999994221" rpy="0 0 0"/>
<mass value="0.0083069793159379519409" />
<inertia ixx="2.7836127023230749198e-06" ixy="-2.3232891279722786467e-22"  ixz="-2.643939273087992777e-22" iyy="1.9255029232159787295e-06" iyz="3.254217677579091043e-22" izz="2.7836127023230761904e-06" />
</inertial>
</link>

<link name="platesblock">
<!-- Shapes for horn -->
<!-- Shapes for horn -->
<!-- Shapes for motor -->
<collision>
<origin xyz="8.6166239718256411254e-15 -0.054999999999998779032 0.015000000000000597924" rpy="1.0755285551056161387e-14 1.0525915470999713258e-15 -3.1415926535896607774" />
<geometry>
<box size="0.020000000000000000416 0.02999999999999999889 0.021999999999999998723" />
</geometry>
</collision>
<!-- Shapes for motor -->
<collision>
<origin xyz="1.0549381904244281415e-15 -0.0080000000000000816985 0.015000000000000120876" rpy="5.8113236445266967354e-17 -1.6767316872556788563e-16 1.3224544352081807209e-13" />
<geometry>
<box size="0.020000000000000000416 0.02999999999999999889 0.021999999999999998723" />
</geometry>
</collision>
<!-- Shapes for plate -->
<collision>
<origin xyz="0.013100000000005471851 -0.031499999999997890798 0.015000000000000296083" rpy="1.57079632679489678 -1.2660011927679041098e-14 -1.5707963267947644415" />
<geometry>
<box size="0.072999999999999995448 0.014999999999999999445 0.0020000000000000000416" />
</geometry>
</collision>
<!-- Shapes for plate -->
<collision>
<origin xyz="-0.013199999999995838326 -0.031500000000001839029 0.015000000000000112202" rpy="1.57079632679489678 2.3852447794685490517e-16 -1.5707963267947644415" />
<geometry>
<box size="0.072999999999999995448 0.014999999999999999445 0.0020000000000000000416" />
</geometry>
</collision>
<visual>
<origin xyz="0 0 0" rpy="0 -0 0" />
<geometry>
<mesh filename="package:///platesblock_visual.stl"/>
</geometry>
<material name="platesblock_material">
<color rgba="0.56009960716362361399 0.49194352283988834751 0.41112126355333494798 1.0"/>
</material>
</visual>
<inertial>
<origin xyz="4.832788172101514919e-15 -0.031499999999999486744 0.015037178789082322056" rpy="0 0 0"/>
<mass value="0.041775469947023399775" />
<inertia ixx="2.982790840338027586e-05" ixy="-2.9977310055797639497e-12"  ixz="-7.2055703159494240758e-21" iyy="4.6241019816153209441e-06" iyz="2.2858791554247905585e-19" izz="2.998282908333069102e-05" />
</inertial>
</link>

<link name="leg">
<!-- Shapes for leg -->
<collision>
<origin xyz="-3.1554436208840472873e-33 0.035000000000000003331 -0.0010000000000000008882" rpy="1.570796326794896558 -1.9721522630525295135e-31 0" />
<geometry>
<box size="0.020000000000000000416 0.0020000000000000000416 0.089999999999999996669" />
</geometry>
</collision>
<collision>
<origin xyz="3.1554436208840472873e-33 0.035000000000000003331 0.030999999999999999778" rpy="1.570796326794896558 -1.9721522630525295135e-31 0" />
<geometry>
<box size="0.020000000000000000416 0.0020000000000000000416 0.089999999999999996669" />
</geometry>
</collision>
<collision>
<origin xyz="0 0.089999999999999996669 0.014999999999999999445" rpy="1.570796326794896558 -1.9721522630525295135e-31 0" />
<geometry>
<sphere radius="0.014999999999999999445" />
</geometry>
</collision>
<visual>
<origin xyz="0 0 0" rpy="0 -0 0" />
<geometry>
<mesh filename="package:///leg_visual.stl"/>
</geometry>
<material name="leg_material">
<color rgba="0.97254901960784312376 0.52941176470588235947 0.0039215686274509803377 1.0"/>
</material>
</visual>
<inertial>
<origin xyz="-1.8202203617586485577e-17 0.053378571500788223048 0.014999999999999985567" rpy="0 0 0"/>
<mass value="0.015416190496614969388" />
<inertia ixx="2.1381616736745932914e-05" ixy="6.9451275771952887615e-64"  ixz="7.9284474501317174684e-36" iyy="3.5840706357844897405e-06" iyz="3.1086857399228876182e-24" izz="1.8820387939403849874e-05" />
</inertial>
</link>

<link name="leg1">
<inertial>
<origin xyz="0 0 0" rpy="0 0 0" />
<mass value="1e-9" />
<inertia ixx="0" ixy="0" ixz="0" iyy="0" iyz="0" izz="0" />
</inertial>
</link>
<joint name="leg1_frame" type="fixed">
<origin xyz="-3.8163916471489756077e-17 0.10529999999999997695 0.014999999999999999445" rpy="1.570796326794896336 -3.3306690735923213114e-16 3.141592653589793116" />
<parent link="leg" />
<child link="leg1" />
<axis xyz="0 0 0"/>
</joint>

<joint name="leg1_c" type="revolute">
<origin xyz="9.6866958898544908152e-15 -0.062999999999998917977 1.0408340855860842566e-17" rpy="1.0750081380628314585e-14 1.0525915471023481637e-15 3.141592653589678541" />
<parent link="platesblock" />
<child link="leg" />
<axis xyz="0 0 1"/>
<limit effort="1" velocity="12" lower="0.0" upper="3.1415926" />
<joint_properties friction="0.0"/>
</joint>

<joint name="leg1_b" type="revolute">
<origin xyz="0.014999999999999995975 -0.040599999999999969447 -0.016149999999999987282" rpy="-1.0842021724855001199e-16 -1.5707963267948819031 0" />
<parent link="doubleu" />
<child link="platesblock" />
<axis xyz="0 0 1"/>
<limit effort="1" velocity="12" lower="-1.570796326794896558" upper="1.570796326794896558"/>
<joint_properties friction="0.0"/>
</joint>

<joint name="leg1_a" type="revolute">
<origin xyz="-0.048499999999999994504 -8.1857264022655584768e-18 -0.00069999999999999923395" rpy="-3.1415926535897917837 3.0486171210481177259e-16 1.5778380874476707341" />
<parent link="body" />
<child link="doubleu" />
<axis xyz="0 0 1"/>
<limit effort="1" velocity="12" lower="-1.570796326794896558" upper="1.570796326794896558"/>
<joint_properties friction="0.0"/>
</joint>

<link name="doubleu_2">
<!-- Shapes for u -->
<collision>
<origin xyz="3.6998338880284845059e-47 -0.019100000000000002393 -0.01499999999999999771" rpy="1.570796326794896558 2.1280679529546364129e-33 4.336808689942017736e-19" />
<geometry>
<box size="0.020000000000000000416 0.02999999999999999889 0.0020000000000000000416" />
</geometry>
</collision>
<!-- Shapes for u -->
<collision>
<origin xyz="-5.0931134309983860753e-17 -0.021500000000000015626 -0.014999999999999995975" rpy="-1.570796326794896558 -1.5707963267948925612 0" />
<geometry>
<box size="0.020000000000000000416 0.02999999999999999889 0.0020000000000000000416" />
</geometry>
</collision>
<visual>
<origin xyz="0 0 0" rpy="0 -0 0" />
<geometry>
<mesh filename="package:///doubleu_2_visual.stl"/>
</geometry>
<material name="doubleu_2_material">
<color rgba="0.97254901960784312376 0.52941176470588235947 0.0039215686274509803377 1.0"/>
</material>
</visual>
<inertial>
<origin xyz="-2.3282301829668469569e-17 -0.020299999999999984723 -0.014999999999999992506" rpy="0 0 0"/>
<mass value="0.0083069793159379519409" />
<inertia ixx="2.7836127023230613673e-06" ixy="-2.1407103490766247123e-21"  ixz="-2.6922189709145116195e-22" iyy="1.9255029232159689886e-06" iyz="5.2197783767117033215e-21" izz="2.7836127023230685671e-06" />
</inertial>
</link>

<link name="platesblock_2">
<!-- Shapes for plate -->
<collision>
<origin xyz="-0.031500000000000083489 0.013199999999999907987 0.015000000000000216285" rpy="1.57079632679489678 9.0812773967385831671e-16 -3.1415926535897900074" />
<geometry>
<box size="0.072999999999999995448 0.014999999999999999445 0.0020000000000000000416" />
</geometry>
</collision>
<!-- Shapes for plate -->
<collision>
<origin xyz="-0.031499999999999958589 -0.013100000000001443823 0.015000000000000252715" rpy="1.57079632679489678 -2.0903417885520592048e-16 -3.1415926535897900074" />
<geometry>
<box size="0.072999999999999995448 0.014999999999999999445 0.0020000000000000000416" />
</geometry>
</collision>
<!-- Shapes for horn -->
<!-- Shapes for horn -->
<!-- Shapes for motor -->
<collision>
<origin xyz="-0.054999999999999993339 -1.5171269225954730984e-15 0.015000000000000224959" rpy="4.0744317642005296073e-15 1.1102230246239089076e-16 1.5707963267949001107" />
<geometry>
<box size="0.020000000000000000416 0.02999999999999999889 0.021999999999999998723" />
</geometry>
</collision>
<!-- Shapes for motor -->
<collision>
<origin xyz="-0.0080000000000000365957 -2.157280059595475121e-17 0.015000000000000245776" rpy="-5.6812193838241073291e-17 -1.1102230246238882e-16 -1.5707963267948932273" />
<geometry>
<box size="0.020000000000000000416 0.02999999999999999889 0.021999999999999998723" />
</geometry>
</collision>
<visual>
<origin xyz="0 0 0" rpy="0 -0 0" />
<geometry>
<mesh filename="package:///platesblock_2_visual.stl"/>
</geometry>
<material name="platesblock_2_material">
<color rgba="0.56009960716362372501 0.49194352283988834751 0.41112126355333494798 1.0"/>
</material>
</visual>
<inertial>
<origin xyz="-0.031500000000000007161 -7.6924032612573872151e-16 0.015037178789082219707" rpy="0 0 0"/>
<mass value="0.041775469947023399775" />
<inertia ixx="4.6241019816153209441e-06" ixy="2.9977342385675577773e-12"  ixz="-5.7704119531699210599e-21" iyy="2.982790840338145493e-05" iyz="5.0230628525349093603e-22" izz="2.9982829083331792163e-05" />
</inertial>
</link>

<link name="leg_2">
<!-- Shapes for leg -->
<collision>
<origin xyz="2.1930333165144130152e-31 0.035000000000000031086 -0.0010000000000000008882" rpy="1.570796326794896558 9.8607613152626475676e-32 0" />
<geometry>
<box size="0.020000000000000000416 0.0020000000000000000416 0.089999999999999996669" />
</geometry>
</collision>
<collision>
<origin xyz="2.2245877527232535155e-31 0.035000000000000031086 0.030999999999999992839" rpy="1.570796326794896558 9.8607613152626475676e-32 0" />
<geometry>
<box size="0.020000000000000000416 0.0020000000000000000416 0.089999999999999996669" />
</geometry>
</collision>
<collision>
<origin xyz="5.6797985175912847888e-31 0.090000000000000024425 0.014999999999999995975" rpy="1.570796326794896558 9.8607613152626475676e-32 0" />
<geometry>
<sphere radius="0.014999999999999999445" />
</geometry>
</collision>
<visual>
<origin xyz="0 0 0" rpy="0 -0 0" />
<geometry>
<mesh filename="package:///leg_2_visual.stl"/>
</geometry>
<material name="leg_2_material">
<color rgba="0.97254901960784312376 0.52941176470588235947 0.0039215686274509803377 1.0"/>
</material>
</visual>
<inertial>
<origin xyz="-1.8202203617586149695e-17 0.053378571500788250803 0.014999999999999982098" rpy="0 0 0"/>
<mass value="0.015416190496614969388" />
<inertia ixx="2.1381616736745932914e-05" ixy="2.2618665648967999069e-35"  ixz="-2.5255665844367521184e-37" iyy="3.5840706357844897405e-06" iyz="-8.1879784877051776605e-34" izz="1.8820387939403843098e-05" />
</inertial>
</link>

<link name="leg2">
<inertial>
<origin xyz="0 0 0" rpy="0 0 0" />
<mass value="1e-9" />
<inertia ixx="0" ixy="0" ixz="0" iyy="0" iyz="0" izz="0" />
</inertial>
</link>
<joint name="leg2_frame" type="fixed">
<origin xyz="-3.6429192995512948983e-17 0.1052999999999999492 0.01499999999999999771" rpy="1.5707963267948958919 -5.5511151202686098547e-17 -3.1415926535897926719" />
<parent link="leg_2" />
<child link="leg2" />
<axis xyz="0 0 0"/>
</joint>

<joint name="leg2_c" type="revolute">
<origin xyz="-0.063000000000000014322 -1.5473733405713119282e-15 -4.336808689942017736e-17" rpy="4.3441812647148931338e-15 3.88578058618604665e-16 1.5707963267949578423" />
<parent link="platesblock_2" />
<child link="leg_2" />
<axis xyz="0 0 1"/>
<limit effort="1" velocity="12" lower="0.0" upper="3.1415926" />
<joint_properties friction="0.0"/>
</joint>

<joint name="leg2_b" type="revolute">
<origin xyz="0.014999999999999819034 -0.040599999999999900058 -0.014999999999999985567" rpy="-1.5707963267948972241 -1.2545389584215661038e-14 1.5707963267948961139" />
<parent link="doubleu_2" />
<child link="platesblock_2" />
<axis xyz="0 0 1"/>
<limit effort="1" velocity="12" lower="-1.570796326794896558" upper="1.570796326794896558"/>
<joint_properties friction="0.0"/>
</joint>

<joint name="leg2_a" type="revolute">
<origin xyz="-2.2903770893756281168e-18 -0.048500000000000001443 -0.00070000000000000270339" rpy="3.1415926535897851224 1.0012515226943914018e-22 -3.1396138859742883653" />
<parent link="body" />
<child link="doubleu_2" />
<axis xyz="0 0 1"/>
<limit effort="1" velocity="12" lower="-1.570796326794896558" upper="1.570796326794896558"/>
<joint_properties friction="0.0"/>
</joint>

<link name="doubleu_3">
<!-- Shapes for u -->
<collision>
<origin xyz="-2.6822294385553387769e-18 0.021499999999999939299 -0.01615000000000000463" rpy="1.5707963267948956698 1.5707963267948947816 0" />
<geometry>
<box size="0.020000000000000000416 0.02999999999999999889 0.0020000000000000000416" />
</geometry>
</collision>
<!-- Shapes for u -->
<collision>
<origin xyz="4.3368086899420129212e-19 0.019100000000000002393 -0.016149999999999997691" rpy="-1.570796326794896558 -0 -4.5441421341288858146e-31" />
<geometry>
<box size="0.020000000000000000416 0.02999999999999999889 0.0020000000000000000416" />
</geometry>
</collision>
<visual>
<origin xyz="0 0 0" rpy="0 -0 0" />
<geometry>
<mesh filename="package:///doubleu_3_visual.stl"/>
</geometry>
<material name="doubleu_3_material">
<color rgba="0.97254901960784312376 0.52941176470588235947 0.0039215686274509803377 1.0"/>
</material>
</visual>
<inertial>
<origin xyz="2.3439535963975522866e-18 0.020299999999999970846 -0.01615000000000000463" rpy="0 0 0"/>
<mass value="0.0083069793159379519409" />
<inertia ixx="2.7836127023230681436e-06" ixy="7.3703985019499361554e-22"  ixz="-5.9536510830443781491e-22" iyy="1.9255029232159761884e-06" iyz="-1.7751443549616606736e-21" izz="2.7836127023230672965e-06" />
</inertial>
</link>

<link name="platesblock_3">
<!-- Shapes for plate -->
<collision>
<origin xyz="-0.031500000000000236144 0.013199999999999389305 0.014999999999999378414" rpy="1.570796326794896336 4.8572257327349553403e-16 -3.1415926535897740202" />
<geometry>
<box size="0.072999999999999995448 0.014999999999999999445 0.0020000000000000000416" />
</geometry>
</collision>
<!-- Shapes for motor -->
<collision>
<origin xyz="-0.054999999999999771294 -2.5064872400090213481e-15 0.014999999999999368006" rpy="-3.9343528435154071676e-15 -3.3306690738513314636e-16 1.5707963267949158759" />
<geometry>
<box size="0.020000000000000000416 0.02999999999999999889 0.021999999999999998723" />
</geometry>
</collision>
<!-- Shapes for motor -->
<collision>
<origin xyz="-0.0079999999999999966971 -1.5492551683459979885e-16 0.014999999999999388822" rpy="-2.775557561563955697e-17 3.3306690738512964579e-16 -1.5707963267948772401" />
<geometry>
<box size="0.020000000000000000416 0.02999999999999999889 0.021999999999999998723" />
</geometry>
</collision>
<!-- Shapes for horn -->
<!-- Shapes for plate -->
<collision>
<origin xyz="-0.031499999999999618583 -0.013100000000001939954 0.014999999999999374944" rpy="1.570796326794896336 1.391248227733393176e-15 -3.1415926535897740202" />
<geometry>
<box size="0.072999999999999995448 0.014999999999999999445 0.0020000000000000000416" />
</geometry>
</collision>
<!-- Shapes for horn -->
<visual>
<origin xyz="0 0 0" rpy="0 -0 0" />
<geometry>
<mesh filename="package:///platesblock_3_visual.stl"/>
</geometry>
<material name="platesblock_3_material">
<color rgba="0.56009960716362372501 0.49194352283988845853 0.41112126355333500349 1.0"/>
</material>
</visual>
<inertial>
<origin xyz="-0.031499999999999896139 -1.3236217981997824079e-15 0.01503717878908138704" rpy="0 0 0"/>
<mass value="0.041775469947023392836" />
<inertia ixx="4.6241019816152955331e-06" ixy="2.9977337956195606218e-12"  ixz="-6.1939284267970712294e-21" iyy="2.9827908403381224537e-05" iyz="-6.4851111831858170387e-21" izz="2.9982829083331602427e-05" />
</inertial>
</link>

<link name="leg_3">
<!-- Shapes for leg -->
<collision>
<origin xyz="-1.7347234759767943833e-18 0.034999999999999982514 -0.00099999999999999915345" rpy="1.570796326794896558 -7.8886090522101180541e-31 6.3108872417680944433e-30" />
<geometry>
<box size="0.020000000000000000416 0.0020000000000000000416 0.089999999999999996669" />
</geometry>
</collision>
<collision>
<origin xyz="-1.7347234759768198055e-18 0.034999999999999982514 0.030999999999999992839" rpy="1.570796326794896558 -7.8886090522101180541e-31 6.3108872417680944433e-30" />
<geometry>
<box size="0.020000000000000000416 0.0020000000000000000416 0.089999999999999996669" />
</geometry>
</collision>
<collision>
<origin xyz="-1.7347234759768070944e-18 0.089999999999999982792 0.01499999999999999771" rpy="1.570796326794896558 -7.8886090522101180541e-31 6.3108872417680944433e-30" />
<geometry>
<sphere radius="0.014999999999999999445" />
</geometry>
</collision>
<visual>
<origin xyz="0 0 0" rpy="0 -0 0" />
<geometry>
<mesh filename="package:///leg_3_visual.stl"/>
</geometry>
<material name="leg_3_material">
<color rgba="0.97254901960784312376 0.52941176470588235947 0.0039215686274509803377 1.0"/>
</material>
</visual>
<inertial>
<origin xyz="-1.9936927093563292672e-17 0.05337857150078820917 0.014999999999999983832" rpy="0 0 0"/>
<mass value="0.015416190496614969388" />
<inertia ixx="2.1381616736745932914e-05" ixy="1.3493697227230506489e-34"  ixz="2.0204532675494016947e-36" iyy="3.5840706357844914346e-06" iyz="-7.7731080520542102208e-23" izz="1.8820387939403843098e-05" />
</inertial>
</link>

<link name="leg3">
<inertial>
<origin xyz="0 0 0" rpy="0 0 0" />
<mass value="1e-9" />
<inertia ixx="0" ixy="0" ixz="0" iyy="0" iyz="0" izz="0" />
</inertial>
</link>
<joint name="leg3_frame" type="fixed">
<origin xyz="-3.8163916471489756077e-17 0.10530000000000006022 0.014999999999999995975" rpy="1.570796326794896558 -1.5777218104420236108e-30 -3.1415926535897926719" />
<parent link="leg_3" />
<child link="leg3" />
<axis xyz="0 0 0"/>
</joint>

<joint name="leg3_c" type="revolute">
<origin xyz="-0.062999999999999639622 -2.6107588313450946771e-15 -1.3877787807814456755e-17" rpy="7.7715611723757526285e-16 -5.0164905648928453635e-15 1.5707963267948472641" />
<parent link="platesblock_3" />
<child link="leg_3" />
<axis xyz="0 0 1"/>
<limit effort="1" velocity="12" lower="0.0" upper="3.1415926" />
<joint_properties friction="0.0"/>
</joint>

<joint name="leg3_b" type="revolute">
<origin xyz="-0.014999999999999994241 0.040599999999999913936 -0.016149999999999973405" rpy="-1.5707963267948987784 -6.4711767589976072281e-15 -1.5707963267948976682" />
<parent link="doubleu_3" />
<child link="platesblock_3" />
<axis xyz="0 0 1"/>
<limit effort="1" velocity="12" lower="-1.570796326794896558" upper="1.570796326794896558"/>
<joint_properties friction="0.0"/>
</joint>

<joint name="leg3_a" type="revolute">
<origin xyz="0.048500000000000029199 9.8662397696180903495e-18 -0.00070000000000000443812" rpy="-3.1415926535897900074 3.1889611596249520989e-15 1.5972933729373051115" />
<parent link="body" />
<child link="doubleu_3" />
<axis xyz="0 0 1"/>
<limit effort="1" velocity="12" lower="-1.570796326794896558" upper="1.570796326794896558"/>
<joint_properties friction="0.0"/>
</joint>

<link name="doubleu_4">
<!-- Shapes for u -->
<collision>
<origin xyz="-4.260480856999038445e-19 0.019099999999999988515 -0.01615000000000000116" rpy="-1.570796326794896558 3.9443045261657063488e-31 6.9388939039072268369e-18" />
<geometry>
<box size="0.020000000000000000416 0.02999999999999999889 0.0020000000000000000416" />
</geometry>
</collision>
<!-- Shapes for u -->
<collision>
<origin xyz="-9.8468455611566692399e-17 0.021499999999999987871 -0.016149999999999983813" rpy="1.57079632679489678 1.5707963267948825692 0" />
<geometry>
<box size="0.020000000000000000416 0.02999999999999999889 0.0020000000000000000416" />
</geometry>
</collision>
<visual>
<origin xyz="0 0 0" rpy="0 -0 0" />
<geometry>
<mesh filename="package:///doubleu_4_visual.stl"/>
</geometry>
<material name="doubleu_4_material">
<color rgba="0.97254901960784312376 0.52941176470588235947 0.0039215686274509803377 1.0"/>
</material>
</visual>
<inertial>
<origin xyz="-4.6260432836370229433e-17 0.020299999999999967376 -0.016149999999999994221" rpy="0 0 0"/>
<mass value="0.0083069793159379519409" />
<inertia ixx="2.7836127023230490853e-06" ixy="4.3385700638230821276e-21"  ixz="1.7419738944523592452e-22" iyy="1.9255029232159685651e-06" iyz="-1.8424871688407283173e-20" izz="2.7836127023230588262e-06" />
</inertial>
</link>

<link name="platesblock_4">
<!-- Shapes for plate -->
<collision>
<origin xyz="-0.031500000000000069611 0.013199999999999876762 0.013500000000000123013" rpy="1.5707963267948921171 -1.3253287356462764786e-15 -3.1415926535897900074" />
<geometry>
<box size="0.072999999999999995448 0.014999999999999999445 0.0020000000000000000416" />
</geometry>
</collision>
<!-- Shapes for plate -->
<collision>
<origin xyz="-0.031500000000000034917 -0.013100000000001429945 0.013499999999999774333" rpy="1.5707963267948921171 5.2041704279304070837e-15 -3.1415926535897900074" />
<geometry>
<box size="0.072999999999999995448 0.014999999999999999445 0.0020000000000000000416" />
</geometry>
</collision>
<!-- Shapes for horn -->
<!-- Shapes for horn -->
<!-- Shapes for motor -->
<collision>
<origin xyz="-0.007999999999999953329 -2.1360298301145037173e-17 0.013500000000000001582" rpy="8.9511731360403778553e-16 5.4124936676086563676e-15 -1.5707963267948932273" />
<geometry>
<box size="0.020000000000000000416 0.02999999999999999889 0.021999999999999998723" />
</geometry>
</collision>
<!-- Shapes for motor -->
<collision>
<origin xyz="-0.055000000000000187628 -1.4995064675572417481e-15 0.013499999999999711883" rpy="-5.3637649877202922691e-15 -4.5181163693942431811e-15 1.5707963267948998887" />
<geometry>
<box size="0.020000000000000000416 0.02999999999999999889 0.021999999999999998723" />
</geometry>
</collision>
<visual>
<origin xyz="0 0 0" rpy="0 -0 0" />
<geometry>
<mesh filename="package:///platesblock_4_visual.stl"/>
</geometry>
<material name="platesblock_4_material">
<color rgba="0.56009960716362372501 0.49194352283988834751 0.41112126355333494798 1.0"/>
</material>
</visual>
<inertial>
<origin xyz="-0.031500000000000062672 -7.6329865757133535394e-16 0.013537178789081862756" rpy="0 0 0"/>
<mass value="0.041775469947023399775" />
<inertia ixx="4.6241019816152904509e-06" ixy="2.997734242816432386e-12"  ixz="-1.2980779916672152696e-19" iyy="2.9827908403381681935e-05" iyz="4.005507510575726007e-22" izz="2.9982829083332022556e-05" />
</inertial>
</link>

<link name="leg_4">
<!-- Shapes for leg -->
<collision>
<origin xyz="4.2914033244023045297e-31 -0.035000000000000003331 0.030999999999999996309" rpy="-1.570796326794896558 -7.8886090522101180541e-31 0" />
<geometry>
<box size="0.020000000000000000416 0.0020000000000000000416 0.089999999999999996669" />
</geometry>
</collision>
<collision>
<origin xyz="4.5438388140730285317e-31 -0.035000000000000003331 -0.0010000000000000043576" rpy="-1.570796326794896558 -7.8886090522101180541e-31 0" />
<geometry>
<box size="0.020000000000000000416 0.0020000000000000000416 0.089999999999999996669" />
</geometry>
</collision>
<collision>
<origin xyz="1.1359597035182569578e-30 -0.089999999999999996669 0.014999999999999995975" rpy="-1.570796326794896558 -7.8886090522101180541e-31 0" />
<geometry>
<sphere radius="0.014999999999999999445" />
</geometry>
</collision>
<visual>
<origin xyz="0 0 0" rpy="0 -0 0" />
<geometry>
<mesh filename="package:///leg_4_visual.stl"/>
</geometry>
<material name="leg_4_material">
<color rgba="0.97254901960784312376 0.52941176470588235947 0.0039215686274509803377 1.0"/>
</material>
</visual>
<inertial>
<origin xyz="-1.8202203617585810731e-17 -0.053378571500788223048 0.015000000000000009853" rpy="0 0 0"/>
<mass value="0.015416190496614969388" />
<inertia ixx="2.1381616736745932914e-05" ixy="-4.5237331297935998138e-35"  ixz="2.0204532675493990219e-36" iyy="3.5840706357844897405e-06" iyz="6.570908891398059428e-33" izz="1.8820387939403849874e-05" />
</inertial>
</link>

<link name="leg4">
<inertial>
<origin xyz="0 0 0" rpy="0 0 0" />
<mass value="1e-9" />
<inertia ixx="0" ixy="0" ixz="0" iyy="0" iyz="0" izz="0" />
</inertial>
</link>
<joint name="leg4_frame" type="fixed">
<origin xyz="-3.6429192995512948983e-17 -0.1052999999999999492 0.01500000000000000118" rpy="1.570796326794896558 1.2621774483536188887e-29 -3.7640226365531159504e-16" />
<parent link="leg_4" />
<child link="leg4" />
<axis xyz="0 0 0"/>
</joint>

<joint name="leg4_c" type="revolute">
<origin xyz="-0.063000000000000014322 -1.4606371667724715735e-15 -0.0014999999999999874545" rpy="5.169475958410841754e-15 4.3515829157150439053e-15 -1.5707963267949756059" />
<parent link="platesblock_4" />
<child link="leg_4" />
<axis xyz="0 0 1"/>
<limit effort="1" velocity="12" lower="0.0" upper="3.1415926" />
<joint_properties friction="0.0"/>
</joint>

<joint name="leg4_b" type="revolute">
<origin xyz="-0.01499999999999981036 0.04059999999999988618 -0.016149999999999976874" rpy="-1.5707963267948970021 -2.3598992662912638568e-14 -1.570796326794896558" />
<parent link="doubleu_4" />
<child link="platesblock_4" />
<axis xyz="0 0 1"/>
<limit effort="1" velocity="12" lower="-1.570796326794896558" upper="1.570796326794896558"/>
<joint_properties friction="0.0"/>
</joint>

<joint name="leg4_a" type="revolute">
<origin xyz="3.794707603699265519e-17 0.048500000000000251243 -0.00070000000000000096867" rpy="-3.1415926535897651384 -5.8572922212664386499e-29 -3.092280065794484667" />
<parent link="body" />
<child link="doubleu_4" />
<axis xyz="0 0 1"/>
<limit effort="1" velocity="12" lower="-1.570796326794896558" upper="1.570796326794896558"/>
<joint_properties friction="0.0"/>
</joint>


</robot>
