<robot name="onshape">
<link name="base">
<visual>
<origin xyz="-0.010000000000000000208 -0.125 1.3877787807814456755e-17" rpy="1.57079632679489678 -0 1.570796326794896558" />
<geometry>
<mesh filename="package:///base.stl"/>
</geometry>
<material name="base_material">
<color rgba="0.61568627450980395466 0.81176470588235294379 0.92941176470588238168 1.0"/>
</material>
</visual>
<collision>
<origin xyz="-0.010000000000000000208 -0.125 1.3877787807814456755e-17" rpy="1.57079632679489678 -0 1.570796326794896558" />
<geometry>
<mesh filename="package:///base.stl"/>
</geometry>
</collision>
<inertial>
<origin xyz="0.00067387932128801404652 0 0.035858035995898429604" rpy="0 0 0"/>
<mass value="1.0125175723561228303" />
<inertia ixx="0.0050063948833493337326" ixy="-4.4318894654038948763e-19"  ixz="-6.2376960104677791756e-06" iyy="0.00047974770084012235884" iyz="7.677497081590269784e-19" izz="0.0046068750516161582551" />
</inertial>
</link>

<link name="branch1">
<visual>
<origin xyz="-0.065000000000000016098 0.045000000000000005274 0.025000000000000001388" rpy="3.141592653589793116 -0 0" />
<geometry>
<mesh filename="package:///branch1.stl"/>
</geometry>
<material name="branch1_material">
<color rgba="0.2313725490196078538 0.38039215686274507888 0.7058823529411765163 1.0"/>
</material>
</visual>
<collision>
<origin xyz="-0.065000000000000016098 0.045000000000000005274 0.025000000000000001388" rpy="3.141592653589793116 -0 0" />
<geometry>
<mesh filename="package:///branch1.stl"/>
</geometry>
</collision>
<inertial>
<origin xyz="-0.032500000000000153766 -0.053385391260156685178 -0.0050000000000000009714" rpy="0 0 0"/>
<mass value="0.12390066204820480988" />
<inertia ixx="0.00017070305209466321377" ixy="-9.7859346890542020275e-05"  ixz="-5.8713323579497821439e-36" iyy="6.9531494545696449945e-05" iyz="0" izz="0.00023816953560622293679" />
</inertial>
</link>

<link name="branch2">
<visual>
<origin xyz="1.3877787807814456755e-17 -0.15177078252031314665 -0.025000000000000001388" rpy="0 -4.8148248609680896326e-34 -1.3877787807814456755e-17" />
<geometry>
<mesh filename="package:///branch2.stl"/>
</geometry>
<material name="branch2_material">
<color rgba="0.91764705882352937127 0.91764705882352937127 0.91764705882352937127 1.0"/>
</material>
</visual>
<collision>
<origin xyz="1.3877787807814456755e-17 -0.15177078252031314665 -0.025000000000000001388" rpy="0 -4.8148248609680896326e-34 -1.3877787807814456755e-17" />
<geometry>
<mesh filename="package:///branch2.stl"/>
</geometry>
</collision>
<inertial>
<origin xyz="0.035328974076700020435 0.041304147573957609996 -0.0043471598284538538748" rpy="0 0 0"/>
<mass value="0.11287599307230634926" />
<inertia ixx="9.4366527777012561133e-05" ixy="-7.2763288808187767871e-05"  ixz="-2.186457386408537913e-06" iyy="7.1533964619043002527e-05" iyz="-2.5562519408665343256e-06" izz="0.00016313290830430931199" />
</inertial>
</link>

<link name="closing_effector_1">
<inertial>
<origin xyz="0 0 0" rpy="0 0 0" />
<mass value="1e-9" />
<inertia ixx="0" ixy="0" ixz="0" iyy="0" iyz="0" izz="0" />
</inertial>
</link>
<joint name="closing_effector_1_frame" type="fixed">
<origin xyz="0.065000000000000016098 0.075993420767853314679 0.0050000000000000027062" rpy="0 -4.8148248609680896326e-34 -1.3877787807814456755e-17" />
<parent link="branch2" />
<child link="closing_effector_1" />
<axis xyz="0 0 0"/>
</joint>

<joint name="passive1" type="revolute">
<origin xyz="-0.065000000000000210387 -0.1067707825203129679 0" rpy="3.141592653589793116 -2.3043122745956649559e-16 -0.61093427862802440753" />
<parent link="branch1" />
<child link="branch2" />
<axis xyz="0 0 1"/>
<limit effort="1" velocity="20" />
<joint_properties friction="0.0"/>
</joint>

<joint name="motor1" type="revolute">
<origin xyz="0.014999999999999995975 -0.059999999999999970024 0.044999999999999991396" rpy="-1.570796326794896336 0.54685095069594424899 1.570796326794896558" />
<parent link="base" />
<child link="branch1" />
<axis xyz="0 0 1"/>
<limit effort="1" velocity="20" />
<joint_properties friction="0.0"/>
</joint>

<link name="branch1_2">
<visual>
<origin xyz="-0.06500000000000000222 -0.045000000000000019151 -0.03500000000000001027" rpy="0 -1.232595164407830946e-32 0" />
<geometry>
<mesh filename="package:///branch1.stl"/>
</geometry>
<material name="branch1_material">
<color rgba="0.2313725490196078538 0.38039215686274507888 0.7058823529411765163 1.0"/>
</material>
</visual>
<collision>
<origin xyz="-0.06500000000000000222 -0.045000000000000019151 -0.03500000000000001027" rpy="0 -1.232595164407830946e-32 0" />
<geometry>
<mesh filename="package:///branch1.stl"/>
</geometry>
</collision>
<inertial>
<origin xyz="-0.032500000000000139888 0.053385391260156699056 -0.0050000000000000079103" rpy="0 0 0"/>
<mass value="0.12390066204820480988" />
<inertia ixx="0.00017070305209466321377" ixy="9.785934689054204738e-05"  ixz="2.1958171337083648393e-36" iyy="6.953149454569647705e-05" iyz="1.2520793617403890956e-36" izz="0.00023816953560622293679" />
</inertial>
</link>

<link name="branch2_2">
<visual>
<origin xyz="0 -0.15177078252031314665 -0.025000000000000001388" rpy="0 -0 1.3877787807814459837e-17" />
<geometry>
<mesh filename="package:///branch2.stl"/>
</geometry>
<material name="branch2_material">
<color rgba="0.91764705882352937127 0.91764705882352937127 0.91764705882352937127 1.0"/>
</material>
</visual>
<collision>
<origin xyz="0 -0.15177078252031314665 -0.025000000000000001388" rpy="0 -0 1.3877787807814459837e-17" />
<geometry>
<mesh filename="package:///branch2.stl"/>
</geometry>
</collision>
<inertial>
<origin xyz="0.035328974076700006557 0.041304147573957609996 -0.0043471598284538538748" rpy="0 0 0"/>
<mass value="0.11287599307230634926" />
<inertia ixx="9.4366527777012534028e-05" ixy="-7.2763288808187754318e-05"  ixz="-2.1864573864085374895e-06" iyy="7.1533964619043002527e-05" iyz="-2.5562519408665343256e-06" izz="0.00016313290830430931199" />
</inertial>
</link>

<link name="closing_effector_2">
<inertial>
<origin xyz="0 0 0" rpy="0 0 0" />
<mass value="1e-9" />
<inertia ixx="0" ixy="0" ixz="0" iyy="0" iyz="0" izz="0" />
</inertial>
</link>
<joint name="closing_effector_2_frame" type="fixed">
<origin xyz="0.06500000000000000222 0.075993420767853286923 0.0050000000000000044409" rpy="3.141592653589793116 -0 1.570796326794896558" />
<parent link="branch2_2" />
<child link="closing_effector_2" />
<axis xyz="0 0 0"/>
</joint>

<link name="effector">
<inertial>
<origin xyz="0 0 0" rpy="0 0 0" />
<mass value="1e-9" />
<inertia ixx="0" ixy="0" ixz="0" iyy="0" iyz="0" izz="0" />
</inertial>
</link>
<joint name="effector_frame" type="fixed">
<origin xyz="0.06500000000000000222 0.075993420767853342435 -0.009999999999999995004" rpy="-3.1415926535897922278 -1.9150136985426451064e-16 2.7755575615628106161e-17" />
<parent link="branch2_2" />
<child link="effector" />
<axis xyz="0 0 0"/>
</joint>

<joint name="passive2" type="revolute">
<origin xyz="-0.065000000000000224265 0.10677078252031299566 -0.010000000000000007147" rpy="-4.1402727141222208915e-16 -5.0706060260327139801e-17 0.61093427862801419348" />
<parent link="branch1_2" />
<child link="branch2_2" />
<axis xyz="0 0 1"/>
<limit effort="1" velocity="20" />
<joint_properties friction="0.0"/>
</joint>

<joint name="motor2" type="revolute">
<origin xyz="0.014999999999999999445 0.059999999999999983902 0.044999999999999991396" rpy="1.570796326794896558 0.54685095069594436001 -1.570796326794896336" />
<parent link="base" />
<child link="branch1_2" />
<axis xyz="0 0 1"/>
<limit effort="1" velocity="20" />
<joint_properties friction="0.0"/>
</joint>


</robot>
