<robot name="onshape">
<link name="base">
<visual>
<origin xyz="-0.010000000000000000208 -0.125 0" rpy="1.570796326794896558 -0 1.570796326794896558" />
<geometry>
<mesh filename="package:///base.stl"/>
</geometry>
<material name="base_material">
<color rgba="0.61568627450980395466 0.81176470588235294379 0.92941176470588238168 1.0"/>
</material>
</visual>
<collision>
<origin xyz="-0.010000000000000000208 -0.125 0" rpy="1.570796326794896558 -0 1.570796326794896558" />
<geometry>
<mesh filename="package:///base.stl"/>
</geometry>
</collision>
<inertial>
<origin xyz="0.00067387932128801751597 0 0.035858035995898415726" rpy="0 0 0"/>
<mass value="1.0125175723561228303" />
<inertia ixx="0.0050063948833493354673" ixy="0"  ixz="-6.2376960104669431541e-06" iyy="0.00047974770084012235884" iyz="0" izz="0.0046068750516161582551" />
</inertial>
</link>

<link name="branch1">
<visual>
<origin xyz="-0.065000000000000029976 0.045000000000000005274 0.025000000000000004857" rpy="3.141592653589793116 -6.1629758220391547298e-33 0" />
<geometry>
<mesh filename="package:///branch1.stl"/>
</geometry>
<material name="branch1_material">
<color rgba="0.2313725490196078538 0.38039215686274507888 0.7058823529411765163 1.0"/>
</material>
</visual>
<collision>
<origin xyz="-0.065000000000000029976 0.045000000000000005274 0.025000000000000004857" rpy="3.141592653589793116 -6.1629758220391547298e-33 0" />
<geometry>
<mesh filename="package:///branch1.stl"/>
</geometry>
</collision>
<inertial>
<origin xyz="-0.032500000000000167644 -0.053385391260156712934 -0.004999999999999997502" rpy="0 0 0"/>
<mass value="0.12390066204820480988" />
<inertia ixx="0.00017070305209466321377" ixy="-9.785934689054204738e-05"  ixz="5.8768770935833259069e-36" iyy="6.953149454569647705e-05" iyz="-4.0312721468899499146e-36" izz="0.00023816953560622293679" />
</inertial>
</link>

<link name="branch2">
<visual>
<origin xyz="-2.7755575615628913511e-17 -0.15177078252031314665 -0.025000000000000001388" rpy="0 -0 5.5511151231257827021e-17" />
<geometry>
<mesh filename="package:///branch2.stl"/>
</geometry>
<material name="branch2_material">
<color rgba="0.91764705882352937127 0.91764705882352937127 0.91764705882352937127 1.0"/>
</material>
</visual>
<collision>
<origin xyz="-2.7755575615628913511e-17 -0.15177078252031314665 -0.025000000000000001388" rpy="0 -0 5.5511151231257827021e-17" />
<geometry>
<mesh filename="package:///branch2.stl"/>
</geometry>
</collision>
<inertial>
<origin xyz="0.035328974076699999618 0.04130414757395764469 -0.0043471598284538538748" rpy="0 0 0"/>
<mass value="0.11287599307230633539" />
<inertia ixx="9.4366527777012534028e-05" ixy="-7.2763288808187767871e-05"  ixz="-2.1864573864085383365e-06" iyy="7.1533964619042975422e-05" iyz="-2.5562519408665347491e-06" izz="0.00016313290830430928488" />
</inertial>
</link>

<link name="closing_effector_1">
<inertial>
<origin xyz="0 0 0" rpy="0 0 0" />
<mass value="1e-9" />
<inertia ixx="0" ixy="0" ixz="0" iyy="0" iyz="0" izz="0" />
</inertial>
</link>
<joint name="closing_effector_1_frame" type="fixed">
<origin xyz="0.064999999999999988343 0.075993420767853286923 0.004999999999999997502" rpy="0 -0 5.5511151231257827021e-17" />
<parent link="branch2" />
<child link="closing_effector_1" />
<axis xyz="0 0 0"/>
</joint>

<joint name="passive1" type="revolute">
<origin xyz="-0.065000000000000224265 -0.10677078252031298178 -5.0306980803327405738e-17" rpy="3.141592653589793116 -2.3755581631045393401e-16 0.6420904266682142536" />
<parent link="branch1" />
<child link="branch2" />
<axis xyz="0 0 1"/>
<limit effort="1" velocity="20" />
<joint_properties friction="0.0"/>
</joint>

<joint name="motor1" type="revolute">
<origin xyz="0.014999999999999999445 -0.060000000000000011657 0.045000000000000012212" rpy="-1.570796326794896558 0.22112146340132790567 1.570796326794896558" />
<parent link="base" />
<child link="branch1" />
<axis xyz="0 0 1"/>
<limit effort="1" velocity="20" />
<joint_properties friction="0.0"/>
</joint>

<link name="branch1_2">
<visual>
<origin xyz="-0.06500000000000000222 -0.045000000000000012212 -0.035000000000000003331" rpy="-1.5407439555097886824e-33 4.1985272787641741597e-32 -2.7755575615628913511e-17" />
<geometry>
<mesh filename="package:///branch1.stl"/>
</geometry>
<material name="branch1_material">
<color rgba="0.2313725490196078538 0.38039215686274507888 0.7058823529411765163 1.0"/>
</material>
</visual>
<collision>
<origin xyz="-0.06500000000000000222 -0.045000000000000012212 -0.035000000000000003331" rpy="-1.5407439555097886824e-33 4.1985272787641741597e-32 -2.7755575615628913511e-17" />
<geometry>
<mesh filename="package:///branch1.stl"/>
</geometry>
</collision>
<inertial>
<origin xyz="-0.032500000000000139888 0.053385391260156705995 -0.0050000000000000009714" rpy="0 0 0"/>
<mass value="0.12390066204820480988" />
<inertia ixx="0.00017070305209466321377" ixy="9.785934689054204738e-05"  ixz="-7.317790405089207469e-36" iyy="6.953149454569647705e-05" iyz="-4.2157816039587116735e-36" izz="0.00023816953560622293679" />
</inertial>
</link>

<link name="branch2_2">
<visual>
<origin xyz="0 -0.1517707825203131744 -0.025000000000000004857" rpy="-6.1629758220391547298e-33 -0 0" />
<geometry>
<mesh filename="package:///branch2.stl"/>
</geometry>
<material name="branch2_material">
<color rgba="0.91764705882352937127 0.91764705882352937127 0.91764705882352937127 1.0"/>
</material>
</visual>
<collision>
<origin xyz="0 -0.1517707825203131744 -0.025000000000000004857" rpy="-6.1629758220391547298e-33 -0 0" />
<geometry>
<mesh filename="package:///branch2.stl"/>
</geometry>
</collision>
<inertial>
<origin xyz="0.035328974076700027374 0.041304147573957616935 -0.0043471598284538573442" rpy="0 0 0"/>
<mass value="0.11287599307230633539" />
<inertia ixx="9.4366527777012534028e-05" ixy="-7.2763288808187767871e-05"  ixz="-2.1864573864085383365e-06" iyy="7.1533964619042975422e-05" iyz="-2.5562519408665347491e-06" izz="0.00016313290830430928488" />
</inertial>
</link>

<link name="closing_effector_2">
<inertial>
<origin xyz="0 0 0" rpy="0 0 0" />
<mass value="1e-9" />
<inertia ixx="0" ixy="0" ixz="0" iyy="0" iyz="0" izz="0" />
</inertial>
</link>
<joint name="closing_effector_2_frame" type="fixed">
<origin xyz="0.065000000000000029976 0.075993420767853286923 0.0050000000000000009714" rpy="3.141592653589793116 6.1629758220391547298e-33 1.570796326794896558" />
<parent link="branch2_2" />
<child link="closing_effector_2" />
<axis xyz="0 0 0"/>
</joint>

<link name="effector">
<inertial>
<origin xyz="0 0 0" rpy="0 0 0" />
<mass value="1e-9" />
<inertia ixx="0" ixy="0" ixz="0" iyy="0" iyz="0" izz="0" />
</inertial>
</link>
<joint name="effector_frame" type="fixed">
<origin xyz="0.065000000000000029976 0.075993420767853286923 -0.010000000000000005412" rpy="3.141592653589793116 -1.7252291750463170016e-17 -5.551115123125917055e-17" />
<parent link="branch2_2" />
<child link="effector" />
<axis xyz="0 0 0"/>
</joint>

<joint name="passive2" type="revolute">
<origin xyz="-0.065000000000000224265 0.10677078252031305117 -0.0099999999999999967387" rpy="9.1577368045060010207e-17 -1.1716466983231724797e-16 -0.64209042666824067691" />
<parent link="branch1_2" />
<child link="branch2_2" />
<axis xyz="0 0 1"/>
<limit effort="1" velocity="20" />
<joint_properties friction="0.0"/>
</joint>

<joint name="motor2" type="revolute">
<origin xyz="0.015000000000000006384 0.05999999999999999778 0.045000000000000005274" rpy="1.570796326794896558 0.22112146340130267586 -1.570796326794896336" />
<parent link="base" />
<child link="branch1_2" />
<axis xyz="0 0 1"/>
<limit effort="1" velocity="20" />
<joint_properties friction="0.0"/>
</joint>


</robot>
