<robot name="megabot">
<link name="center">
<visual>
<origin xyz="0 0 0" rpy="0 -0 0" />
<geometry>
<mesh filename="package:///center.stl"/>
</geometry>
<material name="center_material">
<color rgba="0.91764705882352937127 0.91764705882352937127 0.91764705882352937127 1.0"/>
</material>
</visual>
<collision>
<origin xyz="0 0 0" rpy="0 -0 0" />
<geometry>
<mesh filename="package:///center.stl"/>
</geometry>
</collision>
<inertial>
<origin xyz="6.3338722190923087128e-18 -0.52500000000000091038 0.00010111747709569652795" rpy="0 0 0"/>
<mass value="139.99113879410870709" />
<inertia ixx="23.041997276543963125" ixy="-7.0061685856837680169e-14"  ixz="-1.0041063132080209382e-15" iyy="23.068650072377618443" iyz="-4.5528310731335206555e-16" izz="46.004391019484089043" />
</inertial>
</link>

<link name="base">
<inertial>
<origin xyz="0 0 0" rpy="0 0 0" />
<mass value="1e-9" />
<inertia ixx="0" ixy="0" ixz="0" iyy="0" iyz="0" izz="0" />
</inertial>
</link>
<joint name="base_frame" type="fixed">
<origin xyz="0 -0.52499999999999991118 0.025000000000000105471" rpy="0 -0 -1.570796326794896558" />
<parent link="center" />
<child link="base" />
<axis xyz="0 0 0"/>
</joint>

<link name="cylinder_f">
<visual>
<origin xyz="0.11799999999999999378 -0.035499999999999976019 -7.5794071873447424582e-18" rpy="1.570796326794896558 1.570796326794896336 0" />
<geometry>
<mesh filename="package:///cylinder_f.stl"/>
</geometry>
<material name="cylinder_f_material">
<color rgba="0.26274509803921569651 0.28235294117647058432 0.30196078431372547213 1.0"/>
</material>
</visual>
<collision>
<origin xyz="0.11799999999999999378 -0.035499999999999976019 -7.5794071873447424582e-18" rpy="1.570796326794896558 1.570796326794896336 0" />
<geometry>
<mesh filename="package:///cylinder_f.stl"/>
</geometry>
</collision>
<inertial>
<origin xyz="0.13981491538445647849 -0.034298269917181316291 -3.3207639316941841287e-10" rpy="0 0 0"/>
<mass value="2.7501984867936553059" />
<inertia ixx="0.0053329489546342827636" ixy="-0.0021373023958805169482"  ixz="-9.8161766988590832671e-11" iyy="0.027645758712734874035" iyz="3.3278704863581045429e-12" izz="0.031077682858520978837" />
</inertial>
</link>

<link name="cylinder_m">
<visual>
<origin xyz="9.8607613152626475676e-32 -0.035500000000000087041 -0.33699999999999991074" rpy="1.570796326794896558 -0 -4.9303806576313237838e-32" />
<geometry>
<mesh filename="package:///cylinder_m.stl"/>
</geometry>
<material name="cylinder_m_material">
<color rgba="0.43921568627450979783 0.47450980392156860699 0.50196078431372548323 1.0"/>
</material>
</visual>
<collision>
<origin xyz="9.8607613152626475676e-32 -0.035500000000000087041 -0.33699999999999991074" rpy="1.570796326794896558 -0 -4.9303806576313237838e-32" />
<geometry>
<mesh filename="package:///cylinder_m.stl"/>
</geometry>
</collision>
<inertial>
<origin xyz="-3.8591735189509004646e-09 -4.4177500616027209901e-09 -0.19587031738716759177" rpy="0 0 0"/>
<mass value="2.7499900392833467322" />
<inertia ixx="0.033691032693585303004" ixy="8.2582413614763970083e-11"  ixz="1.661389369319447981e-09" iyy="0.033689032919998092297" iyz="1.8671001117315319735e-09" izz="0.00028217358044707141311" />
</inertial>
</link>

<link name="l1_cl1_1">
<inertial>
<origin xyz="0 0 0" rpy="0 0 0" />
<mass value="1e-9" />
<inertia ixx="0" ixy="0" ixz="0" iyy="0" iyz="0" izz="0" />
</inertial>
</link>
<joint name="l1_cl1_1_frame" type="fixed">
<origin xyz="3.9443045261050590271e-31 -5.5511151231257827021e-17 -0.0094999999999999529265" rpy="-1.570796326794896558 -1.570796326794896558 0" />
<parent link="cylinder_m" />
<child link="l1_cl1_1" />
<axis xyz="0 0 0"/>
</joint>

<joint name="l1_c1" type="prismatic">
<origin xyz="0.45949999999998797362 -1.1102230246251565404e-16 6.1825161828937341108e-16" rpy="1.5839373449339953594e-15 1.5707963267948945596 0" />
<parent link="cylinder_f" />
<child link="cylinder_m" />
<axis xyz="0 0 1"/>
<limit effort="1" velocity="20" lower="0.036499999999999997724" upper="0.23649999999999998801"/>
<joint_properties friction="0.0"/>
</joint>

<joint name="l1_r1" type="revolute">
<origin xyz="-0.44000000000000022427 -0.33500000000000051958 1.0755285551056216311e-16" rpy="3.1415926535897926719 1.5635084904658178429e-16 -1.433149400124039019" />
<parent link="center" />
<child link="cylinder_f" />
<axis xyz="0 0 1"/>
<limit effort="1" velocity="20" lower="0" upper="1.570796326794896558"/>
<joint_properties friction="0.0"/>
</joint>

<link name="hip">
<visual>
<origin xyz="-0.064999999999999946709 6.9388939039072283776e-17 0" rpy="-3.141592653589793116 2.1292708054995839713e-33 1.4026548169033361248e-18" />
<geometry>
<mesh filename="package:///hip.stl"/>
</geometry>
<material name="hip_material">
<color rgba="0.64705882352941179736 0.64705882352941179736 0.64705882352941179736 1.0"/>
</material>
</visual>
<collision>
<origin xyz="-0.064999999999999946709 6.9388939039072283776e-17 0" rpy="-3.141592653589793116 2.1292708054995839713e-33 1.4026548169033361248e-18" />
<geometry>
<mesh filename="package:///hip.stl"/>
</geometry>
</collision>
<inertial>
<origin xyz="-0.037541790219322815347 7.9719590942789279216e-17 -0.016489821713258367292" rpy="0 0 0"/>
<mass value="3.5999999924476484559" />
<inertia ixx="0.008251918124949891159" ixy="8.4275254086615150484e-18"  ixz="-0.012050372331242007948" iyy="0.12642361670580493094" iyz="-1.6902512795895079997e-20" izz="0.12867127256930088741" />
</inertial>
</link>

<link name="l1_cl1_2">
<inertial>
<origin xyz="0 0 0" rpy="0 0 0" />
<mass value="1e-9" />
<inertia ixx="0" ixy="0" ixz="0" iyy="0" iyz="0" izz="0" />
</inertial>
</link>
<joint name="l1_cl1_2_frame" type="fixed">
<origin xyz="0.27499999999999968914 -3.8163916471489756077e-17 0.030000000000000005829" rpy="-1.570796326794896336 1.3210496169531085786e-16 -3.141592653589793116" />
<parent link="hip" />
<child link="l1_cl1_2" />
<axis xyz="0 0 0"/>
</joint>

<link name="femur">
<visual>
<origin xyz="0 0.24250000000000004885 -0.02999999999999999542" rpy="-1.570796326794896558 3.0946996760254941323e-18 -8.6235818173649333721e-17" />
<geometry>
<mesh filename="package:///femur.stl"/>
</geometry>
<material name="femur_material">
<color rgba="0.30196078431372547213 0.30196078431372547213 0.30196078431372547213 1.0"/>
</material>
</visual>
<collision>
<origin xyz="0 0.24250000000000004885 -0.02999999999999999542" rpy="-1.570796326794896558 3.0946996760254941323e-18 -8.6235818173649333721e-17" />
<geometry>
<mesh filename="package:///femur.stl"/>
</geometry>
</collision>
<inertial>
<origin xyz="0.0064139711381488986527 0.24592748545031795082 0.019999999210131440969" rpy="0 0 0"/>
<mass value="3.5999999984857375956" />
<inertia ixx="0.081390757679679695547" ixy="0.00019915715025974964759"  ixz="-1.1782772634003157811e-10" iyy="0.0080793091134649629159" iyz="-5.7702360015011599957e-11" izz="0.074691636552088186418" />
</inertial>
</link>

<link name="l1_cl2_2">
<inertial>
<origin xyz="0 0 0" rpy="0 0 0" />
<mass value="1e-9" />
<inertia ixx="0" ixy="0" ixz="0" iyy="0" iyz="0" izz="0" />
</inertial>
</link>
<joint name="l1_cl2_2_frame" type="fixed">
<origin xyz="-0.012999999999999900524 0.38400000000000011902 0.019999999999999868577" rpy="1.57079632679489678 -3.1065260723641943717e-16 -7.2676014924345448372e-17" />
<parent link="femur" />
<child link="l1_cl2_2" />
<axis xyz="0 0 0"/>
</joint>

<link name="tibia">
<visual>
<origin xyz="-0.37499999999999955591 1.1102230246251565404e-16 5.1174342541315809285e-17" rpy="1.570796326794896558 -3.9138801235724877684e-17 4.8226990568344779528e-18" />
<geometry>
<mesh filename="package:///tibia.stl"/>
</geometry>
<material name="tibia_material">
<color rgba="0.91764705882352937127 0.91764705882352937127 0.91764705882352937127 1.0"/>
</material>
</visual>
<collision>
<origin xyz="-0.37499999999999955591 1.1102230246251565404e-16 5.1174342541315809285e-17" rpy="1.570796326794896558 -3.9138801235724877684e-17 4.8226990568344779528e-18" />
<geometry>
<mesh filename="package:///tibia.stl"/>
</geometry>
</collision>
<inertial>
<origin xyz="-0.37488809734909772642 1.1114600217438099323e-16 -0.019999999999999955314" rpy="0 0 0"/>
<mass value="3.999999995260936192" />
<inertia ixx="0.002964268310106591385" ixy="-4.8658439552630644711e-19"  ixz="-2.9054278394703431879e-17" iyy="0.21898012548041431713" iyz="3.8338588683335416207e-19" izz="0.21991734751853581065" />
</inertial>
</link>

<link name="l1_cl4_2">
<inertial>
<origin xyz="0 0 0" rpy="0 0 0" />
<mass value="1e-9" />
<inertia ixx="0" ixy="0" ixz="0" iyy="0" iyz="0" izz="0" />
</inertial>
</link>
<joint name="l1_cl4_2_frame" type="fixed">
<origin xyz="-0.44999999999999973355 1.1102230246251565404e-16 -0.01999999999999997613" rpy="-1.570796326794896558 3.3141074150295935238e-16 -3.141592653589793116" />
<parent link="tibia" />
<child link="l1_cl4_2" />
<axis xyz="0 0 0"/>
</joint>

<link name="foot">
<visual>
<origin xyz="0 -0.34750000000000025313 -0.029999999999999971134" rpy="-1.570796326794896558 -1.2153413210559988909e-17 -3.0571007039178816691e-17" />
<geometry>
<mesh filename="package:///foot.stl"/>
</geometry>
<material name="foot_material">
<color rgba="0.30196078431372547213 0.30196078431372547213 0.30196078431372547213 1.0"/>
</material>
</visual>
<collision>
<origin xyz="0 -0.34750000000000025313 -0.029999999999999971134" rpy="-1.570796326794896558 -1.2153413210559988909e-17 -3.0571007039178816691e-17" />
<geometry>
<mesh filename="package:///foot.stl"/>
</geometry>
</collision>
<inertial>
<origin xyz="0.0067478869293355111386 -0.37109593568577259326 0.019999996975168576885" rpy="0 0 0"/>
<mass value="3.6499999959578990349" />
<inertia ixx="0.27434960237524297355" ixy="-0.00053748086186041594495"  ixz="3.1806926845897259146e-08" iyy="0.0056481174471628946276" iyz="3.3810617632467876003e-09" izz="0.27004492242811067859" />
</inertial>
</link>

<link name="l1_cl3_2">
<inertial>
<origin xyz="0 0 0" rpy="0 0 0" />
<mass value="1e-9" />
<inertia ixx="0" ixy="0" ixz="0" iyy="0" iyz="0" izz="0" />
</inertial>
</link>
<joint name="l1_cl3_2_frame" type="fixed">
<origin xyz="2.2204460492503130808e-16 -0.50500000000000033751 0.020000000000000052458" rpy="-1.570796326794896558 5.6756690386264740081e-16 3.141592653589793116" />
<parent link="foot" />
<child link="l1_cl3_2" />
<axis xyz="0 0 0"/>
</joint>

<link name="leg_1">
<inertial>
<origin xyz="0 0 0" rpy="0 0 0" />
<mass value="1e-9" />
<inertia ixx="0" ixy="0" ixz="0" iyy="0" iyz="0" izz="0" />
</inertial>
</link>
<joint name="leg_1_frame" type="fixed">
<origin xyz="0.0050000000000001154632 -1.0075000000000002842 0.019999999999999972661" rpy="-1.570796326794896558 -1.6917805583653369258e-16 -2.2741465533138622391e-17" />
<parent link="foot" />
<child link="leg_1" />
<axis xyz="0 0 0"/>
</joint>

<joint name="l1_r5" type="revolute">
<origin xyz="-0.74999999999999977796 0 -0.040000000000000153488" rpy="-1.3519093026149155761e-15 1.7849770799465899747e-15 2.8740211174390379867" />
<parent link="tibia" />
<child link="foot" />
<axis xyz="0 0 1"/>
<limit effort="1" velocity="20" lower="-1.570796326794896558" upper="1.570796326794896558"/>
<joint_properties friction="0.0"/>
</joint>

<joint name="l1_r4" type="revolute">
<origin xyz="3.3306690738754696213e-16 0.4899999999999998801 -1.9949319973733281586e-17" rpy="3.141592653589793116 9.8174925928936230861e-16 -0.41532921468036260171" />
<parent link="femur" />
<child link="tibia" />
<axis xyz="0 0 1"/>
<limit effort="1" velocity="20" lower="-1.570796326794896558" upper="1.570796326794896558"/>
<joint_properties friction="0.0"/>
</joint>

<joint name="l1_r3" type="revolute">
<origin xyz="0.12499999999999977796 -0.019999999999999826944 -0.039999999999999993894" rpy="-1.5707963267948956698 0.46670348839401742946 -4.1843661536946179153e-16" />
<parent link="hip" />
<child link="femur" />
<axis xyz="0 0 1"/>
<limit effort="1" velocity="20" lower="-1.570796326794896558" upper="1.570796326794896558"/>
<joint_properties friction="0.0"/>
</joint>

<link name="cylinder_f_2">
<visual>
<origin xyz="0.11800000000000032685 -0.035500000000000087041 2.0816681711721685133e-17" rpy="1.57079632679489678 1.570796326794896336 0" />
<geometry>
<mesh filename="package:///cylinder_f.stl"/>
</geometry>
<material name="cylinder_f_material">
<color rgba="0.26274509803921569651 0.28235294117647058432 0.30196078431372547213 1.0"/>
</material>
</visual>
<collision>
<origin xyz="0.11800000000000032685 -0.035500000000000087041 2.0816681711721685133e-17" rpy="1.57079632679489678 1.570796326794896336 0" />
<geometry>
<mesh filename="package:///cylinder_f.stl"/>
</geometry>
</collision>
<inertial>
<origin xyz="0.13981491538445681155 -0.034298269917181427313 -3.3207636541149091596e-10" rpy="0 0 0"/>
<mass value="2.7501984867936553059" />
<inertia ixx="0.0053329489546342827636" ixy="-0.002137302395880519984"  ixz="-9.8161767676940126626e-11" iyy="0.027645758712734874035" iyz="3.3278699099812075553e-12" izz="0.031077682858520971898" />
</inertial>
</link>

<link name="cylinder_m_2">
<visual>
<origin xyz="1.0408340855860842566e-16 -0.035500000000000087041 -0.33699999999999996625" rpy="1.570796326794896558 1.886669407534622951e-17 -3.5086200163234459422e-18" />
<geometry>
<mesh filename="package:///cylinder_m.stl"/>
</geometry>
<material name="cylinder_m_material">
<color rgba="0.43921568627450979783 0.47450980392156860699 0.50196078431372548323 1.0"/>
</material>
</visual>
<collision>
<origin xyz="1.0408340855860842566e-16 -0.035500000000000087041 -0.33699999999999996625" rpy="1.570796326794896558 1.886669407534622951e-17 -3.5086200163234459422e-18" />
<geometry>
<mesh filename="package:///cylinder_m.stl"/>
</geometry>
</collision>
<inertial>
<origin xyz="-3.8591734289841603758e-09 -4.4177500407860392784e-09 -0.19587031738716764728" rpy="0 0 0"/>
<mass value="2.7499900392833467322" />
<inertia ixx="0.033691032693585289126" ixy="8.2582415169767090518e-11"  ixz="1.6613893686520594309e-09" iyy="0.033689032919998092297" iyz="1.8671001072293028775e-09" izz="0.00028217358044707152153" />
</inertial>
</link>

<link name="l1_cl2_1">
<inertial>
<origin xyz="0 0 0" rpy="0 0 0" />
<mass value="1e-9" />
<inertia ixx="0" ixy="0" ixz="0" iyy="0" iyz="0" izz="0" />
</inertial>
</link>
<joint name="l1_cl2_1_frame" type="fixed">
<origin xyz="2.185751579730776939e-16 0 -0.0094999999999999529265" rpy="-1.57079632679489678 -1.5707963267948952257 0" />
<parent link="cylinder_m_2" />
<child link="l1_cl2_1" />
<axis xyz="0 0 0"/>
</joint>

<joint name="l1_c2" type="prismatic">
<origin xyz="0.45949999999999657785 4.4408920985006261617e-16 -4.0141501234103316165e-15" rpy="-9.0093448943835609015e-16 1.5707963267948890085 0" />
<parent link="cylinder_f_2" />
<child link="cylinder_m_2" />
<axis xyz="0 0 1"/>
<limit effort="1" velocity="20" lower="0.036499999999999997724" upper="0.23649999999999998801"/>
<joint_properties friction="0.0"/>
</joint>

<joint name="l1_r6" type="revolute">
<origin xyz="-0.41000000000000014211 1.2836953722228372499e-16 -0.095000000000000014988" rpy="1.57079632679489678 0.67750901888019166019 1.6143341020285157788e-15" />
<parent link="hip" />
<child link="cylinder_f_2" />
<axis xyz="0 0 1"/>
<limit effort="1" velocity="20" lower="0" upper="1.570796326794896558"/>
<joint_properties friction="0.0"/>
</joint>

<link name="cylinder_support">
<visual>
<origin xyz="1.1102230246251565404e-16 0.24249999999999993783 -0.029999999999999991951" rpy="-1.570796326794896558 2.5998066656079383138e-17 3.4087984692540397887e-17" />
<geometry>
<mesh filename="package:///cylinder_support.stl"/>
</geometry>
<material name="cylinder_support_material">
<color rgba="0.64705882352941179736 0.64705882352941179736 0.64705882352941179736 1.0"/>
</material>
</visual>
<collision>
<origin xyz="1.1102230246251565404e-16 0.24249999999999993783 -0.029999999999999991951" rpy="-1.570796326794896558 2.5998066656079383138e-17 3.4087984692540397887e-17" />
<geometry>
<mesh filename="package:///cylinder_support.stl"/>
</geometry>
</collision>
<inertial>
<origin xyz="0.0054354402573498364695 0.29828794955270288014 0.020152917736522085734" rpy="0 0 0"/>
<mass value="3.4500000005941280357" />
<inertia ixx="0.12216401720555165877" ixy="-0.00014225366187223010021"  ixz="-9.0029635204973182904e-06" iyy="0.0080920294153276912247" iyz="1.7561733914077016388e-05" izz="0.11536233747142544959" />
</inertial>
</link>

<link name="l1_cl4_1">
<inertial>
<origin xyz="0 0 0" rpy="0 0 0" />
<mass value="1e-9" />
<inertia ixx="0" ixy="0" ixz="0" iyy="0" iyz="0" izz="0" />
</inertial>
</link>
<joint name="l1_cl4_1_frame" type="fixed">
<origin xyz="2.2204460492503130808e-16 0.59000000000000007994 0.020000000000000097561" rpy="1.5707963267948961139 -2.5998066656079383138e-17 -3.141592653589793116" />
<parent link="cylinder_support" />
<child link="l1_cl4_1" />
<axis xyz="0 0 0"/>
</joint>

<link name="cylinder_f_3">
<visual>
<origin xyz="0.11799999999999999378 -0.035500000000000309086 9.3675067702747583098e-17" rpy="1.570796326794896558 1.570796326794896336 0" />
<geometry>
<mesh filename="package:///cylinder_f.stl"/>
</geometry>
<material name="cylinder_f_material">
<color rgba="0.26274509803921569651 0.28235294117647058432 0.30196078431372547213 1.0"/>
</material>
</visual>
<collision>
<origin xyz="0.11799999999999999378 -0.035500000000000309086 9.3675067702747583098e-17" rpy="1.570796326794896558 1.570796326794896336 0" />
<geometry>
<mesh filename="package:///cylinder_f.stl"/>
</geometry>
</collision>
<inertial>
<origin xyz="0.13981491538445647849 -0.034298269917181649358 -3.3207629249676689418e-10" rpy="0 0 0"/>
<mass value="2.7501984867936553059" />
<inertia ixx="0.005332948954634286233" ixy="-0.0021373023958805147798"  ixz="-9.8161765175356193863e-11" iyy="0.027645758712734867096" iyz="3.3278702732288130367e-12" izz="0.031077682858520971898" />
</inertial>
</link>

<link name="cylinder_m_3">
<visual>
<origin xyz="6.5919492087118669588e-17 -0.035499999999999864997 -0.33700000000000018829" rpy="1.57079632679489678 6.7250703923294601717e-17 -1.057346987715704451e-17" />
<geometry>
<mesh filename="package:///cylinder_m.stl"/>
</geometry>
<material name="cylinder_m_material">
<color rgba="0.43921568627450979783 0.47450980392156860699 0.50196078431372548323 1.0"/>
</material>
</visual>
<collision>
<origin xyz="6.5919492087118669588e-17 -0.035499999999999864997 -0.33700000000000018829" rpy="1.57079632679489678 6.7250703923294601717e-17 -1.057346987715704451e-17" />
<geometry>
<mesh filename="package:///cylinder_m.stl"/>
</geometry>
</collision>
<inertial>
<origin xyz="-3.8591734444676265209e-09 -4.4177498187414343533e-09 -0.19587031738716789708" rpy="0 0 0"/>
<mass value="2.7499900392833467322" />
<inertia ixx="0.033691032693585303004" ixy="8.2582416289215144561e-11"  ixz="1.6613893670644396871e-09" iyy="0.033689032919998106175" iyz="1.8671001147114331731e-09" izz="0.00028217358044707152153" />
</inertial>
</link>

<link name="l1_cl3_1">
<inertial>
<origin xyz="0 0 0" rpy="0 0 0" />
<mass value="1e-9" />
<inertia ixx="0" ixy="0" ixz="0" iyy="0" iyz="0" izz="0" />
</inertial>
</link>
<joint name="l1_cl3_1_frame" type="fixed">
<origin xyz="1.7347234759768070944e-17 2.2204460492503130808e-16 -0.0095000000000002859935" rpy="1.57079632679489678 1.570796326794896558 0" />
<parent link="cylinder_m_3" />
<child link="l1_cl3_1" />
<axis xyz="0 0 0"/>
</joint>

<joint name="l1_c3" type="prismatic">
<origin xyz="0.45949999999999446842 2.664535259100375697e-15 -2.1649348980190552538e-15" rpy="-3.1415926535897926719 -1.570796326794896336 0" />
<parent link="cylinder_f_3" />
<child link="cylinder_m_3" />
<axis xyz="0 0 1"/>
<limit effort="1" velocity="20" lower="0.036499999999999997724" upper="0.23649999999999998801"/>
<joint_properties friction="0.0"/>
</joint>

<joint name="l1_r8" type="revolute">
<origin xyz="-9.9920072216264088638e-16 0.3925000000000082867 0.020000000000004944378" rpy="2.2502960553273176995e-14 3.8695720785859771458e-14 -3.0319894979551293979" />
<parent link="cylinder_support" />
<child link="cylinder_f_3" />
<axis xyz="0 0 1"/>
<limit effort="1" velocity="20" lower="0" upper="1.570796326794896558"/>
<joint_properties friction="0.0"/>
</joint>

<joint name="l1_r7" type="revolute">
<origin xyz="-0.12500000000000066613 -0.020000000000001065537 -0.040000000000004920508" rpy="-1.5707963267949032193 0.79185786258827683959 -1.7629992927556572186e-14" />
<parent link="hip" />
<child link="cylinder_support" />
<axis xyz="0 0 1"/>
<limit effort="1" velocity="20" lower="-1.570796326794896558" upper="1.570796326794896558"/>
<joint_properties friction="0.0"/>
</joint>

<joint name="l1_r2" type="revolute">
<origin xyz="-0.49999999999999811262 -1.0249999999999999112 0.030000000000000102973" rpy="3.141592653589793116 -3.0599681271326078913e-18 1.0975074011255603335" />
<parent link="center" />
<child link="hip" />
<axis xyz="0 0 1"/>
<limit effort="1" velocity="20" lower="0" upper="1.570796326794896558"/>
<joint_properties friction="0.0"/>
</joint>

<link name="cylinder_f_4">
<visual>
<origin xyz="0.11799999999999995215 -0.035499999999999976019 -7.5794071873448164139e-18" rpy="1.570796326794896558 1.570796326794896336 0" />
<geometry>
<mesh filename="package:///cylinder_f.stl"/>
</geometry>
<material name="cylinder_f_material">
<color rgba="0.26274509803921569651 0.28235294117647058432 0.30196078431372547213 1.0"/>
</material>
</visual>
<collision>
<origin xyz="0.11799999999999995215 -0.035499999999999976019 -7.5794071873448164139e-18" rpy="1.570796326794896558 1.570796326794896336 0" />
<geometry>
<mesh filename="package:///cylinder_f.stl"/>
</geometry>
</collision>
<inertial>
<origin xyz="0.13981491538445645073 -0.034298269917181316291 -3.3207639316941841287e-10" rpy="0 0 0"/>
<mass value="2.7501984867936553059" />
<inertia ixx="0.0053329489546342844983" ixy="-0.0021373023958805165146"  ixz="-9.8161766988590845596e-11" iyy="0.027645758712734874035" iyz="3.3278704863581037351e-12" izz="0.031077682858520978837" />
</inertial>
</link>

<link name="cylinder_m_4">
<visual>
<origin xyz="1.9721522630525295135e-31 -0.035500000000000003775 -0.33700000000000002176" rpy="1.570796326794896558 1.1567032209398916525e-31 9.4504229327609979771e-32" />
<geometry>
<mesh filename="package:///cylinder_m.stl"/>
</geometry>
<material name="cylinder_m_material">
<color rgba="0.43921568627450979783 0.47450980392156860699 0.50196078431372548323 1.0"/>
</material>
</visual>
<collision>
<origin xyz="1.9721522630525295135e-31 -0.035500000000000003775 -0.33700000000000002176" rpy="1.570796326794896558 1.1567032209398916525e-31 9.4504229327609979771e-32" />
<geometry>
<mesh filename="package:///cylinder_m.stl"/>
</geometry>
</collision>
<inertial>
<origin xyz="-3.8591735189509004646e-09 -4.4177499575193124315e-09 -0.19587031738716767504" rpy="0 0 0"/>
<mass value="2.7499900392833467322" />
<inertia ixx="0.033691032693585303004" ixy="8.2582413614764008857e-11"  ixz="1.6613893693194481878e-09" iyy="0.033689032919998120053" iyz="1.8671001098841361584e-09" izz="0.00028217358044707152153" />
</inertial>
</link>

<link name="l2_cl1_1">
<inertial>
<origin xyz="0 0 0" rpy="0 0 0" />
<mass value="1e-9" />
<inertia ixx="0" ixy="0" ixz="0" iyy="0" iyz="0" izz="0" />
</inertial>
</link>
<joint name="l2_cl1_1_frame" type="fixed">
<origin xyz="9.8607613152626475676e-32 0 -0.00950000000000011946" rpy="-1.5707963267948970021 -1.5707963267948954478 0" />
<parent link="cylinder_m_4" />
<child link="l2_cl1_1" />
<axis xyz="0 0 0"/>
</joint>

<joint name="l2_c1" type="prismatic">
<origin xyz="0.45950000080081426779 5.5511151231257827021e-17 7.9271560598040820885e-17" rpy="1.7200196442759473774e-16 1.5707963267948950037 0" />
<parent link="cylinder_f_4" />
<child link="cylinder_m_4" />
<axis xyz="0 0 1"/>
<limit effort="1" velocity="20" lower="0.036499999999999997724" upper="0.23649999999999998801"/>
<joint_properties friction="0.0"/>
</joint>

<joint name="l2_r1" type="revolute">
<origin xyz="0.18999999999999978018 -0.084999999999999686917 1.0755285551056200288e-16" rpy="3.141592653589793116 -7.1582305289484675573e-17 -2.9958563448520303396" />
<parent link="center" />
<child link="cylinder_f_4" />
<axis xyz="0 0 1"/>
<limit effort="1" velocity="20" lower="0" upper="1.570796326794896558"/>
<joint_properties friction="0.0"/>
</joint>

<link name="hip_2">
<visual>
<origin xyz="-0.064999999999999946709 0 0" rpy="3.141592653589793116 8.3045748532547253976e-33 4.8951601774258117911e-17" />
<geometry>
<mesh filename="package:///hip.stl"/>
</geometry>
<material name="hip_material">
<color rgba="0.64705882352941179736 0.64705882352941179736 0.64705882352941179736 1.0"/>
</material>
</visual>
<collision>
<origin xyz="-0.064999999999999946709 0 0" rpy="3.141592653589793116 8.3045748532547253976e-33 4.8951601774258117911e-17" />
<geometry>
<mesh filename="package:///hip.stl"/>
</geometry>
</collision>
<inertial>
<origin xyz="-0.037541790219322815347 1.1636260864122325996e-17 -0.016489821713258367292" rpy="0 0 0"/>
<mass value="3.5999999924476484559" />
<inertia ixx="0.008251918124949891159" ixy="-6.7346763890778698227e-18"  ixz="-0.012050372331242007948" iyy="0.12642361670580481992" iyz="-5.898850275904999478e-19" izz="0.12867127256930088741" />
</inertial>
</link>

<link name="l2_cl1_2">
<inertial>
<origin xyz="0 0 0" rpy="0 0 0" />
<mass value="1e-9" />
<inertia ixx="0" ixy="0" ixz="0" iyy="0" iyz="0" izz="0" />
</inertial>
</link>
<joint name="l2_cl1_2_frame" type="fixed">
<origin xyz="0.27500000000000013323 -5.5511151231257827021e-17 0.02999999999999999889" rpy="-1.570796326794896336 5.8999261890123592136e-17 -3.1415926535897926719" />
<parent link="hip_2" />
<child link="l2_cl1_2" />
<axis xyz="0 0 0"/>
</joint>

<link name="femur_2">
<visual>
<origin xyz="1.1102230246251565404e-16 0.24249999999999993783 -0.02999999999999999889" rpy="-1.570796326794896558 3.7640571610048617592e-17 -2.8329941078235042007e-17" />
<geometry>
<mesh filename="package:///femur.stl"/>
</geometry>
<material name="femur_material">
<color rgba="0.30196078431372547213 0.30196078431372547213 0.30196078431372547213 1.0"/>
</material>
</visual>
<collision>
<origin xyz="1.1102230246251565404e-16 0.24249999999999993783 -0.02999999999999999889" rpy="-1.570796326794896558 3.7640571610048617592e-17 -2.8329941078235042007e-17" />
<geometry>
<mesh filename="package:///femur.stl"/>
</geometry>
</collision>
<inertial>
<origin xyz="0.0064139711381490157466 0.2459274854503178398 0.019999999210131444438" rpy="0 0 0"/>
<mass value="3.5999999984857375956" />
<inertia ixx="0.081390757679679667791" ixy="0.00019915715025975468913"  ixz="-1.1782771929609031175e-10" iyy="0.0080793091134649663854" iyz="-5.7702353462483375179e-11" izz="0.074691636552088214174" />
</inertial>
</link>

<link name="l2_cl2_2">
<inertial>
<origin xyz="0 0 0" rpy="0 0 0" />
<mass value="1e-9" />
<inertia ixx="0" ixy="0" ixz="0" iyy="0" iyz="0" izz="0" />
</inertial>
</link>
<joint name="l2_cl2_2_frame" type="fixed">
<origin xyz="-0.012999999999999706235 0.3840000000000000635 0.019999999999999962252" rpy="1.570796326794896558 1.4889190345132270871e-16 3.4804450275470782491e-17" />
<parent link="femur_2" />
<child link="l2_cl2_2" />
<axis xyz="0 0 0"/>
</joint>

<link name="tibia_2">
<visual>
<origin xyz="-0.375 1.1102230246251565404e-16 -2.7755575615628913511e-17" rpy="1.570796326794896558 4.2741071574808236446e-17 -1.6971291910097104505e-18" />
<geometry>
<mesh filename="package:///tibia.stl"/>
</geometry>
<material name="tibia_material">
<color rgba="0.91764705882352937127 0.91764705882352937127 0.91764705882352937127 1.0"/>
</material>
</visual>
<collision>
<origin xyz="-0.375 1.1102230246251565404e-16 -2.7755575615628913511e-17" rpy="1.570796326794896558 4.2741071574808236446e-17 -1.6971291910097104505e-18" />
<geometry>
<mesh filename="package:///tibia.stl"/>
</geometry>
</collision>
<inertial>
<origin xyz="-0.37488809734909817051 1.1114479453434903223e-16 -0.020000000000000035111" rpy="0 0 0"/>
<mass value="3.999999995260936192" />
<inertia ixx="0.002964268310106591385" ixy="-2.7944209990812290425e-18"  ixz="-3.4852320575368970176e-18" iyy="0.21898012548041437264" iyz="8.2139724605974744883e-19" izz="0.21991734751853581065" />
</inertial>
</link>

<link name="l2_cl4_2">
<inertial>
<origin xyz="0 0 0" rpy="0 0 0" />
<mass value="1e-9" />
<inertia ixx="0" ixy="0" ixz="0" iyy="0" iyz="0" izz="0" />
</inertial>
</link>
<joint name="l2_cl4_2_frame" type="fixed">
<origin xyz="-0.44999999999999984457 2.2204460492503130808e-16 -0.020000000000000073275" rpy="-1.570796326794896558 -2.4707137350212771429e-16 3.141592653589793116" />
<parent link="tibia_2" />
<child link="l2_cl4_2" />
<axis xyz="0 0 0"/>
</joint>

<link name="foot_2">
<visual>
<origin xyz="0 -0.34749999999999992006 -0.029999999999999915623" rpy="-1.570796326794896558 -6.2185194285329831581e-17 -1.3989175284959775803e-17" />
<geometry>
<mesh filename="package:///foot.stl"/>
</geometry>
<material name="foot_material">
<color rgba="0.30196078431372547213 0.30196078431372547213 0.30196078431372547213 1.0"/>
</material>
</visual>
<collision>
<origin xyz="0 -0.34749999999999992006 -0.029999999999999915623" rpy="-1.570796326794896558 -6.2185194285329831581e-17 -1.3989175284959775803e-17" />
<geometry>
<mesh filename="package:///foot.stl"/>
</geometry>
</collision>
<inertial>
<origin xyz="0.0067478869293355076692 -0.37109593568577226019 0.019999996975168632396" rpy="0 0 0"/>
<mass value="3.6499999959578990349" />
<inertia ixx="0.27434960237524297355" ixy="-0.00053748086186041041552"  ixz="3.1806926860671009289e-08" iyy="0.0056481174471628911582" iyz="3.3810617590836024666e-09" izz="0.27004492242811067859" />
</inertial>
</link>

<link name="l2_cl3_2">
<inertial>
<origin xyz="0 0 0" rpy="0 0 0" />
<mass value="1e-9" />
<inertia ixx="0" ixy="0" ixz="0" iyy="0" iyz="0" izz="0" />
</inertial>
</link>
<joint name="l2_cl3_2_frame" type="fixed">
<origin xyz="2.2204460492503130808e-16 -0.50499999999999989342 0.020000000000000239808" rpy="-1.57079632679489678 -1.1929415864978866461e-15 3.141592653589793116" />
<parent link="foot_2" />
<child link="l2_cl3_2" />
<axis xyz="0 0 0"/>
</joint>

<link name="leg_2">
<inertial>
<origin xyz="0 0 0" rpy="0 0 0" />
<mass value="1e-9" />
<inertia ixx="0" ixy="0" ixz="0" iyy="0" iyz="0" izz="0" />
</inertial>
</link>
<joint name="leg_2_frame" type="fixed">
<origin xyz="0.0050000000000001154632 -1.0074999999999998401 0.020000000000000073275" rpy="-1.570796326794896558 5.1401146879175467997e-16 -6.56223101404631036e-17" />
<parent link="foot_2" />
<child link="leg_2" />
<axis xyz="0 0 0"/>
</joint>

<joint name="l2_r5" type="revolute">
<origin xyz="-0.74999999999999988898 1.1102230246251565404e-16 -0.040000000000000091038" rpy="2.540715062519631097e-16 -2.943161147134564992e-15 2.864108120675692426" />
<parent link="tibia_2" />
<child link="foot_2" />
<axis xyz="0 0 1"/>
<limit effort="1" velocity="20" lower="-1.570796326794896558" upper="1.570796326794896558"/>
<joint_properties friction="0.0"/>
</joint>

<joint name="l2_r4" type="revolute">
<origin xyz="-6.9388939039072283776e-16 0.48999999999999993561 6.6613381477509392425e-16" rpy="3.1415926535897926719 -1.0377520731080190909e-14 -0.41532921468034922352" />
<parent link="femur_2" />
<child link="tibia_2" />
<axis xyz="0 0 1"/>
<limit effort="1" velocity="20" lower="-1.570796326794896558" upper="1.570796326794896558"/>
<joint_properties friction="0.0"/>
</joint>

<joint name="l2_r3" type="revolute">
<origin xyz="0.12499999999999977796 -0.019999999999999934497 -0.040000000000000042466" rpy="-1.5707963267948978903 0.46670348839402453489 -6.6556317978518277341e-15" />
<parent link="hip_2" />
<child link="femur_2" />
<axis xyz="0 0 1"/>
<limit effort="1" velocity="20" lower="-1.570796326794896558" upper="1.570796326794896558"/>
<joint_properties friction="0.0"/>
</joint>

<link name="cylinder_f_5">
<visual>
<origin xyz="0.11799999999999982725 -0.035499999999999976019 -1.1102230246251565404e-16" rpy="1.570796326794896558 1.570796326794896336 0" />
<geometry>
<mesh filename="package:///cylinder_f.stl"/>
</geometry>
<material name="cylinder_f_material">
<color rgba="0.26274509803921569651 0.28235294117647058432 0.30196078431372547213 1.0"/>
</material>
</visual>
<collision>
<origin xyz="0.11799999999999982725 -0.035499999999999976019 -1.1102230246251565404e-16" rpy="1.570796326794896558 1.570796326794896336 0" />
<geometry>
<mesh filename="package:///cylinder_f.stl"/>
</geometry>
</collision>
<inertial>
<origin xyz="0.13981491538445631195 -0.034298269917181316291 -3.3207649563829175283e-10" rpy="0 0 0"/>
<mass value="2.7501984867936553059" />
<inertia ixx="0.0053329489546342827636" ixy="-0.0021373023958805152135"  ixz="-9.8161765432521721996e-11" iyy="0.027645758712734874035" iyz="3.3278685785900115395e-12" izz="0.031077682858520978837" />
</inertial>
</link>

<link name="cylinder_m_5">
<visual>
<origin xyz="5.5511151231257827021e-17 -0.035499999999999976019 -0.33699999999999996625" rpy="1.57079632679489678 -1.879131309382622872e-18 1.4993238605764382848e-17" />
<geometry>
<mesh filename="package:///cylinder_m.stl"/>
</geometry>
<material name="cylinder_m_material">
<color rgba="0.43921568627450979783 0.47450980392156860699 0.50196078431372548323 1.0"/>
</material>
</visual>
<collision>
<origin xyz="5.5511151231257827021e-17 -0.035499999999999976019 -0.33699999999999996625" rpy="1.57079632679489678 -1.879131309382622872e-18 1.4993238605764382848e-17" />
<geometry>
<mesh filename="package:///cylinder_m.stl"/>
</geometry>
</collision>
<inertial>
<origin xyz="-3.8591734559429451674e-09 -4.4177499505804185276e-09 -0.19587031738716767504" rpy="0 0 0"/>
<mass value="2.7499900392833467322" />
<inertia ixx="0.033691032693585303004" ixy="8.2582412740735376078e-11"  ixz="1.6613893694006527153e-09" iyy="0.033689032919998106175" iyz="1.8671001143293948441e-09" izz="0.00028217358044707141311" />
</inertial>
</link>

<link name="l2_cl2_1">
<inertial>
<origin xyz="0 0 0" rpy="0 0 0" />
<mass value="1e-9" />
<inertia ixx="0" ixy="0" ixz="0" iyy="0" iyz="0" izz="0" />
</inertial>
</link>
<joint name="l2_cl2_1_frame" type="fixed">
<origin xyz="1.1102230246251565404e-16 0 -0.0094999999999999945599" rpy="-1.570796326794896336 -1.5707963267948927832 0" />
<parent link="cylinder_m_5" />
<child link="l2_cl2_1" />
<axis xyz="0 0 0"/>
</joint>

<joint name="l2_c2" type="prismatic">
<origin xyz="0.4595000000000002971 1.7763568394002504647e-15 2.3869795029440865619e-15" rpy="3.4013390378763887518e-16 1.5707963267948954478 0" />
<parent link="cylinder_f_5" />
<child link="cylinder_m_5" />
<axis xyz="0 0 1"/>
<limit effort="1" velocity="20" lower="0.036499999999999997724" upper="0.23649999999999998801"/>
<joint_properties friction="0.0"/>
</joint>

<joint name="l2_r6" type="revolute">
<origin xyz="-0.409999999999999587 -4.9960036108132044319e-16 -0.094999999999999723554" rpy="1.5707963267948961139 0.67750901888017123209 1.6649055331051427788e-15" />
<parent link="hip_2" />
<child link="cylinder_f_5" />
<axis xyz="0 0 1"/>
<limit effort="1" velocity="20" lower="0" upper="1.570796326794896558"/>
<joint_properties friction="0.0"/>
</joint>

<link name="cylinder_support_2">
<visual>
<origin xyz="0 0.24249999999999999334 -0.02999999999999999889" rpy="-1.57079632679489678 -3.8722440647568061082e-17 -8.0504667115897289053e-17" />
<geometry>
<mesh filename="package:///cylinder_support.stl"/>
</geometry>
<material name="cylinder_support_material">
<color rgba="0.64705882352941179736 0.64705882352941179736 0.64705882352941179736 1.0"/>
</material>
</visual>
<collision>
<origin xyz="0 0.24249999999999999334 -0.02999999999999999889" rpy="-1.57079632679489678 -3.8722440647568061082e-17 -8.0504667115897289053e-17" />
<geometry>
<mesh filename="package:///cylinder_support.stl"/>
</geometry>
</collision>
<inertial>
<origin xyz="0.0054354402573497133042 0.29828794955270293565 0.020152917736522071857" rpy="0 0 0"/>
<mass value="3.4500000005941280357" />
<inertia ixx="0.12216401720555165877" ixy="-0.00014225366187224563141"  ixz="-9.0029635204942283142e-06" iyy="0.0080920294153276912247" iyz="1.7561733914075972843e-05" izz="0.11536233747142544959" />
</inertial>
</link>

<link name="l2_cl4_1">
<inertial>
<origin xyz="0 0 0" rpy="0 0 0" />
<mass value="1e-9" />
<inertia ixx="0" ixy="0" ixz="0" iyy="0" iyz="0" izz="0" />
</inertial>
</link>
<joint name="l2_cl4_1_frame" type="fixed">
<origin xyz="-5.5511151231257827021e-17 0.5899999999999994138 0.019999999999999712452" rpy="1.5707963267948938935 -7.2175292787070834916e-15 -3.141592653589793116" />
<parent link="cylinder_support_2" />
<child link="l2_cl4_1" />
<axis xyz="0 0 0"/>
</joint>

<link name="cylinder_f_6">
<visual>
<origin xyz="0.117999999999999855 -0.035499999999999976019 0" rpy="1.570796326794896558 1.570796326794896336 0" />
<geometry>
<mesh filename="package:///cylinder_f.stl"/>
</geometry>
<material name="cylinder_f_material">
<color rgba="0.26274509803921569651 0.28235294117647058432 0.30196078431372547213 1.0"/>
</material>
</visual>
<collision>
<origin xyz="0.117999999999999855 -0.035499999999999976019 0" rpy="1.570796326794896558 1.570796326794896336 0" />
<geometry>
<mesh filename="package:///cylinder_f.stl"/>
</geometry>
</collision>
<inertial>
<origin xyz="0.13981491538445633971 -0.034298269917181316291 -3.3207638551520895901e-10" rpy="0 0 0"/>
<mass value="2.7501984867936553059" />
<inertia ixx="0.0053329489546342844983" ixy="-0.0021373023958805169482"  ixz="-9.8161767281440182798e-11" iyy="0.027645758712734874035" iyz="3.3278695842325063235e-12" izz="0.031077682858520978837" />
</inertial>
</link>

<link name="cylinder_m_6">
<visual>
<origin xyz="5.5511151231257827021e-17 -0.035499999999999976019 -0.33700000000000002176" rpy="1.570796326794896558 4.5760566046941206107e-17 -7.8548650933901609232e-17" />
<geometry>
<mesh filename="package:///cylinder_m.stl"/>
</geometry>
<material name="cylinder_m_material">
<color rgba="0.43921568627450979783 0.47450980392156860699 0.50196078431372548323 1.0"/>
</material>
</visual>
<collision>
<origin xyz="5.5511151231257827021e-17 -0.035499999999999976019 -0.33700000000000002176" rpy="1.570796326794896558 4.5760566046941206107e-17 -7.8548650933901609232e-17" />
<geometry>
<mesh filename="package:///cylinder_m.stl"/>
</geometry>
</collision>
<inertial>
<origin xyz="-3.8591734697806329134e-09 -4.4177499575193124315e-09 -0.19587031738716767504" rpy="0 0 0"/>
<mass value="2.7499900392833467322" />
<inertia ixx="0.033691032693585303004" ixy="8.2582410687957025466e-11"  ixz="1.6613893677656402787e-09" iyy="0.033689032919998106175" iyz="1.8671001102665268663e-09" izz="0.00028217358044707152153" />
</inertial>
</link>

<link name="l2_cl3_1">
<inertial>
<origin xyz="0 0 0" rpy="0 0 0" />
<mass value="1e-9" />
<inertia ixx="0" ixy="0" ixz="0" iyy="0" iyz="0" izz="0" />
</inertial>
</link>
<joint name="l2_cl3_1_frame" type="fixed">
<origin xyz="5.5511151231257827021e-17 0 -0.0094999999999998419042" rpy="1.570796326794896558 1.5707963267948956698 0" />
<parent link="cylinder_m_6" />
<child link="l2_cl3_1" />
<axis xyz="0 0 0"/>
</joint>

<joint name="l2_c3" type="prismatic">
<origin xyz="0.45950000000000035261 -5.5511151231257827021e-15 1.0824674490095276269e-14" rpy="3.1415926535897802374 -1.5707963267948861219 0" />
<parent link="cylinder_f_6" />
<child link="cylinder_m_6" />
<axis xyz="0 0 1"/>
<limit effort="1" velocity="20" lower="0.036499999999999997724" upper="0.23649999999999998801"/>
<joint_properties friction="0.0"/>
</joint>

<joint name="l2_r8" type="revolute">
<origin xyz="1.9984014443252817728e-15 0.3924999999999977951 0.020000000000001932898" rpy="1.6800334858317061208e-14 2.9059497397685848373e-14 -3.0259156815526302431" />
<parent link="cylinder_support_2" />
<child link="cylinder_f_6" />
<axis xyz="0 0 1"/>
<limit effort="1" velocity="20" lower="0" upper="1.570796326794896558"/>
<joint_properties friction="0.0"/>
</joint>

<joint name="l2_r7" type="revolute">
<origin xyz="-0.1249999999999990008 -0.020000000000000600631 -0.039999999999999875933" rpy="-1.5707963267948978903 0.79185786258829393702 1.7746994413076171452e-15" />
<parent link="hip_2" />
<child link="cylinder_support_2" />
<axis xyz="0 0 1"/>
<limit effort="1" velocity="20" lower="-1.570796326794896558" upper="1.570796326794896558"/>
<joint_properties friction="0.0"/>
</joint>

<joint name="l2_r2" type="revolute">
<origin xyz="-0.50000000000000022204 -0.024999999999999900774 0.030000000000000106443" rpy="3.141592653589793116 -1.153529978888650079e-16 -0.47328893068798266741" />
<parent link="center" />
<child link="hip_2" />
<axis xyz="0 0 1"/>
<limit effort="1" velocity="20" lower="0" upper="1.570796326794896558"/>
<joint_properties friction="0.0"/>
</joint>

<link name="cylinder_f_7">
<visual>
<origin xyz="0.11799999999999988276 -0.03550000000000003153 -7.5794071873447671101e-18" rpy="1.570796326794896558 1.570796326794896336 0" />
<geometry>
<mesh filename="package:///cylinder_f.stl"/>
</geometry>
<material name="cylinder_f_material">
<color rgba="0.26274509803921569651 0.28235294117647058432 0.30196078431372547213 1.0"/>
</material>
</visual>
<collision>
<origin xyz="0.11799999999999988276 -0.03550000000000003153 -7.5794071873447671101e-18" rpy="1.570796326794896558 1.570796326794896336 0" />
<geometry>
<mesh filename="package:///cylinder_f.stl"/>
</geometry>
</collision>
<inertial>
<origin xyz="0.13981491538445636746 -0.034298269917181371802 -3.3207639316941841287e-10" rpy="0 0 0"/>
<mass value="2.7501984867936553059" />
<inertia ixx="0.0053329489546342844983" ixy="-0.0021373023958805156472"  ixz="-9.8161766988590845596e-11" iyy="0.027645758712734867096" iyz="3.327870486358104139e-12" izz="0.031077682858520978837" />
</inertial>
</link>

<link name="cylinder_m_7">
<visual>
<origin xyz="0 -0.035499999999999976019 -0.33700000000000002176" rpy="1.570796326794896558 9.043972781070106331e-33 4.1603958583083471083e-31" />
<geometry>
<mesh filename="package:///cylinder_m.stl"/>
</geometry>
<material name="cylinder_m_material">
<color rgba="0.43921568627450979783 0.47450980392156860699 0.50196078431372548323 1.0"/>
</material>
</visual>
<collision>
<origin xyz="0 -0.035499999999999976019 -0.33700000000000002176" rpy="1.570796326794896558 9.043972781070106331e-33 4.1603958583083471083e-31" />
<geometry>
<mesh filename="package:///cylinder_m.stl"/>
</geometry>
</collision>
<inertial>
<origin xyz="-3.8591735189509004646e-09 -4.4177499367026307198e-09 -0.19587031738716773055" rpy="0 0 0"/>
<mass value="2.7499900392833467322" />
<inertia ixx="0.033691032693585303004" ixy="8.2582413614763995933e-11"  ixz="1.661389369319447981e-09" iyy="0.033689032919998106175" iyz="1.8671001119457895366e-09" izz="0.00028217358044707141311" />
</inertial>
</link>

<link name="l3_cl1_1">
<inertial>
<origin xyz="0 0 0" rpy="0 0 0" />
<mass value="1e-9" />
<inertia ixx="0" ixy="0" ixz="0" iyy="0" iyz="0" izz="0" />
</inertial>
</link>
<joint name="l3_cl1_1_frame" type="fixed">
<origin xyz="3.9443045261050590271e-31 0 -0.0094999999999998974154" rpy="-1.570796326794896558 -1.570796326794896558 0" />
<parent link="cylinder_m_7" />
<child link="l3_cl1_1" />
<axis xyz="0 0 0"/>
</joint>

<joint name="l3_c1" type="prismatic">
<origin xyz="0.45949999999999835421 5.5511151231257827021e-16 -5.3489951134560793381e-16" rpy="-1.0364157664800512015e-16 1.5707963267948930053 0" />
<parent link="cylinder_f_7" />
<child link="cylinder_m_7" />
<axis xyz="0 0 1"/>
<limit effort="1" velocity="20" lower="0.036499999999999997724" upper="0.23649999999999998801"/>
<joint_properties friction="0.0"/>
</joint>

<joint name="l3_r1" type="revolute">
<origin xyz="0.43999999999999966915 -0.71499999999999852562 1.0755285551057660913e-16" rpy="-3.1415926535897904515 1.1842700142122408505e-24 1.7165326330347507877" />
<parent link="center" />
<child link="cylinder_f_7" />
<axis xyz="0 0 1"/>
<limit effort="1" velocity="20" lower="0" upper="1.570796326794896558"/>
<joint_properties friction="0.0"/>
</joint>

<link name="hip_3">
<visual>
<origin xyz="-0.065000000000000057732 -5.5511151231257827021e-17 -3.4694469519536141888e-18" rpy="-3.141592653589793116 2.8886558778009399796e-32 6.2530459710418313398e-17" />
<geometry>
<mesh filename="package:///hip.stl"/>
</geometry>
<material name="hip_material">
<color rgba="0.64705882352941179736 0.64705882352941179736 0.64705882352941179736 1.0"/>
</material>
</visual>
<collision>
<origin xyz="-0.065000000000000057732 -5.5511151231257827021e-17 -3.4694469519536141888e-18" rpy="-3.141592653589793116 2.8886558778009399796e-32 6.2530459710418313398e-17" />
<geometry>
<mesh filename="package:///hip.stl"/>
</geometry>
</collision>
<inertial>
<origin xyz="-0.037541790219322933309 -4.3502039237342398407e-17 -0.016489821713258370761" rpy="0 0 0"/>
<mass value="3.5999999924476484559" />
<inertia ixx="0.0082519181249498876896" ixy="1.3491562420603985364e-17"  ixz="-0.012050372331242006213" iyy="0.12642361670580487543" iyz="-7.5351532155426757141e-19" izz="0.12867127256930088741" />
</inertial>
</link>

<link name="l3_cl1_2">
<inertial>
<origin xyz="0 0 0" rpy="0 0 0" />
<mass value="1e-9" />
<inertia ixx="0" ixy="0" ixz="0" iyy="0" iyz="0" izz="0" />
</inertial>
</link>
<joint name="l3_cl1_2_frame" type="fixed">
<origin xyz="0.27499999999999985567 0 0.02999999999999999889" rpy="-1.570796326794896558 -4.4993958156375995493e-29 3.1415926535897926719" />
<parent link="hip_3" />
<child link="l3_cl1_2" />
<axis xyz="0 0 0"/>
</joint>

<link name="femur_3">
<visual>
<origin xyz="6.2450045135165055399e-17 0.24249999999999999334 -0.030000000000000082157" rpy="-1.570796326794896558 1.1872526750047945867e-17 -3.9678324370449078024e-17" />
<geometry>
<mesh filename="package:///femur.stl"/>
</geometry>
<material name="femur_material">
<color rgba="0.30196078431372547213 0.30196078431372547213 0.30196078431372547213 1.0"/>
</material>
</visual>
<collision>
<origin xyz="6.2450045135165055399e-17 0.24249999999999999334 -0.030000000000000082157" rpy="-1.570796326794896558 1.1872526750047945867e-17 -3.9678324370449078024e-17" />
<geometry>
<mesh filename="package:///femur.stl"/>
</geometry>
</collision>
<inertial>
<origin xyz="0.0064139711381489611028 0.24592748545031786755 0.019999999210131354233" rpy="0 0 0"/>
<mass value="3.5999999984857375956" />
<inertia ixx="0.081390757679679695547" ixy="0.00019915715025975300862"  ixz="-1.1782772807414813616e-10" iyy="0.0080793091134649663854" iyz="-5.7702355129366214829e-11" izz="0.074691636552088186418" />
</inertial>
</link>

<link name="l3_cl2_2">
<inertial>
<origin xyz="0 0 0" rpy="0 0 0" />
<mass value="1e-9" />
<inertia ixx="0" ixy="0" ixz="0" iyy="0" iyz="0" izz="0" />
</inertial>
</link>
<joint name="l3_cl2_2_frame" type="fixed">
<origin xyz="-0.012999999999999886646 0.38400000000000011902 0.019999999999999962252" rpy="1.5707963267948985564 -4.1117207255037771762e-15 -1.2965582971512668008e-16" />
<parent link="femur_3" />
<child link="l3_cl2_2" />
<axis xyz="0 0 0"/>
</joint>

<link name="tibia_3">
<visual>
<origin xyz="-0.37499999999999994449 0 1.1102230246251565404e-16" rpy="1.570796326794896558 -5.5750872601585572328e-18 -3.8869177208562170798e-18" />
<geometry>
<mesh filename="package:///tibia.stl"/>
</geometry>
<material name="tibia_material">
<color rgba="0.91764705882352937127 0.91764705882352937127 0.91764705882352937127 1.0"/>
</material>
</visual>
<collision>
<origin xyz="-0.37499999999999994449 0 1.1102230246251565404e-16" rpy="1.570796326794896558 -5.5750872601585572328e-18 -3.8869177208562170798e-18" />
<geometry>
<mesh filename="package:///tibia.stl"/>
</geometry>
</collision>
<inertial>
<origin xyz="-0.374888097349098115 1.3583694420707371452e-19 -0.019999999999999896333" rpy="0 0 0"/>
<mass value="3.999999995260936192" />
<inertia ixx="0.0029642683101065922524" ixy="1.5692839397477093541e-18"  ixz="4.4900516408415715296e-18" iyy="0.21898012548041437264" iyz="2.5129709551588322733e-19" izz="0.21991734751853581065" />
</inertial>
</link>

<link name="l3_cl4_2">
<inertial>
<origin xyz="0 0 0" rpy="0 0 0" />
<mass value="1e-9" />
<inertia ixx="0" ixy="0" ixz="0" iyy="0" iyz="0" izz="0" />
</inertial>
</link>
<joint name="l3_cl4_2_frame" type="fixed">
<origin xyz="-0.44999999999999990008 0 -0.019999999999999962252" rpy="-1.570796326794896558 2.2761969218518991462e-16 3.141592653589793116" />
<parent link="tibia_3" />
<child link="l3_cl4_2" />
<axis xyz="0 0 0"/>
</joint>

<link name="foot_3">
<visual>
<origin xyz="0 -0.34750000000000014211 -0.030000000000000026645" rpy="-1.570796326794896558 2.1731986716189348718e-17 -2.1446760487773670345e-17" />
<geometry>
<mesh filename="package:///foot.stl"/>
</geometry>
<material name="foot_material">
<color rgba="0.30196078431372547213 0.30196078431372547213 0.30196078431372547213 1.0"/>
</material>
</visual>
<collision>
<origin xyz="0 -0.34750000000000014211 -0.030000000000000026645" rpy="-1.570796326794896558 2.1731986716189348718e-17 -2.1446760487773670345e-17" />
<geometry>
<mesh filename="package:///foot.stl"/>
</geometry>
</collision>
<inertial>
<origin xyz="0.0067478869293355128733 -0.37109593568577248224 0.019999996975168528313" rpy="0 0 0"/>
<mass value="3.6499999959578990349" />
<inertia ixx="0.27434960237524297355" ixy="-0.00053748086186041312603"  ixz="3.1806926850434205839e-08" iyy="0.0056481174471628928929" iyz="3.3810617509643573973e-09" izz="0.27004492242811078961" />
</inertial>
</link>

<link name="l3_cl3_2">
<inertial>
<origin xyz="0 0 0" rpy="0 0 0" />
<mass value="1e-9" />
<inertia ixx="0" ixy="0" ixz="0" iyy="0" iyz="0" izz="0" />
</inertial>
</link>
<joint name="l3_cl3_2_frame" type="fixed">
<origin xyz="0 -0.50500000000000011546 0.020000000000000073275" rpy="-1.570796326794896558 -5.2716164429158478364e-17 -3.141592653589793116" />
<parent link="foot_3" />
<child link="l3_cl3_2" />
<axis xyz="0 0 0"/>
</joint>

<link name="leg_3">
<inertial>
<origin xyz="0 0 0" rpy="0 0 0" />
<mass value="1e-9" />
<inertia ixx="0" ixy="0" ixz="0" iyy="0" iyz="0" izz="0" />
</inertial>
</link>
<joint name="leg_3_frame" type="fixed">
<origin xyz="0.0049999999999998934186 -1.0075000000000000622 0.019999999999999962252" rpy="-1.57079632679489678 3.302719205854473423e-16 9.2428687743045562232e-17" />
<parent link="foot_3" />
<child link="leg_3" />
<axis xyz="0 0 0"/>
</joint>

<joint name="l3_r5" type="revolute">
<origin xyz="-0.75 0 -0.040000000000000146549" rpy="-1.2697226730609879444e-15 1.6397443508591157754e-15 2.8709603175061224611" />
<parent link="tibia_3" />
<child link="foot_3" />
<axis xyz="0 0 1"/>
<limit effort="1" velocity="20" lower="-1.570796326794896558" upper="1.570796326794896558"/>
<joint_properties friction="0.0"/>
</joint>

<joint name="l3_r4" type="revolute">
<origin xyz="4.1633363423443370266e-16 0.48999999999999943601 1.6098233857064769836e-15" rpy="-3.1415926535897895633 -1.1450887451527557207e-14 -0.41532921468024797118" />
<parent link="femur_3" />
<child link="tibia_3" />
<axis xyz="0 0 1"/>
<limit effort="1" velocity="20" lower="-1.570796326794896558" upper="1.570796326794896558"/>
<joint_properties friction="0.0"/>
</joint>

<joint name="l3_r3" type="revolute">
<origin xyz="0.12499999999999167333 -0.01999999999999840794 -0.040000000000000097977" rpy="-1.5707963267948958919 0.46670348839395431328 -8.9960860717502477891e-15" />
<parent link="hip_3" />
<child link="femur_3" />
<axis xyz="0 0 1"/>
<limit effort="1" velocity="20" lower="-1.570796326794896558" upper="1.570796326794896558"/>
<joint_properties friction="0.0"/>
</joint>

<link name="cylinder_f_8">
<visual>
<origin xyz="0.11799999999999993827 -0.035500000000000087041 0" rpy="1.57079632679489678 1.570796326794896336 0" />
<geometry>
<mesh filename="package:///cylinder_f.stl"/>
</geometry>
<material name="cylinder_f_material">
<color rgba="0.26274509803921569651 0.28235294117647058432 0.30196078431372547213 1.0"/>
</material>
</visual>
<collision>
<origin xyz="0.11799999999999993827 -0.035500000000000087041 0" rpy="1.57079632679489678 1.570796326794896336 0" />
<geometry>
<mesh filename="package:///cylinder_f.stl"/>
</geometry>
</collision>
<inertial>
<origin xyz="0.13981491538445642298 -0.034298269917181427313 -3.3207638528180402595e-10" rpy="0 0 0"/>
<mass value="2.7501984867936553059" />
<inertia ixx="0.005332948954634286233" ixy="-0.0021373023958805173819"  ixz="-9.8161765695918220738e-11" iyy="0.027645758712734874035" iyz="3.3278684881375466005e-12" izz="0.031077682858520992715" />
</inertial>
</link>

<link name="cylinder_m_8">
<visual>
<origin xyz="-5.5511151231257827021e-17 -0.03550000000000003153 -0.33699999999999996625" rpy="1.570796326794896558 8.0097691219059760037e-17 -4.049646395640020554e-17" />
<geometry>
<mesh filename="package:///cylinder_m.stl"/>
</geometry>
<material name="cylinder_m_material">
<color rgba="0.43921568627450979783 0.47450980392156860699 0.50196078431372548323 1.0"/>
</material>
</visual>
<collision>
<origin xyz="-5.5511151231257827021e-17 -0.03550000000000003153 -0.33699999999999996625" rpy="1.570796326794896558 8.0097691219059760037e-17 -4.049646395640020554e-17" />
<geometry>
<mesh filename="package:///cylinder_m.stl"/>
</geometry>
</collision>
<inertial>
<origin xyz="-3.8591735728072719174e-09 -4.4177499991526758549e-09 -0.19587031738716764728" rpy="0 0 0"/>
<mass value="2.7499900392833467322" />
<inertia ixx="0.033691032693585303004" ixy="8.258241088547489567e-11"  ixz="1.6613893666270584256e-09" iyy="0.033689032919998106175" iyz="1.8671001117865936646e-09" izz="0.00028217358044707152153" />
</inertial>
</link>

<link name="l3_cl2_1">
<inertial>
<origin xyz="0 0 0" rpy="0 0 0" />
<mass value="1e-9" />
<inertia ixx="0" ixy="0" ixz="0" iyy="0" iyz="0" izz="0" />
</inertial>
</link>
<joint name="l3_cl2_1_frame" type="fixed">
<origin xyz="0 -5.5511151231257827021e-17 -0.009499999999999987621" rpy="-1.5707963267948974462 -1.5707963267948961139 0" />
<parent link="cylinder_m_8" />
<child link="l3_cl2_1" />
<axis xyz="0 0 0"/>
</joint>

<joint name="l3_c2" type="prismatic">
<origin xyz="0.45950000000000540412 9.4924068605450884206e-15 -9.0483176506950258045e-15" rpy="-2.8571979860306309276e-16 1.5707963267948910069 0" />
<parent link="cylinder_f_8" />
<child link="cylinder_m_8" />
<axis xyz="0 0 1"/>
<limit effort="1" velocity="20" lower="0.036499999999999997724" upper="0.23649999999999998801"/>
<joint_properties friction="0.0"/>
</joint>

<joint name="l3_r6" type="revolute">
<origin xyz="-0.40999999999999930944 -1.6653345369377348106e-15 -0.095000000000000750511" rpy="1.5707963267948974462 0.67750901888020520492 -4.8652669090637057603e-15" />
<parent link="hip_3" />
<child link="cylinder_f_8" />
<axis xyz="0 0 1"/>
<limit effort="1" velocity="20" lower="0" upper="1.570796326794896558"/>
<joint_properties friction="0.0"/>
</joint>

<link name="cylinder_support_3">
<visual>
<origin xyz="5.5511151231257827021e-17 0.24250000000000004885 -0.029999999999999971134" rpy="-1.570796326794896558 3.6311749399212789228e-17 1.704663285845587178e-17" />
<geometry>
<mesh filename="package:///cylinder_support.stl"/>
</geometry>
<material name="cylinder_support_material">
<color rgba="0.64705882352941179736 0.64705882352941179736 0.64705882352941179736 1.0"/>
</material>
</visual>
<collision>
<origin xyz="5.5511151231257827021e-17 0.24250000000000004885 -0.029999999999999971134" rpy="-1.570796326794896558 3.6311749399212789228e-17 1.704663285845587178e-17" />
<geometry>
<mesh filename="package:///cylinder_support.stl"/>
</geometry>
</collision>
<inertial>
<origin xyz="0.0054354402573497852952 0.29828794955270299116 0.02015291773652211349" rpy="0 0 0"/>
<mass value="3.4500000005941280357" />
<inertia ixx="0.12216401720555165877" ixy="-0.00014225366187223229572"  ixz="-9.0029635204870556392e-06" iyy="0.0080920294153276912247" iyz="1.7561733914073286055e-05" izz="0.11536233747142544959" />
</inertial>
</link>

<link name="l3_cl4_1">
<inertial>
<origin xyz="0 0 0" rpy="0 0 0" />
<mass value="1e-9" />
<inertia ixx="0" ixy="0" ixz="0" iyy="0" iyz="0" izz="0" />
</inertial>
</link>
<joint name="l3_cl4_1_frame" type="fixed">
<origin xyz="8.3266726846886740532e-17 0.58999999999999996891 0.019999999999999962252" rpy="1.5707963267949054398 9.6515610006004477964e-15 3.141592653589793116" />
<parent link="cylinder_support_3" />
<child link="l3_cl4_1" />
<axis xyz="0 0 0"/>
</joint>

<link name="cylinder_f_9">
<visual>
<origin xyz="0.11800000000000000766 -0.035499999999999976019 5.5511151231257827021e-17" rpy="1.570796326794896558 1.570796326794896336 0" />
<geometry>
<mesh filename="package:///cylinder_f.stl"/>
</geometry>
<material name="cylinder_f_material">
<color rgba="0.26274509803921569651 0.28235294117647058432 0.30196078431372547213 1.0"/>
</material>
</visual>
<collision>
<origin xyz="0.11800000000000000766 -0.035499999999999976019 5.5511151231257827021e-17" rpy="1.570796326794896558 1.570796326794896336 0" />
<geometry>
<mesh filename="package:///cylinder_f.stl"/>
</geometry>
</collision>
<inertial>
<origin xyz="0.13981491538445650624 -0.034298269917181316291 -3.3207633040639098477e-10" rpy="0 0 0"/>
<mass value="2.7501984867936553059" />
<inertia ixx="0.0053329489546342844983" ixy="-0.0021373023958805173819"  ixz="-9.8161764873255836712e-11" iyy="0.027645758712734874035" iyz="3.3278687445513715247e-12" izz="0.031077682858520978837" />
</inertial>
</link>

<link name="cylinder_m_9">
<visual>
<origin xyz="5.5511151231257827021e-17 -0.035499999999999976019 -0.33699999999999991074" rpy="1.570796326794896558 2.2097144210973277284e-19 -1.0065746546612449146e-16" />
<geometry>
<mesh filename="package:///cylinder_m.stl"/>
</geometry>
<material name="cylinder_m_material">
<color rgba="0.43921568627450979783 0.47450980392156860699 0.50196078431372548323 1.0"/>
</material>
</visual>
<collision>
<origin xyz="5.5511151231257827021e-17 -0.035499999999999976019 -0.33699999999999991074" rpy="1.570796326794896558 2.2097144210973277284e-19 -1.0065746546612449146e-16" />
<geometry>
<mesh filename="package:///cylinder_m.stl"/>
</geometry>
</collision>
<inertial>
<origin xyz="-3.8591734720642494557e-09 -4.4177499297637368159e-09 -0.19587031738716759177" rpy="0 0 0"/>
<mass value="2.7499900392833467322" />
<inertia ixx="0.033691032693585316882" ixy="8.2582409927205943739e-11"  ixz="1.661389369295384263e-09" iyy="0.033689032919998120053" iyz="1.8671001119152707079e-09" izz="0.00028217358044707152153" />
</inertial>
</link>

<link name="l3_cl3_1">
<inertial>
<origin xyz="0 0 0" rpy="0 0 0" />
<mass value="1e-9" />
<inertia ixx="0" ixy="0" ixz="0" iyy="0" iyz="0" izz="0" />
</inertial>
</link>
<joint name="l3_cl3_1_frame" type="fixed">
<origin xyz="-1.1102230246251565404e-16 0 -0.0094999999999999529265" rpy="1.57079632679489678 1.5707963267948874542 0" />
<parent link="cylinder_m_9" />
<child link="l3_cl3_1" />
<axis xyz="0 0 0"/>
</joint>

<joint name="l3_c3" type="prismatic">
<origin xyz="0.45949999999999446842 -1.5543122344752191566e-15 9.9920072216264088638e-16" rpy="3.1415926535897829019 -1.5707963267948807928 0" />
<parent link="cylinder_f_9" />
<child link="cylinder_m_9" />
<axis xyz="0 0 1"/>
<limit effort="1" velocity="20" lower="0.036499999999999997724" upper="0.23649999999999998801"/>
<joint_properties friction="0.0"/>
</joint>

<joint name="l3_r8" type="revolute">
<origin xyz="1.7763568394002504647e-15 0.39249999999999962697 0.020000000000000128786" rpy="1.3451873289489358511e-14 1.1341460953105552235e-14 -3.0301163114049525227" />
<parent link="cylinder_support_3" />
<child link="cylinder_f_9" />
<axis xyz="0 0 1"/>
<limit effort="1" velocity="20" lower="0" upper="1.570796326794896558"/>
<joint_properties friction="0.0"/>
</joint>

<joint name="l3_r7" type="revolute">
<origin xyz="-0.12499999999999988898 -0.020000000000000905942 -0.039999999999999431843" rpy="-1.57079632679489678 0.79185786258829671258 -1.035821479701865864e-14" />
<parent link="hip_3" />
<child link="cylinder_support_3" />
<axis xyz="0 0 1"/>
<limit effort="1" velocity="20" lower="-1.570796326794896558" upper="1.570796326794896558"/>
<joint_properties friction="0.0"/>
</joint>

<joint name="l3_r2" type="revolute">
<origin xyz="0.5 -0.024999999999999918121 0.030000000000000102973" rpy="-3.1415926535897926719 -7.5808492435147575872e-16 -2.0440852524641424104" />
<parent link="center" />
<child link="hip_3" />
<axis xyz="0 0 1"/>
<limit effort="1" velocity="20" lower="0" upper="1.570796326794896558"/>
<joint_properties friction="0.0"/>
</joint>

<link name="cylinder_f_10">
<visual>
<origin xyz="0.11799999999999999378 -0.035500000000000087041 -7.5794071873447671101e-18" rpy="1.570796326794896558 1.570796326794896336 0" />
<geometry>
<mesh filename="package:///cylinder_f.stl"/>
</geometry>
<material name="cylinder_f_material">
<color rgba="0.26274509803921569651 0.28235294117647058432 0.30196078431372547213 1.0"/>
</material>
</visual>
<collision>
<origin xyz="0.11799999999999999378 -0.035500000000000087041 -7.5794071873447671101e-18" rpy="1.570796326794896558 1.570796326794896336 0" />
<geometry>
<mesh filename="package:///cylinder_f.stl"/>
</geometry>
</collision>
<inertial>
<origin xyz="0.13981491538445647849 -0.034298269917181427313 -3.3207639316941841287e-10" rpy="0 0 0"/>
<mass value="2.7501984867936553059" />
<inertia ixx="0.0053329489546342844983" ixy="-0.0021373023958805169482"  ixz="-9.8161766988590845596e-11" iyy="0.027645758712734874035" iyz="3.3278704863581029273e-12" izz="0.031077682858520978837" />
</inertial>
</link>

<link name="cylinder_m_10">
<visual>
<origin xyz="0 -0.035499999999999976019 -0.33700000000000007727" rpy="1.570796326794896558 5.7289517137548081718e-32 -8.1178161778140621661e-33" />
<geometry>
<mesh filename="package:///cylinder_m.stl"/>
</geometry>
<material name="cylinder_m_material">
<color rgba="0.43921568627450979783 0.47450980392156860699 0.50196078431372548323 1.0"/>
</material>
</visual>
<collision>
<origin xyz="0 -0.035499999999999976019 -0.33700000000000007727" rpy="1.570796326794896558 5.7289517137548081718e-32 -8.1178161778140621661e-33" />
<geometry>
<mesh filename="package:///cylinder_m.stl"/>
</geometry>
</collision>
<inertial>
<origin xyz="-3.8591735189509004646e-09 -4.4177499367026307198e-09 -0.19587031738716775831" rpy="0 0 0"/>
<mass value="2.7499900392833467322" />
<inertia ixx="0.033691032693585303004" ixy="8.2582413614764060556e-11"  ixz="1.6613893693194481878e-09" iyy="0.033689032919998106175" iyz="1.8671001119331134073e-09" izz="0.00028217358044707152153" />
</inertial>
</link>

<link name="l4_cl1_1">
<inertial>
<origin xyz="0 0 0" rpy="0 0 0" />
<mass value="1e-9" />
<inertia ixx="0" ixy="0" ixz="0" iyy="0" iyz="0" izz="0" />
</inertial>
</link>
<joint name="l4_cl1_1_frame" type="fixed">
<origin xyz="9.8607613152626475676e-32 -1.1102230246251565404e-16 -0.0095000000000000361933" rpy="-1.570796326794896558 -1.570796326794896336 0" />
<parent link="cylinder_m_10" />
<child link="l4_cl1_1" />
<axis xyz="0 0 0"/>
</joint>

<joint name="l4_c1" type="prismatic">
<origin xyz="0.45949999999999974198 -9.9920072216264088638e-16 7.9164734028173481031e-17" rpy="2.7892200453038867559e-16 1.5707963267948952257 0" />
<parent link="cylinder_f_10" />
<child link="cylinder_m_10" />
<axis xyz="0 0 1"/>
<limit effort="1" velocity="20" lower="0.036499999999999997724" upper="0.23649999999999998801"/>
<joint_properties friction="0.0"/>
</joint>

<joint name="l4_r1" type="revolute">
<origin xyz="-0.18999999999999969691 -0.96500000000000030198 1.0755285551056218776e-16" rpy="3.1415926535897922278 -2.294689447613700712e-16 0.14573630623988689803" />
<parent link="center" />
<child link="cylinder_f_10" />
<axis xyz="0 0 1"/>
<limit effort="1" velocity="20" lower="0" upper="1.570796326794896558"/>
<joint_properties friction="0.0"/>
</joint>

<link name="hip_4">
<visual>
<origin xyz="-0.064999999999999946709 -1.1102230246251565404e-16 0" rpy="-3.141592653589793116 -5.271313191710901301e-33 -2.0608336271419962865e-17" />
<geometry>
<mesh filename="package:///hip.stl"/>
</geometry>
<material name="hip_material">
<color rgba="0.64705882352941179736 0.64705882352941179736 0.64705882352941179736 1.0"/>
</material>
</visual>
<collision>
<origin xyz="-0.064999999999999946709 -1.1102230246251565404e-16 0" rpy="-3.141592653589793116 -5.271313191710901301e-33 -2.0608336271419962865e-17" />
<geometry>
<mesh filename="package:///hip.stl"/>
</geometry>
</collision>
<inertial>
<origin xyz="-0.03754179021932280147 -1.012960329695824589e-16 -0.016489821713258367292" rpy="0 0 0"/>
<mass value="3.5999999924476484559" />
<inertia ixx="0.0082519181249498946285" ixy="4.7004642340168698153e-18"  ixz="-0.012050372331242011417" iyy="0.12642361670580487543" iyz="2.4833812519804841432e-19" izz="0.12867127256930088741" />
</inertial>
</link>

<link name="l4_cl1_2">
<inertial>
<origin xyz="0 0 0" rpy="0 0 0" />
<mass value="1e-9" />
<inertia ixx="0" ixy="0" ixz="0" iyy="0" iyz="0" izz="0" />
</inertial>
</link>
<joint name="l4_cl1_2_frame" type="fixed">
<origin xyz="0.27499999999999591438 5.5511151231257827021e-16 0.02999999999999993644" rpy="-1.5707963267948945596 1.109557078629070938e-15 3.141592653589793116" />
<parent link="hip_4" />
<child link="l4_cl1_2" />
<axis xyz="0 0 0"/>
</joint>

<link name="femur_4">
<visual>
<origin xyz="1.1102230246251565404e-16 0.24249999999999988232 -0.029999999999999804601" rpy="-1.570796326794896558 -3.0904633520968255113e-17 -5.1964113954969109388e-17" />
<geometry>
<mesh filename="package:///femur.stl"/>
</geometry>
<material name="femur_material">
<color rgba="0.30196078431372547213 0.30196078431372547213 0.30196078431372547213 1.0"/>
</material>
</visual>
<collision>
<origin xyz="1.1102230246251565404e-16 0.24249999999999988232 -0.029999999999999804601" rpy="-1.570796326794896558 -3.0904633520968255113e-17 -5.1964113954969109388e-17" />
<geometry>
<mesh filename="package:///femur.stl"/>
</geometry>
</collision>
<inertial>
<origin xyz="0.0064139711381490122771 0.24592748545031778429 0.019999999210131652605" rpy="0 0 0"/>
<mass value="3.5999999984857375956" />
<inertia ixx="0.081390757679679695547" ixy="0.00019915715025975178889"  ixz="-1.17827719914616295e-10" iyy="0.0080793091134649629159" iyz="-5.7702359840077388988e-11" izz="0.074691636552088241929" />
</inertial>
</link>

<link name="l4_cl2_2">
<inertial>
<origin xyz="0 0 0" rpy="0 0 0" />
<mass value="1e-9" />
<inertia ixx="0" ixy="0" ixz="0" iyy="0" iyz="0" izz="0" />
</inertial>
</link>
<joint name="l4_cl2_2_frame" type="fixed">
<origin xyz="-0.012999999999999789502 0.38399999999999984146 0.020000000000000017764" rpy="1.5707963267948981123 5.6418899027106805647e-15 -8.2747863375710439487e-17" />
<parent link="femur_4" />
<child link="l4_cl2_2" />
<axis xyz="0 0 0"/>
</joint>

<link name="tibia_4">
<visual>
<origin xyz="-0.37499999999999988898 -1.1102230246251565404e-16 0" rpy="1.570796326794896558 -7.0085930073561983583e-17 1.800904183881451465e-18" />
<geometry>
<mesh filename="package:///tibia.stl"/>
</geometry>
<material name="tibia_material">
<color rgba="0.91764705882352937127 0.91764705882352937127 0.91764705882352937127 1.0"/>
</material>
</visual>
<collision>
<origin xyz="-0.37499999999999988898 -1.1102230246251565404e-16 0" rpy="1.570796326794896558 -7.0085930073561983583e-17 1.800904183881451465e-18" />
<geometry>
<mesh filename="package:///tibia.stl"/>
</geometry>
</collision>
<inertial>
<origin xyz="-0.37488809734909805949 -1.1081130059516287212e-16 -0.020000000000000007355" rpy="0 0 0"/>
<mass value="3.999999995260936192" />
<inertia ixx="0.0029642683101065922524" ixy="-4.4287685591106432486e-18"  ixz="-1.1302036876631743312e-17" iyy="0.21898012548041437264" iyz="-6.080007253492933693e-19" izz="0.21991734751853581065" />
</inertial>
</link>

<link name="l4_cl4_2">
<inertial>
<origin xyz="0 0 0" rpy="0 0 0" />
<mass value="1e-9" />
<inertia ixx="0" ixy="0" ixz="0" iyy="0" iyz="0" izz="0" />
</inertial>
</link>
<joint name="l4_cl4_2_frame" type="fixed">
<origin xyz="-0.45000000000000117684 1.1102230246251565404e-16 -0.020000000000001016964" rpy="-1.570796326794896558 -1.3365231167518776006e-16 -3.141592653589793116" />
<parent link="tibia_4" />
<child link="l4_cl4_2" />
<axis xyz="0 0 0"/>
</joint>

<link name="foot_4">
<visual>
<origin xyz="-2.2204460492503130808e-16 -0.34750000000000014211 -0.030000000000000026645" rpy="-1.570796326794896558 3.508662038462727703e-17 -1.5407546537866189627e-17" />
<geometry>
<mesh filename="package:///foot.stl"/>
</geometry>
<material name="foot_material">
<color rgba="0.30196078431372547213 0.30196078431372547213 0.30196078431372547213 1.0"/>
</material>
</visual>
<collision>
<origin xyz="-2.2204460492503130808e-16 -0.34750000000000014211 -0.030000000000000026645" rpy="-1.570796326794896558 3.508662038462727703e-17 -1.5407546537866189627e-17" />
<geometry>
<mesh filename="package:///foot.stl"/>
</geometry>
</collision>
<inertial>
<origin xyz="0.0067478869293352925635 -0.37109593568577248224 0.019999996975168528313" rpy="0 0 0"/>
<mass value="3.6499999959578990349" />
<inertia ixx="0.27434960237524297355" ixy="-0.00053748086186041171657"  ixz="3.1806926853785346111e-08" iyy="0.0056481174471628928929" iyz="3.3810617678903744184e-09" izz="0.27004492242811078961" />
</inertial>
</link>

<link name="l4_cl3_2">
<inertial>
<origin xyz="0 0 0" rpy="0 0 0" />
<mass value="1e-9" />
<inertia ixx="0" ixy="0" ixz="0" iyy="0" iyz="0" izz="0" />
</inertial>
</link>
<joint name="l4_cl3_2_frame" type="fixed">
<origin xyz="0 -0.50500000000000011546 0.020000000000000239808" rpy="-1.5707963267948983344 4.250158188698657927e-15 3.141592653589793116" />
<parent link="foot_4" />
<child link="l4_cl3_2" />
<axis xyz="0 0 0"/>
</joint>

<link name="leg_4">
<inertial>
<origin xyz="0 0 0" rpy="0 0 0" />
<mass value="1e-9" />
<inertia ixx="0" ixy="0" ixz="0" iyy="0" iyz="0" izz="0" />
</inertial>
</link>
<joint name="leg_4_frame" type="fixed">
<origin xyz="0.0050000000000001154632 -1.0075000000000000622 0.020000000000000017764" rpy="-1.57079632679489678 8.44481009585997054e-17 4.062073120193065484e-17" />
<parent link="foot_4" />
<child link="leg_4" />
<axis xyz="0 0 0"/>
</joint>

<joint name="l4_r5" type="revolute">
<origin xyz="-0.74999999999999966693 0 -0.039999999999999813483" rpy="-4.1114399506133858885e-17 -3.1816225832927581697e-17 2.876806338808024055" />
<parent link="tibia_4" />
<child link="foot_4" />
<axis xyz="0 0 1"/>
<limit effort="1" velocity="20" lower="-1.570796326794896558" upper="1.570796326794896558"/>
<joint_properties friction="0.0"/>
</joint>

<joint name="l4_r4" type="revolute">
<origin xyz="-4.2188474935755948536e-15 0.48999999999999549471 -2.4424906541753443889e-15" rpy="3.1415926535897908956 -2.3344824489569353479e-14 -0.4152831526151581909" />
<parent link="femur_4" />
<child link="tibia_4" />
<axis xyz="0 0 1"/>
<limit effort="1" velocity="20" lower="-1.570796326794896558" upper="1.570796326794896558"/>
<joint_properties friction="0.0"/>
</joint>

<joint name="l4_r3" type="revolute">
<origin xyz="0.125 -0.020000000000000239808 -0.040000000000000021649" rpy="-1.570796326794896558 0.4666163750680140665 -1.6377357379776283407e-14" />
<parent link="hip_4" />
<child link="femur_4" />
<axis xyz="0 0 1"/>
<limit effort="1" velocity="20" lower="-1.570796326794896558" upper="1.570796326794896558"/>
<joint_properties friction="0.0"/>
</joint>

<link name="cylinder_f_11">
<visual>
<origin xyz="0.11799999999999999378 -0.035500000000000087041 1.1102230246251565404e-16" rpy="1.570796326794896558 1.570796326794896336 0" />
<geometry>
<mesh filename="package:///cylinder_f.stl"/>
</geometry>
<material name="cylinder_f_material">
<color rgba="0.26274509803921569651 0.28235294117647058432 0.30196078431372547213 1.0"/>
</material>
</visual>
<collision>
<origin xyz="0.11799999999999999378 -0.035500000000000087041 1.1102230246251565404e-16" rpy="1.570796326794896558 1.570796326794896336 0" />
<geometry>
<mesh filename="package:///cylinder_f.stl"/>
</geometry>
</collision>
<inertial>
<origin xyz="0.13981491538445647849 -0.034298269917181427313 -3.3207627423919159106e-10" rpy="0 0 0"/>
<mass value="2.7501984867936553059" />
<inertia ixx="0.0053329489546342827636" ixy="-0.0021373023958805178156"  ixz="-9.8161769150795148759e-11" iyy="0.027645758712734874035" iyz="3.327870345109104227e-12" izz="0.031077682858520978837" />
</inertial>
</link>

<link name="cylinder_m_11">
<visual>
<origin xyz="1.1102230246251565404e-16 -0.035499999999999864997 -0.33699999999999985523" rpy="1.57079632679489678 -4.9021131829392702322e-17 7.799161561238237068e-17" />
<geometry>
<mesh filename="package:///cylinder_m.stl"/>
</geometry>
<material name="cylinder_m_material">
<color rgba="0.43921568627450979783 0.47450980392156860699 0.50196078431372548323 1.0"/>
</material>
</visual>
<collision>
<origin xyz="1.1102230246251565404e-16 -0.035499999999999864997 -0.33699999999999985523" rpy="1.57079632679489678 -4.9021131829392702322e-17 7.799161561238237068e-17" />
<geometry>
<mesh filename="package:///cylinder_m.stl"/>
</geometry>
</collision>
<inertial>
<origin xyz="-3.8591734195527016254e-09 -4.4177498187414343533e-09 -0.1958703173871675085" rpy="0 0 0"/>
<mass value="2.7499900392833467322" />
<inertia ixx="0.033691032693585303004" ixy="8.2582413680453949743e-11"  ixz="1.6613893709531770469e-09" iyy="0.033689032919998106175" iyz="1.8671001134966013975e-09" izz="0.00028217358044707152153" />
</inertial>
</link>

<link name="l4_cl2_1">
<inertial>
<origin xyz="0 0 0" rpy="0 0 0" />
<mass value="1e-9" />
<inertia ixx="0" ixy="0" ixz="0" iyy="0" iyz="0" izz="0" />
</inertial>
</link>
<joint name="l4_cl2_1_frame" type="fixed">
<origin xyz="1.1102230246251565404e-16 1.1102230246251565404e-16 -0.0094999999999998419042" rpy="-1.57079632679489678 -1.570796326794896336 0" />
<parent link="cylinder_m_11" />
<child link="l4_cl2_1" />
<axis xyz="0 0 0"/>
</joint>

<joint name="l4_c2" type="prismatic">
<origin xyz="0.45949999999999890932 -5.5511151231257827021e-16 -8.8817841970012523234e-16" rpy="1.7957032038766200501e-15 1.5707963267948890085 0" />
<parent link="cylinder_f_11" />
<child link="cylinder_m_11" />
<axis xyz="0 0 1"/>
<limit effort="1" velocity="20" lower="0.036499999999999997724" upper="0.23649999999999998801"/>
<joint_properties friction="0.0"/>
</joint>

<joint name="l4_r6" type="revolute">
<origin xyz="-0.40999999999999747757 -8.8817841970012523234e-16 -0.094999999999998280265" rpy="1.5707963267948974462 0.67749592276418513226 -2.3346654462577296161e-15" />
<parent link="hip_4" />
<child link="cylinder_f_11" />
<axis xyz="0 0 1"/>
<limit effort="1" velocity="20" lower="0" upper="1.570796326794896558"/>
<joint_properties friction="0.0"/>
</joint>

<link name="cylinder_support_4">
<visual>
<origin xyz="-2.2204460492503130808e-16 0.24250000000000015987 -0.030000000000000026645" rpy="-1.570796326794896558 -9.9298959086621501716e-18 -4.5354258332932102468e-17" />
<geometry>
<mesh filename="package:///cylinder_support.stl"/>
</geometry>
<material name="cylinder_support_material">
<color rgba="0.64705882352941179736 0.64705882352941179736 0.64705882352941179736 1.0"/>
</material>
</visual>
<collision>
<origin xyz="-2.2204460492503130808e-16 0.24250000000000015987 -0.030000000000000026645" rpy="-1.570796326794896558 -9.9298959086621501716e-18 -4.5354258332932102468e-17" />
<geometry>
<mesh filename="package:///cylinder_support.stl"/>
</geometry>
</collision>
<inertial>
<origin xyz="0.005435440257349485188 0.29828794955270310219 0.020152917736522061448" rpy="0 0 0"/>
<mass value="3.4500000005941280357" />
<inertia ixx="0.12216401720555163102" ixy="-0.00014225366187224221617"  ixz="-9.0029635204943909445e-06" iyy="0.0080920294153276946941" iyz="1.7561733914074837819e-05" izz="0.11536233747142547734" />
</inertial>
</link>

<link name="l4_cl4_1">
<inertial>
<origin xyz="0 0 0" rpy="0 0 0" />
<mass value="1e-9" />
<inertia ixx="0" ixy="0" ixz="0" iyy="0" iyz="0" izz="0" />
</inertial>
</link>
<joint name="l4_cl4_1_frame" type="fixed">
<origin xyz="-1.1102230246251565404e-16 0.59000000000000030198 0.020000000000000239808" rpy="1.570796326794896558 -2.1172771087553852848e-17 3.141592653589793116" />
<parent link="cylinder_support_4" />
<child link="l4_cl4_1" />
<axis xyz="0 0 0"/>
</joint>

<link name="cylinder_f_12">
<visual>
<origin xyz="0.11799999999999988276 -0.035500000000000087041 0" rpy="1.570796326794896558 1.570796326794896336 0" />
<geometry>
<mesh filename="package:///cylinder_f.stl"/>
</geometry>
<material name="cylinder_f_material">
<color rgba="0.26274509803921569651 0.28235294117647058432 0.30196078431372547213 1.0"/>
</material>
</visual>
<collision>
<origin xyz="0.11799999999999988276 -0.035500000000000087041 0" rpy="1.570796326794896558 1.570796326794896336 0" />
<geometry>
<mesh filename="package:///cylinder_f.stl"/>
</geometry>
</collision>
<inertial>
<origin xyz="0.13981491538445636746 -0.034298269917181427313 -3.3207638456792539213e-10" rpy="0 0 0"/>
<mass value="2.7501984867936553059" />
<inertia ixx="0.0053329489546342844983" ixy="-0.0021373023958805165146"  ixz="-9.8161767676922988477e-11" iyy="0.027645758712734874035" iyz="3.3278679551880752506e-12" izz="0.031077682858520992715" />
</inertial>
</link>

<link name="cylinder_m_12">
<visual>
<origin xyz="-1.1102230246251565404e-16 -0.035500000000000309086 -0.33700000000000018829" rpy="1.570796326794896558 1.3682144421321855621e-17 -9.9664644270980770386e-18" />
<geometry>
<mesh filename="package:///cylinder_m.stl"/>
</geometry>
<material name="cylinder_m_material">
<color rgba="0.43921568627450979783 0.47450980392156860699 0.50196078431372548323 1.0"/>
</material>
</visual>
<collision>
<origin xyz="-1.1102230246251565404e-16 -0.035500000000000309086 -0.33700000000000018829" rpy="1.570796326794896558 1.3682144421321855621e-17 -9.9664644270980770386e-18" />
<geometry>
<mesh filename="package:///cylinder_m.stl"/>
</geometry>
</collision>
<inertial>
<origin xyz="-3.8591736429906393527e-09 -4.4177502975251137229e-09 -0.19587031738716789708" rpy="0 0 0"/>
<mass value="2.7499900392833467322" />
<inertia ixx="0.033691032693585303004" ixy="8.258241143369013911e-11"  ixz="1.661389368836343484e-09" iyy="0.033689032919998106175" iyz="1.8671001090699455902e-09" izz="0.00028217358044707152153" />
</inertial>
</link>

<link name="l4_cl3_1">
<inertial>
<origin xyz="0 0 0" rpy="0 0 0" />
<mass value="1e-9" />
<inertia ixx="0" ixy="0" ixz="0" iyy="0" iyz="0" izz="0" />
</inertial>
</link>
<joint name="l4_cl3_1_frame" type="fixed">
<origin xyz="-5.5511151231257827021e-16 -4.4408920985006261617e-16 -0.0094999999999998419042" rpy="1.57079632679489678 1.570796326794896336 0" />
<parent link="cylinder_m_12" />
<child link="l4_cl3_1" />
<axis xyz="0 0 0"/>
</joint>

<joint name="l4_c3" type="prismatic">
<origin xyz="0.45949999999999957545 4.4408920985006261617e-16 3.3306690738754696213e-16" rpy="-3.1415926535897926719 -1.5707963267948958919 0" />
<parent link="cylinder_f_12" />
<child link="cylinder_m_12" />
<axis xyz="0 0 1"/>
<limit effort="1" velocity="20" lower="0.036499999999999997724" upper="0.23649999999999998801"/>
<joint_properties friction="0.0"/>
</joint>

<joint name="l4_r8" type="revolute">
<origin xyz="-1.1102230246251565404e-16 0.39250000000000051514 0.019999999999999684697" rpy="-6.1759297529534193009e-16 2.3607132528423478458e-16 -3.0336414428136180277" />
<parent link="cylinder_support_4" />
<child link="cylinder_f_12" />
<axis xyz="0 0 1"/>
<limit effort="1" velocity="20" lower="0" upper="1.570796326794896558"/>
<joint_properties friction="0.0"/>
</joint>

<joint name="l4_r7" type="revolute">
<origin xyz="-0.125 -0.020000000000000128786 -0.039999999999999993894" rpy="-1.57079632679489678 0.79176818239134705291 3.9765294598519190235e-15" />
<parent link="hip_4" />
<child link="cylinder_support_4" />
<axis xyz="0 0 1"/>
<limit effort="1" velocity="20" lower="-1.570796326794896558" upper="1.570796326794896558"/>
<joint_properties friction="0.0"/>
</joint>

<joint name="l4_r2" type="revolute">
<origin xyz="0.49999999999999933387 -1.0249999999999996891 0.030000000000000116851" rpy="3.1415926535897926719 -6.4212163323135518491e-16 2.6683037279205028547" />
<parent link="center" />
<child link="hip_4" />
<axis xyz="0 0 1"/>
<limit effort="1" velocity="20" lower="0" upper="1.570796326794896558"/>
<joint_properties friction="0.0"/>
</joint>


</robot>
