<robot name="onshape">
<link name="base">
<visual>
<origin xyz="0 0 0" rpy="0 -0 0" />
<geometry>
<mesh filename="package:///base.stl"/>
</geometry>
<material name="base_material">
<color rgba="0.61568627450980395466 0.81176470588235294379 0.92941176470588238168 1.0"/>
</material>
</visual>
<collision>
<origin xyz="0 0 0" rpy="0 -0 0" />
<geometry>
<mesh filename="package:///base.stl"/>
</geometry>
</collision>
<inertial>
<origin xyz="-4.3854433115842976622e-19 1.3777276490407727741e-18 0.002500000000000000052" rpy="0 0 0"/>
<mass value="0.022106994804229673779" />
<inertia ixx="2.8439727690857972453e-06" ixy="0"  ixz="0" iyy="2.8439727690857968218e-06" iyz="0" izz="5.5958330598206373096e-06" />
</inertial>
</link>

<link name="ring">
<visual>
<origin xyz="-1.2456679569688523307e-17 6.3186423493322252371e-18 0.010000000000000001943" rpy="3.141592653589793116 -0 0" />
<geometry>
<mesh filename="package:///ring.stl"/>
</geometry>
<material name="ring_material">
<color rgba="0.64705882352941179736 0.64705882352941179736 0.64705882352941179736 1.0"/>
</material>
</visual>
<collision>
<origin xyz="-1.2456679569688523307e-17 6.3186423493322252371e-18 0.010000000000000001943" rpy="3.141592653589793116 -0 0" />
<geometry>
<mesh filename="package:///ring.stl"/>
</geometry>
</collision>
<inertial>
<origin xyz="-6.7787260609702578019e-18 3.21649870348168287e-18 0.0025000000000000013531" rpy="0 0 0"/>
<mass value="0.021266466137444883094" />
<inertia ixx="8.1309860336448455491e-06" ixy="0"  ixz="0" iyy="8.1309860336448455491e-06" iyz="0" izz="1.6173361791717006628e-05" />
</inertial>
</link>

<joint name="lower" type="revolute">
<origin xyz="6.9787070280364672227e-18 -2.5134897948386625574e-18 0.0050000000000000009714" rpy="0 -0 0" />
<parent link="base" />
<child link="ring" />
<axis xyz="0 0 1"/>
<limit effort="1" velocity="20" />
<joint_properties friction="0.0"/>
</joint>

<link name="ring_2">
<visual>
<origin xyz="0 -1.3777276490407725815e-18 -0.010000000000000001943" rpy="-6.0089014264881758615e-32 1.5998861900492123711e-33 1.8482058781080402454e-35" />
<geometry>
<mesh filename="package:///ring.stl"/>
</geometry>
<material name="ring_material">
<color rgba="0.64705882352941179736 0.64705882352941179736 0.64705882352941179736 1.0"/>
</material>
</visual>
<collision>
<origin xyz="0 -1.3777276490407725815e-18 -0.010000000000000001943" rpy="-6.0089014264881758615e-32 1.5998861900492123711e-33 1.8482058781080402454e-35" />
<geometry>
<mesh filename="package:///ring.stl"/>
</geometry>
</collision>
<inertial>
<origin xyz="5.6779535087182655052e-18 1.7244159968097699783e-18 -0.0025000000000000013531" rpy="0 0 0"/>
<mass value="0.021266466137444883094" />
<inertia ixx="8.1309860336448455491e-06" ixy="-1.4193104137727079363e-37"  ixz="-1.3008652266711409118e-38" iyy="8.1309860336448455491e-06" iyz="-4.88582935763239449e-37" izz="1.6173361791717006628e-05" />
</inertial>
</link>

<joint name="upper" type="revolute">
<origin xyz="3.4694469519536141888e-18 1.3777276490407700778e-18 0.044999999999999998335" rpy="3.4000580129145483145e-16 -9.788590809453151338e-17 -2.8085211743323700543e-18" />
<parent link="base" />
<child link="ring_2" />
<axis xyz="0 0 1"/>
<limit effort="1" velocity="20" />
<joint_properties friction="0.0"/>
</joint>

<link name="shaft1">
<visual>
<origin xyz="-1.4027763383387752091e-18 2.2871353342480030844e-20 0.044999999999999991396" rpy="3.141592653589793116 -0 0" />
<geometry>
<mesh filename="package:///shaft1.stl"/>
</geometry>
<material name="shaft1_material">
<color rgba="0.90980392156862743835 0.57254901960784310155 0.16470588235294117418 1.0"/>
</material>
</visual>
<collision>
<origin xyz="-1.4027763383387752091e-18 2.2871353342480030844e-20 0.044999999999999991396" rpy="3.141592653589793116 -0 0" />
<geometry>
<mesh filename="package:///shaft1.stl"/>
</geometry>
</collision>
<inertial>
<origin xyz="-1.0215871159641080725e-18 7.0520006139313428938e-20 0.019999999999999993477" rpy="0 0 0"/>
<mass value="0.0086799999999999984807" />
<inertia ixx="1.3110699999999994176e-06" ixy="0"  ixz="0" iyy="1.3110699999999994176e-06" iyz="0" izz="3.0747333333333320007e-07" />
</inertial>
</link>

<link name="shaft2">
<visual>
<origin xyz="8.6736173798840354721e-18 0.024999999999999984041 0.0074999999999999997224" rpy="1.570796326794896558 2.572926490009910756e-32 -2.1916057325622088889e-17" />
<geometry>
<mesh filename="package:///shaft2.stl"/>
</geometry>
<material name="shaft2_material">
<color rgba="0.65490196078431373028 0.82352941176470584317 0.57647058823529406801 1.0"/>
</material>
</visual>
<collision>
<origin xyz="8.6736173798840354721e-18 0.024999999999999984041 0.0074999999999999997224" rpy="1.570796326794896558 2.572926490009910756e-32 -2.1916057325622088889e-17" />
<geometry>
<mesh filename="package:///shaft2.stl"/>
</geometry>
</collision>
<inertial>
<origin xyz="0.012094260206525781626 -0.016646315354263471059 -0.01939234549963326365" rpy="0 0 0"/>
<mass value="0.028491984468144111731" />
<inertia ixx="2.0031681978535440496e-05" ixy="1.2028669081953350504e-05"  ixz="2.7943160590434955602e-06" iyy="1.2214979591772785555e-05" iyz="-3.8460423754995675188e-06" izz="2.7795633184329120147e-05" />
</inertial>
</link>

<link name="effector">
<inertial>
<origin xyz="0 0 0" rpy="0 0 0" />
<mass value="1e-9" />
<inertia ixx="0" ixy="0" ixz="0" iyy="0" iyz="0" izz="0" />
</inertial>
</link>
<joint name="effector_frame" type="fixed">
<origin xyz="0.049667853818713914027 -0.068361936024683156443 -0.02749999999999998973" rpy="0.942477796076938934 1.570796326794896558 0" />
<parent link="shaft2" />
<child link="effector" />
<axis xyz="0 0 0"/>
</joint>

<joint name="beta" type="revolute">
<origin xyz="-1.3777276490407427296e-18 -0.0074999999999999997224 0.019999999999999996947" rpy="-1.570796326794896558 -0.62831853071796783805 -2.0584666929331748659e-16" />
<parent link="shaft1" />
<child link="shaft2" />
<axis xyz="0 0 1"/>
<limit effort="1" velocity="20" />
<joint_properties friction="0.0"/>
</joint>

<joint name="alpha" type="revolute">
<origin xyz="0 1.3777276490407720037e-18 0.004999999999999997502" rpy="0 -0 1.570796326794896558" />
<parent link="base" />
<child link="shaft1" />
<axis xyz="0 0 1"/>
<limit effort="1" velocity="20" />
<joint_properties friction="0.0"/>
</joint>


</robot>
