<?xml version="1.0" ?>
<!-- Generated using onshape-to-robot -->
<!-- Onshape https://cad.onshape.com/documents/d028fa2bf853f0c1089b2eda/w/07caf1293628e1642b8cee41/e/1a20b014b0a60532533cddf2 -->
<robot name="spm">
  <!-- Link moteur_bati_v2 -->
  <link name="moteur_bati_v2">
    <inertial>
      <origin xyz="-1.75928e-15 2.49372e-15 0.0444979" rpy="0 0 0"/>
      <mass value="0.925424"/>
      <inertia ixx="0.00239196" ixy="-7.45589e-17" ixz="5.10426e-17" iyy="0.00239196" iyz="-5.80928e-17" izz="0.00451909"/>
    </inertial>
    <!-- Part b08_cra_ri30_40_pro_xx_客户参考 -->
    <visual>
      <origin xyz="-0.0926361 0.0115732 0.0764594" rpy="2.35619 -2.01031e-14 1.5708"/>
      <geometry>
        <mesh filename="package://assets/b08_cra_ri30_40_pro_xx_客户参考.stl"/>
      </geometry>
      <material name="b08_cra_ri30_40_pro_xx_客户参考_material">
        <color rgba="1 1 1 1.0"/>
      </material>
    </visual>
    <!-- Part cra_ri30_40_pro_xx_后盖 -->
    <visual>
      <origin xyz="-0.0926361 0.0115732 0.0764594" rpy="2.35619 -2.01031e-14 1.5708"/>
      <geometry>
        <mesh filename="package://assets/cra_ri30_40_pro_xx_后盖.stl"/>
      </geometry>
      <material name="cra_ri30_40_pro_xx_后盖_material">
        <color rgba="0.690196 0.764706 0.0196078 1.0"/>
      </material>
    </visual>
    <!-- Part extruded_4_2 -->
    <visual>
      <origin xyz="-0.0926361 0.0115732 0.0764594" rpy="2.35619 -2.01031e-14 1.5708"/>
      <geometry>
        <mesh filename="package://assets/extruded_4_2.stl"/>
      </geometry>
      <material name="extruded_4_2_material">
        <color rgba="0.960784 0.796078 0.207843 1.0"/>
      </material>
    </visual>
    <!-- Part 1_bati3 -->
    <visual>
      <origin xyz="0.0280564 -0.0254488 0.0198908" rpy="0.785398 -0 0.523599"/>
      <geometry>
        <mesh filename="package://assets/1_bati3.stl"/>
      </geometry>
      <material name="1_bati3_material">
        <color rgba="0.980392 0.713725 0.00392157 1.0"/>
      </material>
    </visual>
    <!-- Part extruded_6 -->
    <visual>
      <origin xyz="-0.0926361 0.0115732 0.0764594" rpy="2.35619 -2.01031e-14 1.5708"/>
      <geometry>
        <mesh filename="package://assets/extruded_6.stl"/>
      </geometry>
      <material name="extruded_6_material">
        <color rgba="0.00784314 0.392157 0.72549 1.0"/>
      </material>
    </visual>
    <!-- Part extruded_1 -->
    <visual>
      <origin xyz="-0.0926361 0.0115732 0.0764594" rpy="2.35619 -2.01031e-14 1.5708"/>
      <geometry>
        <mesh filename="package://assets/extruded_1.stl"/>
      </geometry>
      <material name="extruded_1_material">
        <color rgba="0.14902 0.180392 0.435294 1.0"/>
      </material>
    </visual>
    <!-- Part cra_ri30_40_xx_柔轮盖 -->
    <visual>
      <origin xyz="-0.0926361 0.0115732 0.0764594" rpy="2.35619 -2.01031e-14 1.5708"/>
      <geometry>
        <mesh filename="package://assets/cra_ri30_40_xx_柔轮盖.stl"/>
      </geometry>
      <material name="cra_ri30_40_xx_柔轮盖_material">
        <color rgba="0.368627 0.941176 0.733333 1.0"/>
      </material>
    </visual>
    <!-- Part cross_recessed_countersunk_head_screws_gb1_gb_cross_screws_type4_m2x10_8_8__h_type_n_5 -->
    <visual>
      <origin xyz="-0.0926361 0.0115732 0.0764594" rpy="2.35619 -2.01031e-14 1.5708"/>
      <geometry>
        <mesh filename="package://assets/cross_recessed_countersunk_head_screws_gb1_gb_cross_screws_type4_m2x10_8_8__h_type_n_5.stl"/>
      </geometry>
      <material name="cross_recessed_countersunk_head_screws_gb1_gb_cross_screws_type4_m2x10_8_8__h_type_n_5_material">
        <color rgba="0.776471 0.756863 0.737255 1.0"/>
      </material>
    </visual>
    <!-- Part extruded_4_4 -->
    <visual>
      <origin xyz="-0.0926361 0.0115732 0.0764594" rpy="2.35619 -2.01031e-14 1.5708"/>
      <geometry>
        <mesh filename="package://assets/extruded_4_4.stl"/>
      </geometry>
      <material name="extruded_4_4_material">
        <color rgba="0.960784 0.796078 0.207843 1.0"/>
      </material>
    </visual>
    <!-- Part user_library_0805_2012m__cap -->
    <visual>
      <origin xyz="-0.0926361 0.0115732 0.0764594" rpy="2.35619 -2.01031e-14 1.5708"/>
      <geometry>
        <mesh filename="package://assets/user_library_0805_2012m__cap.stl"/>
      </geometry>
      <material name="user_library_0805_2012m__cap_material">
        <color rgba="0.0196078 0.498039 0.341176 1.0"/>
      </material>
    </visual>
    <!-- Part extruded_2 -->
    <visual>
      <origin xyz="-0.0926361 0.0115732 0.0764594" rpy="2.35619 -2.01031e-14 1.5708"/>
      <geometry>
        <mesh filename="package://assets/extruded_2.stl"/>
      </geometry>
      <material name="extruded_2_material">
        <color rgba="0.176471 0.0431373 0.792157 1.0"/>
      </material>
    </visual>
    <!-- Part user_library_0805_2012m__cap_2 -->
    <visual>
      <origin xyz="-0.0926361 0.0115732 0.0764594" rpy="2.35619 -2.01031e-14 1.5708"/>
      <geometry>
        <mesh filename="package://assets/user_library_0805_2012m__cap__2.stl"/>
      </geometry>
      <material name="user_library_0805_2012m__cap_2_material">
        <color rgba="1 1 1 1.0"/>
      </material>
    </visual>
    <!-- Part user_library_0805_2012m__cap_3 -->
    <visual>
      <origin xyz="-0.0926361 0.0115732 0.0764594" rpy="2.35619 -2.01031e-14 1.5708"/>
      <geometry>
        <mesh filename="package://assets/user_library_0805_2012m__cap__3.stl"/>
      </geometry>
      <material name="user_library_0805_2012m__cap_3_material">
        <color rgba="0.0196078 0.498039 0.341176 1.0"/>
      </material>
    </visual>
    <!-- Part extruded -->
    <visual>
      <origin xyz="-0.0926361 0.0115732 0.0764594" rpy="2.35619 -2.01031e-14 1.5708"/>
      <geometry>
        <mesh filename="package://assets/extruded.stl"/>
      </geometry>
      <material name="extruded_material">
        <color rgba="0.14902 0.180392 0.435294 1.0"/>
      </material>
    </visual>
    <!-- Part extruded_4_3 -->
    <visual>
      <origin xyz="-0.0926361 0.0115732 0.0764594" rpy="2.35619 -2.01031e-14 1.5708"/>
      <geometry>
        <mesh filename="package://assets/extruded_4_3.stl"/>
      </geometry>
      <material name="extruded_4_3_material">
        <color rgba="0.960784 0.796078 0.207843 1.0"/>
      </material>
    </visual>
    <!-- Part cra_ri30_40_xx_b_电机壳_1 -->
    <visual>
      <origin xyz="-0.0926361 0.0115732 0.0764594" rpy="2.35619 -2.01031e-14 1.5708"/>
      <geometry>
        <mesh filename="package://assets/cra_ri30_40_xx_b_电机壳_1.stl"/>
      </geometry>
      <material name="cra_ri30_40_xx_b_电机壳_1_material">
        <color rgba="0.898039 0.917647 0.929412 1.0"/>
      </material>
    </visual>
    <!-- Part cross_recessed_countersunk_head_screws_gb1_gb_cross_screws_type4_m2x10_8_8__h_type_n_2 -->
    <visual>
      <origin xyz="-0.0926361 0.0115732 0.0764594" rpy="2.35619 -2.01031e-14 1.5708"/>
      <geometry>
        <mesh filename="package://assets/cross_recessed_countersunk_head_screws_gb1_gb_cross_screws_type4_m2x10_8_8__h_type_n_2.stl"/>
      </geometry>
      <material name="cross_recessed_countersunk_head_screws_gb1_gb_cross_screws_type4_m2x10_8_8__h_type_n_2_material">
        <color rgba="0.776471 0.756863 0.737255 1.0"/>
      </material>
    </visual>
    <!-- Part cross_recessed_countersunk_head_screws_gb1_gb_cross_screws_type4_m2x10_8_8__h_type_n_6 -->
    <visual>
      <origin xyz="-0.0926361 0.0115732 0.0764594" rpy="2.35619 -2.01031e-14 1.5708"/>
      <geometry>
        <mesh filename="package://assets/cross_recessed_countersunk_head_screws_gb1_gb_cross_screws_type4_m2x10_8_8__h_type_n_6.stl"/>
      </geometry>
      <material name="cross_recessed_countersunk_head_screws_gb1_gb_cross_screws_type4_m2x10_8_8__h_type_n_6_material">
        <color rgba="0.776471 0.756863 0.737255 1.0"/>
      </material>
    </visual>
    <!-- Part lsg_8_减速器外圈固定_1 -->
    <visual>
      <origin xyz="-0.0926361 0.0115732 0.0764594" rpy="2.35619 -2.01031e-14 1.5708"/>
      <geometry>
        <mesh filename="package://assets/lsg_8_减速器外圈固定_1.stl"/>
      </geometry>
      <material name="lsg_8_减速器外圈固定_1_material">
        <color rgba="0.898039 0.917647 0.929412 1.0"/>
      </material>
    </visual>
    <!-- Part extruded_0 -->
    <visual>
      <origin xyz="-0.0926361 0.0115732 0.0764594" rpy="2.35619 -2.01031e-14 1.5708"/>
      <geometry>
        <mesh filename="package://assets/extruded_0.stl"/>
      </geometry>
      <material name="extruded_0_material">
        <color rgba="0.105882 0.580392 0.14902 1.0"/>
      </material>
    </visual>
    <!-- Part hexagon_socket_head_cap_screws_gb_gb_fastener_screws_hshcs_m2x20_n -->
    <visual>
      <origin xyz="-0.0926361 0.0115732 0.0764594" rpy="2.35619 -2.01031e-14 1.5708"/>
      <geometry>
        <mesh filename="package://assets/hexagon_socket_head_cap_screws_gb_gb_fastener_screws_hshcs_m2x20_n.stl"/>
      </geometry>
      <material name="hexagon_socket_head_cap_screws_gb_gb_fastener_screws_hshcs_m2x20_n_material">
        <color rgba="0.776471 0.756863 0.737255 1.0"/>
      </material>
    </visual>
    <!-- Part cross_recessed_countersunk_head_screws_gb1_gb_cross_screws_type4_m2x10_8_8__h_type_n_4 -->
    <visual>
      <origin xyz="-0.0926361 0.0115732 0.0764594" rpy="2.35619 -2.01031e-14 1.5708"/>
      <geometry>
        <mesh filename="package://assets/cross_recessed_countersunk_head_screws_gb1_gb_cross_screws_type4_m2x10_8_8__h_type_n_4.stl"/>
      </geometry>
      <material name="cross_recessed_countersunk_head_screws_gb1_gb_cross_screws_type4_m2x10_8_8__h_type_n_4_material">
        <color rgba="0.776471 0.756863 0.737255 1.0"/>
      </material>
    </visual>
    <!-- Part extruded_1_2 -->
    <visual>
      <origin xyz="-0.0926361 0.0115732 0.0764594" rpy="2.35619 -2.01031e-14 1.5708"/>
      <geometry>
        <mesh filename="package://assets/extruded_1__2.stl"/>
      </geometry>
      <material name="extruded_1_2_material">
        <color rgba="0.435294 0.792157 0.176471 1.0"/>
      </material>
    </visual>
    <!-- Part cross_recessed_countersunk_head_screws_gb1_gb_cross_screws_type4_m2x10_8_8__h_type_n_1 -->
    <visual>
      <origin xyz="-0.0926361 0.0115732 0.0764594" rpy="2.35619 -2.01031e-14 1.5708"/>
      <geometry>
        <mesh filename="package://assets/cross_recessed_countersunk_head_screws_gb1_gb_cross_screws_type4_m2x10_8_8__h_type_n_1.stl"/>
      </geometry>
      <material name="cross_recessed_countersunk_head_screws_gb1_gb_cross_screws_type4_m2x10_8_8__h_type_n_1_material">
        <color rgba="0.776471 0.756863 0.737255 1.0"/>
      </material>
    </visual>
    <!-- Part extruded_4_5 -->
    <visual>
      <origin xyz="-0.0926361 0.0115732 0.0764594" rpy="2.35619 -2.01031e-14 1.5708"/>
      <geometry>
        <mesh filename="package://assets/extruded_4_5.stl"/>
      </geometry>
      <material name="extruded_4_5_material">
        <color rgba="0.960784 0.796078 0.207843 1.0"/>
      </material>
    </visual>
    <!-- Part lsg_08_柔轮 -->
    <visual>
      <origin xyz="-0.0926361 0.0115732 0.0764594" rpy="2.35619 -2.01031e-14 1.5708"/>
      <geometry>
        <mesh filename="package://assets/lsg_08_柔轮.stl"/>
      </geometry>
      <material name="lsg_08_柔轮_material">
        <color rgba="1 1 1 1.0"/>
      </material>
    </visual>
    <!-- Part hexagon_socket_head_cap_screws_gb_gb_fastener_screws_hshcs_m2x20_n_1 -->
    <visual>
      <origin xyz="-0.0926361 0.0115732 0.0764594" rpy="2.35619 -2.01031e-14 1.5708"/>
      <geometry>
        <mesh filename="package://assets/hexagon_socket_head_cap_screws_gb_gb_fastener_screws_hshcs_m2x20_n_1.stl"/>
      </geometry>
      <material name="hexagon_socket_head_cap_screws_gb_gb_fastener_screws_hshcs_m2x20_n_1_material">
        <color rgba="0.776471 0.756863 0.737255 1.0"/>
      </material>
    </visual>
    <!-- Part extruded_5 -->
    <visual>
      <origin xyz="-0.0926361 0.0115732 0.0764594" rpy="2.35619 -2.01031e-14 1.5708"/>
      <geometry>
        <mesh filename="package://assets/extruded_5.stl"/>
      </geometry>
      <material name="extruded_5_material">
        <color rgba="0.792157 0.576471 0.509804 1.0"/>
      </material>
    </visual>
    <!-- Part extruded_4_1 -->
    <visual>
      <origin xyz="-0.0926361 0.0115732 0.0764594" rpy="2.35619 -2.01031e-14 1.5708"/>
      <geometry>
        <mesh filename="package://assets/extruded_4_1.stl"/>
      </geometry>
      <material name="extruded_4_1_material">
        <color rgba="0.960784 0.796078 0.207843 1.0"/>
      </material>
    </visual>
    <!-- Part cross_recessed_countersunk_head_screws_gb1_gb_cross_screws_type4_m2x10_8_8__h_type_n_3 -->
    <visual>
      <origin xyz="-0.0926361 0.0115732 0.0764594" rpy="2.35619 -2.01031e-14 1.5708"/>
      <geometry>
        <mesh filename="package://assets/cross_recessed_countersunk_head_screws_gb1_gb_cross_screws_type4_m2x10_8_8__h_type_n_3.stl"/>
      </geometry>
      <material name="cross_recessed_countersunk_head_screws_gb1_gb_cross_screws_type4_m2x10_8_8__h_type_n_3_material">
        <color rgba="0.776471 0.756863 0.737255 1.0"/>
      </material>
    </visual>
    <!-- Part cross_recessed_countersunk_head_screws_gb1_gb_cross_screws_type4_m2x10_8_8__h_type_n -->
    <visual>
      <origin xyz="-0.0926361 0.0115732 0.0764594" rpy="2.35619 -2.01031e-14 1.5708"/>
      <geometry>
        <mesh filename="package://assets/cross_recessed_countersunk_head_screws_gb1_gb_cross_screws_type4_m2x10_8_8__h_type_n.stl"/>
      </geometry>
      <material name="cross_recessed_countersunk_head_screws_gb1_gb_cross_screws_type4_m2x10_8_8__h_type_n_material">
        <color rgba="0.776471 0.756863 0.737255 1.0"/>
      </material>
    </visual>
    <!-- Part extruded_4 -->
    <visual>
      <origin xyz="-0.0926361 0.0115732 0.0764594" rpy="2.35619 -2.01031e-14 1.5708"/>
      <geometry>
        <mesh filename="package://assets/extruded_4.stl"/>
      </geometry>
      <material name="extruded_4_material">
        <color rgba="0.960784 0.796078 0.207843 1.0"/>
      </material>
    </visual>
    <!-- Part extruded_0_1 -->
    <visual>
      <origin xyz="-0.0926361 0.0115732 0.0764594" rpy="2.35619 -2.01031e-14 1.5708"/>
      <geometry>
        <mesh filename="package://assets/extruded_0_1.stl"/>
      </geometry>
      <material name="extruded_0_1_material">
        <color rgba="0.105882 0.580392 0.14902 1.0"/>
      </material>
    </visual>
    <!-- Part user_library_0805_2012m__cap_4 -->
    <visual>
      <origin xyz="0.0362954 -0.0860118 0.0764594" rpy="2.35619 1.99341e-16 -2.61799"/>
      <geometry>
        <mesh filename="package://assets/user_library_0805_2012m__cap__3.stl"/>
      </geometry>
      <material name="user_library_0805_2012m__cap_4_material">
        <color rgba="0.0196078 0.498039 0.341176 1.0"/>
      </material>
    </visual>
    <!-- Part cross_recessed_countersunk_head_screws_gb1_gb_cross_screws_type4_m2x10_8_8__h_type_n_4_2 -->
    <visual>
      <origin xyz="0.0362954 -0.0860118 0.0764594" rpy="2.35619 1.99341e-16 -2.61799"/>
      <geometry>
        <mesh filename="package://assets/cross_recessed_countersunk_head_screws_gb1_gb_cross_screws_type4_m2x10_8_8__h_type_n_4.stl"/>
      </geometry>
      <material name="cross_recessed_countersunk_head_screws_gb1_gb_cross_screws_type4_m2x10_8_8__h_type_n_4_2_material">
        <color rgba="0.776471 0.756863 0.737255 1.0"/>
      </material>
    </visual>
    <!-- Part cross_recessed_countersunk_head_screws_gb1_gb_cross_screws_type4_m2x10_8_8__h_type_n_1_2 -->
    <visual>
      <origin xyz="0.0362954 -0.0860118 0.0764594" rpy="2.35619 1.99341e-16 -2.61799"/>
      <geometry>
        <mesh filename="package://assets/cross_recessed_countersunk_head_screws_gb1_gb_cross_screws_type4_m2x10_8_8__h_type_n_1.stl"/>
      </geometry>
      <material name="cross_recessed_countersunk_head_screws_gb1_gb_cross_screws_type4_m2x10_8_8__h_type_n_1_2_material">
        <color rgba="0.776471 0.756863 0.737255 1.0"/>
      </material>
    </visual>
    <!-- Part hexagon_socket_head_cap_screws_gb_gb_fastener_screws_hshcs_m2x20_n_1_2 -->
    <visual>
      <origin xyz="0.0362954 -0.0860118 0.0764594" rpy="2.35619 1.99341e-16 -2.61799"/>
      <geometry>
        <mesh filename="package://assets/hexagon_socket_head_cap_screws_gb_gb_fastener_screws_hshcs_m2x20_n_1.stl"/>
      </geometry>
      <material name="hexagon_socket_head_cap_screws_gb_gb_fastener_screws_hshcs_m2x20_n_1_2_material">
        <color rgba="0.776471 0.756863 0.737255 1.0"/>
      </material>
    </visual>
    <!-- Part user_library_0805_2012m__cap_5 -->
    <visual>
      <origin xyz="0.0362954 -0.0860118 0.0764594" rpy="2.35619 1.99341e-16 -2.61799"/>
      <geometry>
        <mesh filename="package://assets/user_library_0805_2012m__cap.stl"/>
      </geometry>
      <material name="user_library_0805_2012m__cap_5_material">
        <color rgba="0.0196078 0.498039 0.341176 1.0"/>
      </material>
    </visual>
    <!-- Part extruded_4_2 -->
    <visual>
      <origin xyz="0.0362954 -0.0860118 0.0764594" rpy="2.35619 1.99341e-16 -2.61799"/>
      <geometry>
        <mesh filename="package://assets/extruded_4.stl"/>
      </geometry>
      <material name="extruded_4_2_material">
        <color rgba="0.960784 0.796078 0.207843 1.0"/>
      </material>
    </visual>
    <!-- Part extruded_4_3_2 -->
    <visual>
      <origin xyz="0.0563407 0.0744386 0.0764594" rpy="2.35619 3.18634e-14 -0.523599"/>
      <geometry>
        <mesh filename="package://assets/extruded_4_3.stl"/>
      </geometry>
      <material name="extruded_4_3_2_material">
        <color rgba="0.960784 0.796078 0.207843 1.0"/>
      </material>
    </visual>
    <!-- Part extruded_4_3_3 -->
    <visual>
      <origin xyz="0.0362954 -0.0860118 0.0764594" rpy="2.35619 1.99341e-16 -2.61799"/>
      <geometry>
        <mesh filename="package://assets/extruded_4_3.stl"/>
      </geometry>
      <material name="extruded_4_3_3_material">
        <color rgba="0.960784 0.796078 0.207843 1.0"/>
      </material>
    </visual>
    <!-- Part cross_recessed_countersunk_head_screws_gb1_gb_cross_screws_type4_m2x10_8_8__h_type_n_6_2 -->
    <visual>
      <origin xyz="0.0563407 0.0744386 0.0764594" rpy="2.35619 3.18634e-14 -0.523599"/>
      <geometry>
        <mesh filename="package://assets/cross_recessed_countersunk_head_screws_gb1_gb_cross_screws_type4_m2x10_8_8__h_type_n_6.stl"/>
      </geometry>
      <material name="cross_recessed_countersunk_head_screws_gb1_gb_cross_screws_type4_m2x10_8_8__h_type_n_6_2_material">
        <color rgba="0.776471 0.756863 0.737255 1.0"/>
      </material>
    </visual>
    <!-- Part cross_recessed_countersunk_head_screws_gb1_gb_cross_screws_type4_m2x10_8_8__h_type_n_6_3 -->
    <visual>
      <origin xyz="0.0362954 -0.0860118 0.0764594" rpy="2.35619 1.99341e-16 -2.61799"/>
      <geometry>
        <mesh filename="package://assets/cross_recessed_countersunk_head_screws_gb1_gb_cross_screws_type4_m2x10_8_8__h_type_n_6.stl"/>
      </geometry>
      <material name="cross_recessed_countersunk_head_screws_gb1_gb_cross_screws_type4_m2x10_8_8__h_type_n_6_3_material">
        <color rgba="0.776471 0.756863 0.737255 1.0"/>
      </material>
    </visual>
    <!-- Part extruded_6_2 -->
    <visual>
      <origin xyz="0.0362954 -0.0860118 0.0764594" rpy="2.35619 1.99341e-16 -2.61799"/>
      <geometry>
        <mesh filename="package://assets/extruded_6.stl"/>
      </geometry>
      <material name="extruded_6_2_material">
        <color rgba="0.00784314 0.392157 0.72549 1.0"/>
      </material>
    </visual>
    <!-- Part cross_recessed_countersunk_head_screws_gb1_gb_cross_screws_type4_m2x10_8_8__h_type_n_2_2 -->
    <visual>
      <origin xyz="0.0563407 0.0744386 0.0764594" rpy="2.35619 3.18634e-14 -0.523599"/>
      <geometry>
        <mesh filename="package://assets/cross_recessed_countersunk_head_screws_gb1_gb_cross_screws_type4_m2x10_8_8__h_type_n_2.stl"/>
      </geometry>
      <material name="cross_recessed_countersunk_head_screws_gb1_gb_cross_screws_type4_m2x10_8_8__h_type_n_2_2_material">
        <color rgba="0.776471 0.756863 0.737255 1.0"/>
      </material>
    </visual>
    <!-- Part cra_ri30_40_pro_xx_后盖_2 -->
    <visual>
      <origin xyz="0.0362954 -0.0860118 0.0764594" rpy="2.35619 6.00895e-16 -2.61799"/>
      <geometry>
        <mesh filename="package://assets/cra_ri30_40_pro_xx_后盖.stl"/>
      </geometry>
      <material name="cra_ri30_40_pro_xx_后盖_2_material">
        <color rgba="0.690196 0.764706 0.0196078 1.0"/>
      </material>
    </visual>
    <!-- Part extruded_0_1_2 -->
    <visual>
      <origin xyz="0.0362954 -0.0860118 0.0764594" rpy="2.35619 1.99341e-16 -2.61799"/>
      <geometry>
        <mesh filename="package://assets/extruded_0_1.stl"/>
      </geometry>
      <material name="extruded_0_1_2_material">
        <color rgba="0.105882 0.580392 0.14902 1.0"/>
      </material>
    </visual>
    <!-- Part cra_ri30_40_xx_b_电机壳_1_2 -->
    <visual>
      <origin xyz="0.0362954 -0.0860118 0.0764594" rpy="2.35619 1.99341e-16 -2.61799"/>
      <geometry>
        <mesh filename="package://assets/cra_ri30_40_xx_b_电机壳_1.stl"/>
      </geometry>
      <material name="cra_ri30_40_xx_b_电机壳_1_2_material">
        <color rgba="0.898039 0.917647 0.929412 1.0"/>
      </material>
    </visual>
    <!-- Part extruded_0_1_3 -->
    <visual>
      <origin xyz="0.0563407 0.0744386 0.0764594" rpy="2.35619 3.18634e-14 -0.523599"/>
      <geometry>
        <mesh filename="package://assets/extruded_0_1.stl"/>
      </geometry>
      <material name="extruded_0_1_3_material">
        <color rgba="0.105882 0.580392 0.14902 1.0"/>
      </material>
    </visual>
    <!-- Part extruded_1_3 -->
    <visual>
      <origin xyz="0.0563407 0.0744386 0.0764594" rpy="2.35619 3.18634e-14 -0.523599"/>
      <geometry>
        <mesh filename="package://assets/extruded_1__2.stl"/>
      </geometry>
      <material name="extruded_1_3_material">
        <color rgba="0.435294 0.792157 0.176471 1.0"/>
      </material>
    </visual>
    <!-- Part cross_recessed_countersunk_head_screws_gb1_gb_cross_screws_type4_m2x10_8_8__h_type_n_2 -->
    <visual>
      <origin xyz="0.0362954 -0.0860118 0.0764594" rpy="2.35619 1.99341e-16 -2.61799"/>
      <geometry>
        <mesh filename="package://assets/cross_recessed_countersunk_head_screws_gb1_gb_cross_screws_type4_m2x10_8_8__h_type_n.stl"/>
      </geometry>
      <material name="cross_recessed_countersunk_head_screws_gb1_gb_cross_screws_type4_m2x10_8_8__h_type_n_2_material">
        <color rgba="0.776471 0.756863 0.737255 1.0"/>
      </material>
    </visual>
    <!-- Part extruded_2 -->
    <visual>
      <origin xyz="0.0362954 -0.0860118 0.0764594" rpy="2.35619 1.99341e-16 -2.61799"/>
      <geometry>
        <mesh filename="package://assets/extruded.stl"/>
      </geometry>
      <material name="extruded_2_material">
        <color rgba="0.14902 0.180392 0.435294 1.0"/>
      </material>
    </visual>
    <!-- Part extruded_2_2 -->
    <visual>
      <origin xyz="0.0362954 -0.0860118 0.0764594" rpy="2.35619 1.99341e-16 -2.61799"/>
      <geometry>
        <mesh filename="package://assets/extruded_2.stl"/>
      </geometry>
      <material name="extruded_2_2_material">
        <color rgba="0.176471 0.0431373 0.792157 1.0"/>
      </material>
    </visual>
    <!-- Part user_library_0805_2012m__cap_6 -->
    <visual>
      <origin xyz="0.0563407 0.0744386 0.0764594" rpy="2.35619 3.18634e-14 -0.523599"/>
      <geometry>
        <mesh filename="package://assets/user_library_0805_2012m__cap__2.stl"/>
      </geometry>
      <material name="user_library_0805_2012m__cap_6_material">
        <color rgba="1 1 1 1.0"/>
      </material>
    </visual>
    <!-- Part extruded_4_4_2 -->
    <visual>
      <origin xyz="0.0563407 0.0744386 0.0764594" rpy="2.35619 3.18634e-14 -0.523599"/>
      <geometry>
        <mesh filename="package://assets/extruded_4_4.stl"/>
      </geometry>
      <material name="extruded_4_4_2_material">
        <color rgba="0.960784 0.796078 0.207843 1.0"/>
      </material>
    </visual>
    <!-- Part extruded_1_4 -->
    <visual>
      <origin xyz="0.0563407 0.0744386 0.0764594" rpy="2.35619 3.18634e-14 -0.523599"/>
      <geometry>
        <mesh filename="package://assets/extruded_1.stl"/>
      </geometry>
      <material name="extruded_1_4_material">
        <color rgba="0.14902 0.180392 0.435294 1.0"/>
      </material>
    </visual>
    <!-- Part cra_ri30_40_xx_柔轮盖_2 -->
    <visual>
      <origin xyz="0.0362954 -0.0860118 0.0764594" rpy="2.35619 1.99341e-16 -2.61799"/>
      <geometry>
        <mesh filename="package://assets/cra_ri30_40_xx_柔轮盖.stl"/>
      </geometry>
      <material name="cra_ri30_40_xx_柔轮盖_2_material">
        <color rgba="0.368627 0.941176 0.733333 1.0"/>
      </material>
    </visual>
    <!-- Part cross_recessed_countersunk_head_screws_gb1_gb_cross_screws_type4_m2x10_8_8__h_type_n_2_3 -->
    <visual>
      <origin xyz="0.0362954 -0.0860118 0.0764594" rpy="2.35619 1.99341e-16 -2.61799"/>
      <geometry>
        <mesh filename="package://assets/cross_recessed_countersunk_head_screws_gb1_gb_cross_screws_type4_m2x10_8_8__h_type_n_2.stl"/>
      </geometry>
      <material name="cross_recessed_countersunk_head_screws_gb1_gb_cross_screws_type4_m2x10_8_8__h_type_n_2_3_material">
        <color rgba="0.776471 0.756863 0.737255 1.0"/>
      </material>
    </visual>
    <!-- Part extruded_6_3 -->
    <visual>
      <origin xyz="0.0563407 0.0744386 0.0764594" rpy="2.35619 3.18634e-14 -0.523599"/>
      <geometry>
        <mesh filename="package://assets/extruded_6.stl"/>
      </geometry>
      <material name="extruded_6_3_material">
        <color rgba="0.00784314 0.392157 0.72549 1.0"/>
      </material>
    </visual>
    <!-- Part extruded_3 -->
    <visual>
      <origin xyz="0.0563407 0.0744386 0.0764594" rpy="2.35619 3.18634e-14 -0.523599"/>
      <geometry>
        <mesh filename="package://assets/extruded.stl"/>
      </geometry>
      <material name="extruded_3_material">
        <color rgba="0.14902 0.180392 0.435294 1.0"/>
      </material>
    </visual>
    <!-- Part lsg_8_减速器外圈固定_1_2 -->
    <visual>
      <origin xyz="0.0563407 0.0744386 0.0764594" rpy="2.35619 3.18634e-14 -0.523599"/>
      <geometry>
        <mesh filename="package://assets/lsg_8_减速器外圈固定_1.stl"/>
      </geometry>
      <material name="lsg_8_减速器外圈固定_1_2_material">
        <color rgba="0.898039 0.917647 0.929412 1.0"/>
      </material>
    </visual>
    <!-- Part lsg_08_柔轮_2 -->
    <visual>
      <origin xyz="0.0563407 0.0744386 0.0764594" rpy="2.35619 3.18634e-14 -0.523599"/>
      <geometry>
        <mesh filename="package://assets/lsg_08_柔轮.stl"/>
      </geometry>
      <material name="lsg_08_柔轮_2_material">
        <color rgba="1 1 1 1.0"/>
      </material>
    </visual>
    <!-- Part cra_ri30_40_xx_柔轮盖_3 -->
    <visual>
      <origin xyz="0.0563407 0.0744386 0.0764594" rpy="2.35619 3.18634e-14 -0.523599"/>
      <geometry>
        <mesh filename="package://assets/cra_ri30_40_xx_柔轮盖.stl"/>
      </geometry>
      <material name="cra_ri30_40_xx_柔轮盖_3_material">
        <color rgba="0.368627 0.941176 0.733333 1.0"/>
      </material>
    </visual>
    <!-- Part extruded_5_2 -->
    <visual>
      <origin xyz="0.0362954 -0.0860118 0.0764594" rpy="2.35619 1.99341e-16 -2.61799"/>
      <geometry>
        <mesh filename="package://assets/extruded_5.stl"/>
      </geometry>
      <material name="extruded_5_2_material">
        <color rgba="0.792157 0.576471 0.509804 1.0"/>
      </material>
    </visual>
    <!-- Part extruded_5_3 -->
    <visual>
      <origin xyz="0.0563407 0.0744386 0.0764594" rpy="2.35619 3.18634e-14 -0.523599"/>
      <geometry>
        <mesh filename="package://assets/extruded_5.stl"/>
      </geometry>
      <material name="extruded_5_3_material">
        <color rgba="0.792157 0.576471 0.509804 1.0"/>
      </material>
    </visual>
    <!-- Part cross_recessed_countersunk_head_screws_gb1_gb_cross_screws_type4_m2x10_8_8__h_type_n_3 -->
    <visual>
      <origin xyz="0.0563407 0.0744386 0.0764594" rpy="2.35619 3.18634e-14 -0.523599"/>
      <geometry>
        <mesh filename="package://assets/cross_recessed_countersunk_head_screws_gb1_gb_cross_screws_type4_m2x10_8_8__h_type_n.stl"/>
      </geometry>
      <material name="cross_recessed_countersunk_head_screws_gb1_gb_cross_screws_type4_m2x10_8_8__h_type_n_3_material">
        <color rgba="0.776471 0.756863 0.737255 1.0"/>
      </material>
    </visual>
    <!-- Part cross_recessed_countersunk_head_screws_gb1_gb_cross_screws_type4_m2x10_8_8__h_type_n_3_2 -->
    <visual>
      <origin xyz="0.0362954 -0.0860118 0.0764594" rpy="2.35619 1.99341e-16 -2.61799"/>
      <geometry>
        <mesh filename="package://assets/cross_recessed_countersunk_head_screws_gb1_gb_cross_screws_type4_m2x10_8_8__h_type_n_3.stl"/>
      </geometry>
      <material name="cross_recessed_countersunk_head_screws_gb1_gb_cross_screws_type4_m2x10_8_8__h_type_n_3_2_material">
        <color rgba="0.776471 0.756863 0.737255 1.0"/>
      </material>
    </visual>
    <!-- Part extruded_1_5 -->
    <visual>
      <origin xyz="0.0362954 -0.0860118 0.0764594" rpy="2.35619 1.99341e-16 -2.61799"/>
      <geometry>
        <mesh filename="package://assets/extruded_1__2.stl"/>
      </geometry>
      <material name="extruded_1_5_material">
        <color rgba="0.435294 0.792157 0.176471 1.0"/>
      </material>
    </visual>
    <!-- Part extruded_4_2_2 -->
    <visual>
      <origin xyz="0.0563407 0.0744386 0.0764594" rpy="2.35619 3.18634e-14 -0.523599"/>
      <geometry>
        <mesh filename="package://assets/extruded_4_2.stl"/>
      </geometry>
      <material name="extruded_4_2_2_material">
        <color rgba="0.960784 0.796078 0.207843 1.0"/>
      </material>
    </visual>
    <!-- Part b08_cra_ri30_40_pro_xx_客户参考_2 -->
    <visual>
      <origin xyz="0.0563407 0.0744386 0.0764594" rpy="2.35619 3.18634e-14 -0.523599"/>
      <geometry>
        <mesh filename="package://assets/b08_cra_ri30_40_pro_xx_客户参考.stl"/>
      </geometry>
      <material name="b08_cra_ri30_40_pro_xx_客户参考_2_material">
        <color rgba="1 1 1 1.0"/>
      </material>
    </visual>
    <!-- Part cra_ri30_40_xx_b_电机壳_1_3 -->
    <visual>
      <origin xyz="0.0563407 0.0744386 0.0764594" rpy="2.35619 3.18634e-14 -0.523599"/>
      <geometry>
        <mesh filename="package://assets/cra_ri30_40_xx_b_电机壳_1.stl"/>
      </geometry>
      <material name="cra_ri30_40_xx_b_电机壳_1_3_material">
        <color rgba="0.898039 0.917647 0.929412 1.0"/>
      </material>
    </visual>
    <!-- Part extruded_1_6 -->
    <visual>
      <origin xyz="0.0362954 -0.0860118 0.0764594" rpy="2.35619 1.99341e-16 -2.61799"/>
      <geometry>
        <mesh filename="package://assets/extruded_1.stl"/>
      </geometry>
      <material name="extruded_1_6_material">
        <color rgba="0.14902 0.180392 0.435294 1.0"/>
      </material>
    </visual>
    <!-- Part extruded_0_2 -->
    <visual>
      <origin xyz="0.0362954 -0.0860118 0.0764594" rpy="2.35619 1.99341e-16 -2.61799"/>
      <geometry>
        <mesh filename="package://assets/extruded_0.stl"/>
      </geometry>
      <material name="extruded_0_2_material">
        <color rgba="0.105882 0.580392 0.14902 1.0"/>
      </material>
    </visual>
    <!-- Part lsg_08_柔轮_3 -->
    <visual>
      <origin xyz="0.0362954 -0.0860118 0.0764594" rpy="2.35619 1.99341e-16 -2.61799"/>
      <geometry>
        <mesh filename="package://assets/lsg_08_柔轮.stl"/>
      </geometry>
      <material name="lsg_08_柔轮_3_material">
        <color rgba="1 1 1 1.0"/>
      </material>
    </visual>
    <!-- Part user_library_0805_2012m__cap_7 -->
    <visual>
      <origin xyz="0.0563407 0.0744386 0.0764594" rpy="2.35619 3.18634e-14 -0.523599"/>
      <geometry>
        <mesh filename="package://assets/user_library_0805_2012m__cap__3.stl"/>
      </geometry>
      <material name="user_library_0805_2012m__cap_7_material">
        <color rgba="0.0196078 0.498039 0.341176 1.0"/>
      </material>
    </visual>
    <!-- Part hexagon_socket_head_cap_screws_gb_gb_fastener_screws_hshcs_m2x20_n_2 -->
    <visual>
      <origin xyz="0.0563407 0.0744386 0.0764594" rpy="2.35619 3.18634e-14 -0.523599"/>
      <geometry>
        <mesh filename="package://assets/hexagon_socket_head_cap_screws_gb_gb_fastener_screws_hshcs_m2x20_n.stl"/>
      </geometry>
      <material name="hexagon_socket_head_cap_screws_gb_gb_fastener_screws_hshcs_m2x20_n_2_material">
        <color rgba="0.776471 0.756863 0.737255 1.0"/>
      </material>
    </visual>
    <!-- Part extruded_4_1_2 -->
    <visual>
      <origin xyz="0.0563407 0.0744386 0.0764594" rpy="2.35619 3.18634e-14 -0.523599"/>
      <geometry>
        <mesh filename="package://assets/extruded_4_1.stl"/>
      </geometry>
      <material name="extruded_4_1_2_material">
        <color rgba="0.960784 0.796078 0.207843 1.0"/>
      </material>
    </visual>
    <!-- Part hexagon_socket_head_cap_screws_gb_gb_fastener_screws_hshcs_m2x20_n_1_3 -->
    <visual>
      <origin xyz="0.0563407 0.0744386 0.0764594" rpy="2.35619 3.18634e-14 -0.523599"/>
      <geometry>
        <mesh filename="package://assets/hexagon_socket_head_cap_screws_gb_gb_fastener_screws_hshcs_m2x20_n_1.stl"/>
      </geometry>
      <material name="hexagon_socket_head_cap_screws_gb_gb_fastener_screws_hshcs_m2x20_n_1_3_material">
        <color rgba="0.776471 0.756863 0.737255 1.0"/>
      </material>
    </visual>
    <!-- Part b08_cra_ri30_40_pro_xx_客户参考_3 -->
    <visual>
      <origin xyz="0.0362954 -0.0860118 0.0764594" rpy="2.35619 1.99341e-16 -2.61799"/>
      <geometry>
        <mesh filename="package://assets/b08_cra_ri30_40_pro_xx_客户参考.stl"/>
      </geometry>
      <material name="b08_cra_ri30_40_pro_xx_客户参考_3_material">
        <color rgba="1 1 1 1.0"/>
      </material>
    </visual>
    <!-- Part cross_recessed_countersunk_head_screws_gb1_gb_cross_screws_type4_m2x10_8_8__h_type_n_5_2 -->
    <visual>
      <origin xyz="0.0563407 0.0744386 0.0764594" rpy="2.35619 3.18634e-14 -0.523599"/>
      <geometry>
        <mesh filename="package://assets/cross_recessed_countersunk_head_screws_gb1_gb_cross_screws_type4_m2x10_8_8__h_type_n_5.stl"/>
      </geometry>
      <material name="cross_recessed_countersunk_head_screws_gb1_gb_cross_screws_type4_m2x10_8_8__h_type_n_5_2_material">
        <color rgba="0.776471 0.756863 0.737255 1.0"/>
      </material>
    </visual>
    <!-- Part user_library_0805_2012m__cap_8 -->
    <visual>
      <origin xyz="0.0362954 -0.0860118 0.0764594" rpy="2.35619 1.99341e-16 -2.61799"/>
      <geometry>
        <mesh filename="package://assets/user_library_0805_2012m__cap__2.stl"/>
      </geometry>
      <material name="user_library_0805_2012m__cap_8_material">
        <color rgba="1 1 1 1.0"/>
      </material>
    </visual>
    <!-- Part extruded_4_3 -->
    <visual>
      <origin xyz="0.0563407 0.0744386 0.0764594" rpy="2.35619 3.18634e-14 -0.523599"/>
      <geometry>
        <mesh filename="package://assets/extruded_4.stl"/>
      </geometry>
      <material name="extruded_4_3_material">
        <color rgba="0.960784 0.796078 0.207843 1.0"/>
      </material>
    </visual>
    <!-- Part cross_recessed_countersunk_head_screws_gb1_gb_cross_screws_type4_m2x10_8_8__h_type_n_1_3 -->
    <visual>
      <origin xyz="0.0563407 0.0744386 0.0764594" rpy="2.35619 3.18634e-14 -0.523599"/>
      <geometry>
        <mesh filename="package://assets/cross_recessed_countersunk_head_screws_gb1_gb_cross_screws_type4_m2x10_8_8__h_type_n_1.stl"/>
      </geometry>
      <material name="cross_recessed_countersunk_head_screws_gb1_gb_cross_screws_type4_m2x10_8_8__h_type_n_1_3_material">
        <color rgba="0.776471 0.756863 0.737255 1.0"/>
      </material>
    </visual>
    <!-- Part cross_recessed_countersunk_head_screws_gb1_gb_cross_screws_type4_m2x10_8_8__h_type_n_3_3 -->
    <visual>
      <origin xyz="0.0563407 0.0744386 0.0764594" rpy="2.35619 3.18634e-14 -0.523599"/>
      <geometry>
        <mesh filename="package://assets/cross_recessed_countersunk_head_screws_gb1_gb_cross_screws_type4_m2x10_8_8__h_type_n_3.stl"/>
      </geometry>
      <material name="cross_recessed_countersunk_head_screws_gb1_gb_cross_screws_type4_m2x10_8_8__h_type_n_3_3_material">
        <color rgba="0.776471 0.756863 0.737255 1.0"/>
      </material>
    </visual>
    <!-- Part extruded_4_2_3 -->
    <visual>
      <origin xyz="0.0362954 -0.0860118 0.0764594" rpy="2.35619 1.99341e-16 -2.61799"/>
      <geometry>
        <mesh filename="package://assets/extruded_4_2.stl"/>
      </geometry>
      <material name="extruded_4_2_3_material">
        <color rgba="0.960784 0.796078 0.207843 1.0"/>
      </material>
    </visual>
    <!-- Part cross_recessed_countersunk_head_screws_gb1_gb_cross_screws_type4_m2x10_8_8__h_type_n_5_3 -->
    <visual>
      <origin xyz="0.0362954 -0.0860118 0.0764594" rpy="2.35619 1.99341e-16 -2.61799"/>
      <geometry>
        <mesh filename="package://assets/cross_recessed_countersunk_head_screws_gb1_gb_cross_screws_type4_m2x10_8_8__h_type_n_5.stl"/>
      </geometry>
      <material name="cross_recessed_countersunk_head_screws_gb1_gb_cross_screws_type4_m2x10_8_8__h_type_n_5_3_material">
        <color rgba="0.776471 0.756863 0.737255 1.0"/>
      </material>
    </visual>
    <!-- Part user_library_0805_2012m__cap_9 -->
    <visual>
      <origin xyz="0.0563407 0.0744386 0.0764594" rpy="2.35619 3.18634e-14 -0.523599"/>
      <geometry>
        <mesh filename="package://assets/user_library_0805_2012m__cap.stl"/>
      </geometry>
      <material name="user_library_0805_2012m__cap_9_material">
        <color rgba="0.0196078 0.498039 0.341176 1.0"/>
      </material>
    </visual>
    <!-- Part cross_recessed_countersunk_head_screws_gb1_gb_cross_screws_type4_m2x10_8_8__h_type_n_4_3 -->
    <visual>
      <origin xyz="0.0563407 0.0744386 0.0764594" rpy="2.35619 3.18634e-14 -0.523599"/>
      <geometry>
        <mesh filename="package://assets/cross_recessed_countersunk_head_screws_gb1_gb_cross_screws_type4_m2x10_8_8__h_type_n_4.stl"/>
      </geometry>
      <material name="cross_recessed_countersunk_head_screws_gb1_gb_cross_screws_type4_m2x10_8_8__h_type_n_4_3_material">
        <color rgba="0.776471 0.756863 0.737255 1.0"/>
      </material>
    </visual>
    <!-- Part extruded_0_3 -->
    <visual>
      <origin xyz="0.0563407 0.0744386 0.0764594" rpy="2.35619 3.18634e-14 -0.523599"/>
      <geometry>
        <mesh filename="package://assets/extruded_0.stl"/>
      </geometry>
      <material name="extruded_0_3_material">
        <color rgba="0.105882 0.580392 0.14902 1.0"/>
      </material>
    </visual>
    <!-- Part hexagon_socket_head_cap_screws_gb_gb_fastener_screws_hshcs_m2x20_n_3 -->
    <visual>
      <origin xyz="0.0362954 -0.0860118 0.0764594" rpy="2.35619 1.99341e-16 -2.61799"/>
      <geometry>
        <mesh filename="package://assets/hexagon_socket_head_cap_screws_gb_gb_fastener_screws_hshcs_m2x20_n.stl"/>
      </geometry>
      <material name="hexagon_socket_head_cap_screws_gb_gb_fastener_screws_hshcs_m2x20_n_3_material">
        <color rgba="0.776471 0.756863 0.737255 1.0"/>
      </material>
    </visual>
    <!-- Part extruded_4_4_3 -->
    <visual>
      <origin xyz="0.0362954 -0.0860118 0.0764594" rpy="2.35619 1.99341e-16 -2.61799"/>
      <geometry>
        <mesh filename="package://assets/extruded_4_4.stl"/>
      </geometry>
      <material name="extruded_4_4_3_material">
        <color rgba="0.960784 0.796078 0.207843 1.0"/>
      </material>
    </visual>
    <!-- Part extruded_4_5_2 -->
    <visual>
      <origin xyz="0.0563407 0.0744386 0.0764594" rpy="2.35619 3.18634e-14 -0.523599"/>
      <geometry>
        <mesh filename="package://assets/extruded_4_5.stl"/>
      </geometry>
      <material name="extruded_4_5_2_material">
        <color rgba="0.960784 0.796078 0.207843 1.0"/>
      </material>
    </visual>
    <!-- Part lsg_8_减速器外圈固定_1_3 -->
    <visual>
      <origin xyz="0.0362954 -0.0860118 0.0764594" rpy="2.35619 1.607e-16 -2.61799"/>
      <geometry>
        <mesh filename="package://assets/lsg_8_减速器外圈固定_1.stl"/>
      </geometry>
      <material name="lsg_8_减速器外圈固定_1_3_material">
        <color rgba="0.898039 0.917647 0.929412 1.0"/>
      </material>
    </visual>
    <!-- Part cra_ri30_40_pro_xx_后盖_3 -->
    <visual>
      <origin xyz="0.0563407 0.0744386 0.0764594" rpy="2.35619 3.18634e-14 -0.523599"/>
      <geometry>
        <mesh filename="package://assets/cra_ri30_40_pro_xx_后盖.stl"/>
      </geometry>
      <material name="cra_ri30_40_pro_xx_后盖_3_material">
        <color rgba="0.690196 0.764706 0.0196078 1.0"/>
      </material>
    </visual>
    <!-- Part extruded_2_3 -->
    <visual>
      <origin xyz="0.0563407 0.0744386 0.0764594" rpy="2.35619 3.18634e-14 -0.523599"/>
      <geometry>
        <mesh filename="package://assets/extruded_2.stl"/>
      </geometry>
      <material name="extruded_2_3_material">
        <color rgba="0.176471 0.0431373 0.792157 1.0"/>
      </material>
    </visual>
    <!-- Part extruded_4_5_3 -->
    <visual>
      <origin xyz="0.0362954 -0.0860118 0.0764594" rpy="2.35619 1.99341e-16 -2.61799"/>
      <geometry>
        <mesh filename="package://assets/extruded_4_5.stl"/>
      </geometry>
      <material name="extruded_4_5_3_material">
        <color rgba="0.960784 0.796078 0.207843 1.0"/>
      </material>
    </visual>
    <!-- Part extruded_4_1_3 -->
    <visual>
      <origin xyz="0.0362954 -0.0860118 0.0764594" rpy="2.35619 1.99341e-16 -2.61799"/>
      <geometry>
        <mesh filename="package://assets/extruded_4_1.stl"/>
      </geometry>
      <material name="extruded_4_1_3_material">
        <color rgba="0.960784 0.796078 0.207843 1.0"/>
      </material>
    </visual>
  </link>
  <!-- Link 2_arbremoteur3 -->
  <link name="2_arbremoteur3">
    <inertial>
      <origin xyz="0.0107909 -0.00909413 -0.0175921" rpy="0 0 0"/>
      <mass value="0.0293635"/>
      <inertia ixx="1.73972e-05" ixy="4.85555e-06" ixz="6.98022e-06" iyy="1.81718e-05" iyz="-7.26176e-06" izz="1.24115e-05"/>
    </inertial>
    <!-- Part dbtm3_14_5 -->
    <visual>
      <origin xyz="0.0307218 -0.0376264 -0.0600264" rpy="-1.36944 0.25268 2.25552"/>
      <geometry>
        <mesh filename="package://assets/dbtm3_14_5.stl"/>
      </geometry>
      <material name="dbtm3_14_5_material">
        <color rgba="0.690196 0.690196 0.690196 1.0"/>
      </material>
    </visual>
    <!-- Part 2_arbremoteur3 -->
    <visual>
      <origin xyz="0.0115732 -0.04 0.0184386" rpy="-1.5708 1.14939e-30 -8.75143e-31"/>
      <geometry>
        <mesh filename="package://assets/2_arbremoteur3.stl"/>
      </geometry>
      <material name="2_arbremoteur3_material">
        <color rgba="0.615686 0.811765 0.929412 1.0"/>
      </material>
    </visual>
    <collision>
      <origin xyz="0.0115732 -0.04 0.0184386" rpy="-1.5708 1.14939e-30 -8.75143e-31"/>
      <geometry>
        <mesh filename="package://assets/2_arbremoteur3.stl"/>
      </geometry>
    </collision>
    <!-- Part sfl676zz -->
    <visual>
      <origin xyz="0.0288847 -0.0353764 -0.0607764" rpy="-1.77215 -0.25268 -0.886077"/>
      <geometry>
        <mesh filename="package://assets/sfl676zz.stl"/>
      </geometry>
      <material name="sfl676zz_material">
        <color rgba="0.917647 0.917647 0.917647 1.0"/>
      </material>
    </visual>
  </link>
  <!-- Link 3_lien2 -->
  <link name="3_lien2">
    <inertial>
      <origin xyz="0.0153881 0.00162035 -0.0217923" rpy="0 0 0"/>
      <mass value="0.0118051"/>
      <inertia ixx="3.6573e-06" ixy="-1.03018e-07" ixz="1.62019e-06" iyy="4.83538e-06" iyz="-2.61509e-08" izz="1.52639e-06"/>
    </inertial>
    <!-- Part dbtm3_14_5_2 -->
    <visual>
      <origin xyz="0.0206151 2.22045e-15 -0.0478913" rpy="3.14159 0.25268 9.10057e-15"/>
      <geometry>
        <mesh filename="package://assets/dbtm3_14_5.stl"/>
      </geometry>
      <material name="dbtm3_14_5_2_material">
        <color rgba="0.690196 0.690196 0.690196 1.0"/>
      </material>
    </visual>
    <!-- Part sfl676zz_2 -->
    <visual>
      <origin xyz="-2.77556e-17 1.38778e-17 -0.0046" rpy="3.14159 1.5708 0"/>
      <geometry>
        <mesh filename="package://assets/sfl676zz.stl"/>
      </geometry>
      <material name="sfl676zz_2_material">
        <color rgba="0.917647 0.917647 0.917647 1.0"/>
      </material>
    </visual>
    <!-- Part sfl676zz_3 -->
    <visual>
      <origin xyz="0.0235199 2.24126e-15 -0.0486413" rpy="9.03006e-15 -0.25268 -3.14159"/>
      <geometry>
        <mesh filename="package://assets/sfl676zz.stl"/>
      </geometry>
      <material name="sfl676zz_3_material">
        <color rgba="0.917647 0.917647 0.917647 1.0"/>
      </material>
    </visual>
    <!-- Part 3_lien2 -->
    <visual>
      <origin xyz="-0.031712 0.0736879 0.0172703" rpy="-2.81984 -0.659058 8.2896e-15"/>
      <geometry>
        <mesh filename="package://assets/3_lien2.stl"/>
      </geometry>
      <material name="3_lien2_material">
        <color rgba="0.647059 0.647059 0.647059 1.0"/>
      </material>
    </visual>
    <collision>
      <origin xyz="-0.031712 0.0736879 0.0172703" rpy="-2.81984 -0.659058 8.2896e-15"/>
      <geometry>
        <mesh filename="package://assets/3_lien2.stl"/>
      </geometry>
    </collision>
    <!-- Part hex_thin_nut_grade_a___b_m3__1f32078b7141c356c1ef5a853a7893b2 -->
    <visual>
      <origin xyz="-2.77556e-17 1.38778e-17 -0.0085" rpy="3.14159 9.0895e-15 6.96076e-15"/>
      <geometry>
        <mesh filename="package://assets/hex_thin_nut_grade_a___b_m3__1f32078b7141c356c1ef5a853a7893b2.stl"/>
      </geometry>
      <material name="hex_thin_nut_grade_a___b_m3__1f32078b7141c356c1ef5a853a7893b2_material">
        <color rgba="0.603922 0.647059 0.686275 1.0"/>
      </material>
    </visual>
  </link>
  <!-- Link 4_supporthead -->
  <link name="4_supporthead">
    <inertial>
      <origin xyz="-0.0158547 -0.0129454 0.0084229" rpy="0 0 0"/>
      <mass value="0.0273657"/>
      <inertia ixx="6.25196e-06" ixy="1.01863e-06" ixz="1.61059e-06" iyy="5.8361e-06" iyz="1.31505e-06" izz="7.08366e-06"/>
    </inertial>
    <!-- Part 4_supporthead -->
    <visual>
      <origin xyz="0.0500108 0.0736879 0.0745559" rpy="-2.81984 0.659058 -1.44144e-14"/>
      <geometry>
        <mesh filename="package://assets/4_supporthead.stl"/>
      </geometry>
      <material name="4_supporthead_material">
        <color rgba="0.917647 0.917647 0.917647 1.0"/>
      </material>
    </visual>
    <!-- Part sfl676zz_4 -->
    <visual>
      <origin xyz="9.16628e-15 2.98372e-15 -0.0026" rpy="-3.14159 1.5708 0"/>
      <geometry>
        <mesh filename="package://assets/sfl676zz.stl"/>
      </geometry>
      <material name="sfl676zz_4_material">
        <color rgba="0.917647 0.917647 0.917647 1.0"/>
      </material>
    </visual>
    <!-- Part hex_thin_nut_grade_a___b_m3__1f32078b7141c356c1ef5a853a7893b2_2 -->
    <visual>
      <origin xyz="9.17322e-15 2.98372e-15 -0.0065" rpy="1.13424e-14 5.08248e-15 -1.16676e-14"/>
      <geometry>
        <mesh filename="package://assets/hex_thin_nut_grade_a___b_m3__1f32078b7141c356c1ef5a853a7893b2.stl"/>
      </geometry>
      <material name="hex_thin_nut_grade_a___b_m3__1f32078b7141c356c1ef5a853a7893b2_2_material">
        <color rgba="0.603922 0.647059 0.686275 1.0"/>
      </material>
    </visual>
    <!-- Part hex_thin_nut_grade_a___b_m3__1f32078b7141c356c1ef5a853a7893b2_3 -->
    <visual>
      <origin xyz="-0.00685348 -0.033575 0.0200434" rpy="-1.24905 0.659058 2.29931e-14"/>
      <geometry>
        <mesh filename="package://assets/hex_thin_nut_grade_a___b_m3__1f32078b7141c356c1ef5a853a7893b2.stl"/>
      </geometry>
      <material name="hex_thin_nut_grade_a___b_m3__1f32078b7141c356c1ef5a853a7893b2_3_material">
        <color rgba="0.603922 0.647059 0.686275 1.0"/>
      </material>
    </visual>
    <!-- Part hex_thin_nut_grade_a___b_m3__1f32078b7141c356c1ef5a853a7893b2_4 -->
    <visual>
      <origin xyz="-0.0342674 -6.59195e-16 0.0200434" rpy="3.39119e-14 1.31812 -1.04307e-14"/>
      <geometry>
        <mesh filename="package://assets/hex_thin_nut_grade_a___b_m3__1f32078b7141c356c1ef5a853a7893b2.stl"/>
      </geometry>
      <material name="hex_thin_nut_grade_a___b_m3__1f32078b7141c356c1ef5a853a7893b2_4_material">
        <color rgba="0.603922 0.647059 0.686275 1.0"/>
      </material>
    </visual>
    <!-- Part sfl676zz_5 -->
    <visual>
      <origin xyz="-0.00609825 -0.0298752 0.0210184" rpy="0.886077 0.25268 -1.77215"/>
      <geometry>
        <mesh filename="package://assets/sfl676zz.stl"/>
      </geometry>
      <material name="sfl676zz_5_material">
        <color rgba="0.917647 0.917647 0.917647 1.0"/>
      </material>
    </visual>
    <!-- Part sfl676zz_6 -->
    <visual>
      <origin xyz="-0.0304912 -4.85723e-16 0.0210184" rpy="-9.23743e-15 0.25268 -3.14159"/>
      <geometry>
        <mesh filename="package://assets/sfl676zz.stl"/>
      </geometry>
      <material name="sfl676zz_6_material">
        <color rgba="0.917647 0.917647 0.917647 1.0"/>
      </material>
    </visual>
  </link>
  <!-- Frame effector (dummy link + fixed joint) -->
  <link name="effector">
    <origin xyz="0 0 0" rpy="0 -0 0"/>
    <inertial>
      <origin xyz="0 0 0" rpy="0 0 0"/>
      <mass value="1e-9"/>
      <inertia ixx="0" ixy="0" ixz="0" iyy="0" iyz="0" izz="0"/>
    </inertial>
  </link>
  <joint name="effector_frame" type="fixed">
    <origin xyz="-0.0183545 -0.0149864 0.0051956" rpy="2.42787 -0.361367 -1.27367"/>
    <parent link="4_supporthead"/>
    <child link="effector"/>
    <axis xyz="0 0 0"/>
  </joint>
  <!-- Frame closing_m1_p2_2 (dummy link + fixed joint) -->
  <link name="closing_m1_p2_2">
    <origin xyz="0 0 0" rpy="0 -0 0"/>
    <inertial>
      <origin xyz="0 0 0" rpy="0 0 0"/>
      <mass value="1e-9"/>
      <inertia ixx="0" ixy="0" ixz="0" iyy="0" iyz="0" izz="0"/>
    </inertial>
  </link>
  <joint name="closing_m1_p2_2_frame" type="fixed">
    <origin xyz="-0.0279738 -5.82867e-16 0.0216684" rpy="-1.82348 -7.45088e-15 1.5708"/>
    <parent link="4_supporthead"/>
    <child link="closing_m1_p2_2"/>
    <axis xyz="0 0 0"/>
  </joint>
  <!-- Frame closing_m3_p2_2 (dummy link + fixed joint) -->
  <link name="closing_m3_p2_2">
    <origin xyz="0 0 0" rpy="0 -0 0"/>
    <inertial>
      <origin xyz="0 0 0" rpy="0 0 0"/>
      <mass value="1e-9"/>
      <inertia ixx="0" ixy="0" ixz="0" iyy="0" iyz="0" izz="0"/>
    </inertial>
  </link>
  <joint name="closing_m3_p2_2_frame" type="fixed">
    <origin xyz="-0.00559476 -0.0274086 0.0216684" rpy="1.95839 -0.848062 -0.49848"/>
    <parent link="4_supporthead"/>
    <child link="closing_m3_p2_2"/>
    <axis xyz="0 0 0"/>
  </joint>
  <!-- Joint from 3_lien2 to 4_supporthead -->
  <joint name="m2_p2" type="revolute">
    <origin xyz="0.0279738 2.2829e-15 -0.0497913" rpy="-3.36345e-14 -1.31812 6.54005e-15"/>
    <parent link="3_lien2"/>
    <child link="4_supporthead"/>
    <axis xyz="0 0 1"/>
    <limit effort="10" velocity="10" lower="-3.141592653589793" upper="3.141592653589793"/>
  </joint>
  <!-- Joint from 2_arbremoteur3 to 3_lien2 -->
  <joint name="m1_p1" type="revolute">
    <origin xyz="0.0260678 -0.0319264 -0.0619264" rpy="1.31313 0.19488 0.633732"/>
    <parent link="2_arbremoteur3"/>
    <child link="3_lien2"/>
    <axis xyz="0 0 1"/>
    <limit effort="10" velocity="10" lower="-3.141592653589793" upper="3.141592653589793"/>
  </joint>
  <!-- Joint from moteur_bati_v2 to 2_arbremoteur3 -->
  <joint name="m1" type="revolute">
    <origin xyz="-0.0513137 2.95076e-15 0.0612132" rpy="2.35619 -9.97813e-15 -1.5708"/>
    <parent link="moteur_bati_v2"/>
    <child link="2_arbremoteur3"/>
    <axis xyz="0 0 1"/>
    <limit effort="10" velocity="10" lower="-3.141592653589793" upper="3.141592653589793"/>
  </joint>
  <!-- Link 2_arbremoteur3_2 -->
  <link name="2_arbremoteur3_2">
    <inertial>
      <origin xyz="-0.0107909 0.00909413 -0.0175921" rpy="0 0 0"/>
      <mass value="0.0293635"/>
      <inertia ixx="1.73972e-05" ixy="4.85555e-06" ixz="-6.98022e-06" iyy="1.81718e-05" iyz="7.26176e-06" izz="1.24115e-05"/>
    </inertial>
    <!-- Part dbtm3_14_5_3 -->
    <visual>
      <origin xyz="-0.0307218 0.0376264 -0.0600264" rpy="-1.36944 0.25268 -0.886077"/>
      <geometry>
        <mesh filename="package://assets/dbtm3_14_5.stl"/>
      </geometry>
      <material name="dbtm3_14_5_3_material">
        <color rgba="0.690196 0.690196 0.690196 1.0"/>
      </material>
    </visual>
    <!-- Part 2_arbremoteur3_2 -->
    <visual>
      <origin xyz="-0.0115732 0.04 0.0184386" rpy="-1.5708 -9.02412e-15 3.14159"/>
      <geometry>
        <mesh filename="package://assets/2_arbremoteur3.stl"/>
      </geometry>
      <material name="2_arbremoteur3_2_material">
        <color rgba="0.615686 0.811765 0.929412 1.0"/>
      </material>
    </visual>
    <collision>
      <origin xyz="-0.0115732 0.04 0.0184386" rpy="-1.5708 -9.02412e-15 3.14159"/>
      <geometry>
        <mesh filename="package://assets/2_arbremoteur3.stl"/>
      </geometry>
    </collision>
    <!-- Part sfl676zz_7 -->
    <visual>
      <origin xyz="-0.0288847 0.0353764 -0.0607764" rpy="-1.77215 -0.25268 2.25552"/>
      <geometry>
        <mesh filename="package://assets/sfl676zz.stl"/>
      </geometry>
      <material name="sfl676zz_7_material">
        <color rgba="0.917647 0.917647 0.917647 1.0"/>
      </material>
    </visual>
  </link>
  <!-- Link 3_lien2_2 -->
  <link name="3_lien2_2">
    <inertial>
      <origin xyz="0.0153881 0.00162035 -0.0217923" rpy="0 0 0"/>
      <mass value="0.0118051"/>
      <inertia ixx="3.6573e-06" ixy="-1.03018e-07" ixz="1.62019e-06" iyy="4.83538e-06" iyz="-2.61509e-08" izz="1.52639e-06"/>
    </inertial>
    <!-- Part dbtm3_14_5_4 -->
    <visual>
      <origin xyz="0.0206151 1.70697e-15 -0.0478913" rpy="3.14159 0.25268 -1.37782e-14"/>
      <geometry>
        <mesh filename="package://assets/dbtm3_14_5.stl"/>
      </geometry>
      <material name="dbtm3_14_5_4_material">
        <color rgba="0.690196 0.690196 0.690196 1.0"/>
      </material>
    </visual>
    <!-- Part sfl676zz_8 -->
    <visual>
      <origin xyz="-6.93889e-18 0 -0.0046" rpy="-3.14159 1.5708 0"/>
      <geometry>
        <mesh filename="package://assets/sfl676zz.stl"/>
      </geometry>
      <material name="sfl676zz_8_material">
        <color rgba="0.917647 0.917647 0.917647 1.0"/>
      </material>
    </visual>
    <!-- Part sfl676zz_9 -->
    <visual>
      <origin xyz="0.0235199 1.66533e-15 -0.0486413" rpy="-2.78626e-15 -0.25268 3.14159"/>
      <geometry>
        <mesh filename="package://assets/sfl676zz.stl"/>
      </geometry>
      <material name="sfl676zz_9_material">
        <color rgba="0.917647 0.917647 0.917647 1.0"/>
      </material>
    </visual>
    <!-- Part 3_lien2_2 -->
    <visual>
      <origin xyz="-0.031712 0.0736879 0.0172703" rpy="-2.81984 -0.659058 -1.54845e-14"/>
      <geometry>
        <mesh filename="package://assets/3_lien2.stl"/>
      </geometry>
      <material name="3_lien2_2_material">
        <color rgba="0.647059 0.647059 0.647059 1.0"/>
      </material>
    </visual>
    <collision>
      <origin xyz="-0.031712 0.0736879 0.0172703" rpy="-2.81984 -0.659058 -1.54845e-14"/>
      <geometry>
        <mesh filename="package://assets/3_lien2.stl"/>
      </geometry>
    </collision>
    <!-- Part hex_thin_nut_grade_a___b_m3__1f32078b7141c356c1ef5a853a7893b2_5 -->
    <visual>
      <origin xyz="0 -6.93889e-18 -0.0085" rpy="3.14159 3.02103e-15 -3.1485e-14"/>
      <geometry>
        <mesh filename="package://assets/hex_thin_nut_grade_a___b_m3__1f32078b7141c356c1ef5a853a7893b2.stl"/>
      </geometry>
      <material name="hex_thin_nut_grade_a___b_m3__1f32078b7141c356c1ef5a853a7893b2_5_material">
        <color rgba="0.603922 0.647059 0.686275 1.0"/>
      </material>
    </visual>
  </link>
  <!-- Frame closing_m3_p2_1 (dummy link + fixed joint) -->
  <link name="closing_m3_p2_1">
    <origin xyz="0 0 0" rpy="0 -0 0"/>
    <inertial>
      <origin xyz="0 0 0" rpy="0 0 0"/>
      <mass value="1e-9"/>
      <inertia ixx="0" ixy="0" ixz="0" iyy="0" iyz="0" izz="0"/>
    </inertial>
  </link>
  <joint name="closing_m3_p2_1_frame" type="fixed">
    <origin xyz="0.0279738 1.6237e-15 -0.0497913" rpy="-3.14159 -1.31812 -1.81564e-14"/>
    <parent link="3_lien2_2"/>
    <child link="closing_m3_p2_1"/>
    <axis xyz="0 0 0"/>
  </joint>
  <!-- Joint from 2_arbremoteur3_2 to 3_lien2_2 -->
  <joint name="m2_p1" type="revolute">
    <origin xyz="-0.0260678 0.0319264 -0.0619264" rpy="1.31313 0.19488 -2.50786"/>
    <parent link="2_arbremoteur3_2"/>
    <child link="3_lien2_2"/>
    <axis xyz="0 0 1"/>
    <limit effort="10" velocity="10" lower="-3.141592653589793" upper="3.141592653589793"/>
  </joint>
  <!-- Joint from moteur_bati_v2 to 2_arbremoteur3_2 -->
  <joint name="m2" type="revolute">
    <origin xyz="0.0256569 -0.044439 0.0612132" rpy="-2.35619 1.99341e-16 -2.61799"/>
    <parent link="moteur_bati_v2"/>
    <child link="2_arbremoteur3_2"/>
    <axis xyz="0 0 1"/>
    <limit effort="10" velocity="10" lower="-3.141592653589793" upper="3.141592653589793"/>
  </joint>
  <!-- Link 2_arbremoteur3_3 -->
  <link name="2_arbremoteur3_3">
    <inertial>
      <origin xyz="-0.0107909 0.00909413 -0.0175921" rpy="0 0 0"/>
      <mass value="0.0293635"/>
      <inertia ixx="1.73972e-05" ixy="4.85555e-06" ixz="-6.98022e-06" iyy="1.81718e-05" iyz="7.26176e-06" izz="1.24115e-05"/>
    </inertial>
    <!-- Part dbtm3_14_5_5 -->
    <visual>
      <origin xyz="-0.0307218 0.0376264 -0.0600264" rpy="-1.36944 0.25268 -0.886077"/>
      <geometry>
        <mesh filename="package://assets/dbtm3_14_5.stl"/>
      </geometry>
      <material name="dbtm3_14_5_5_material">
        <color rgba="0.690196 0.690196 0.690196 1.0"/>
      </material>
    </visual>
    <!-- Part 2_arbremoteur3_3 -->
    <visual>
      <origin xyz="-0.0115732 0.04 0.0184386" rpy="-1.5708 -9.09611e-16 3.14159"/>
      <geometry>
        <mesh filename="package://assets/2_arbremoteur3.stl"/>
      </geometry>
      <material name="2_arbremoteur3_3_material">
        <color rgba="0.615686 0.811765 0.929412 1.0"/>
      </material>
    </visual>
    <collision>
      <origin xyz="-0.0115732 0.04 0.0184386" rpy="-1.5708 -9.09611e-16 3.14159"/>
      <geometry>
        <mesh filename="package://assets/2_arbremoteur3.stl"/>
      </geometry>
    </collision>
    <!-- Part sfl676zz_10 -->
    <visual>
      <origin xyz="-0.0288847 0.0353764 -0.0607764" rpy="-1.77215 -0.25268 2.25552"/>
      <geometry>
        <mesh filename="package://assets/sfl676zz.stl"/>
      </geometry>
      <material name="sfl676zz_10_material">
        <color rgba="0.917647 0.917647 0.917647 1.0"/>
      </material>
    </visual>
  </link>
  <!-- Link 3_lien2_3 -->
  <link name="3_lien2_3">
    <inertial>
      <origin xyz="0.0153881 0.00162035 -0.0217923" rpy="0 0 0"/>
      <mass value="0.0118051"/>
      <inertia ixx="3.6573e-06" ixy="-1.03018e-07" ixz="1.62019e-06" iyy="4.83538e-06" iyz="-2.61509e-08" izz="1.52639e-06"/>
    </inertial>
    <!-- Part dbtm3_14_5_6 -->
    <visual>
      <origin xyz="0.0206151 2.01922e-15 -0.0478913" rpy="-3.14159 0.25268 1.30264e-15"/>
      <geometry>
        <mesh filename="package://assets/dbtm3_14_5.stl"/>
      </geometry>
      <material name="dbtm3_14_5_6_material">
        <color rgba="0.690196 0.690196 0.690196 1.0"/>
      </material>
    </visual>
    <!-- Part sfl676zz_11 -->
    <visual>
      <origin xyz="1.38778e-17 -4.85723e-17 -0.0046" rpy="3.14159 1.5708 0"/>
      <geometry>
        <mesh filename="package://assets/sfl676zz.stl"/>
      </geometry>
      <material name="sfl676zz_11_material">
        <color rgba="0.917647 0.917647 0.917647 1.0"/>
      </material>
    </visual>
    <!-- Part sfl676zz_12 -->
    <visual>
      <origin xyz="0.0235199 2.01228e-15 -0.0486413" rpy="-1.22286e-15 -0.25268 -3.14159"/>
      <geometry>
        <mesh filename="package://assets/sfl676zz.stl"/>
      </geometry>
      <material name="sfl676zz_12_material">
        <color rgba="0.917647 0.917647 0.917647 1.0"/>
      </material>
    </visual>
    <!-- Part 3_lien2_3 -->
    <visual>
      <origin xyz="-0.031712 0.0736879 0.0172703" rpy="-2.81984 -0.659058 -3.26688e-17"/>
      <geometry>
        <mesh filename="package://assets/3_lien2.stl"/>
      </geometry>
      <material name="3_lien2_3_material">
        <color rgba="0.647059 0.647059 0.647059 1.0"/>
      </material>
    </visual>
    <collision>
      <origin xyz="-0.031712 0.0736879 0.0172703" rpy="-2.81984 -0.659058 -3.26688e-17"/>
      <geometry>
        <mesh filename="package://assets/3_lien2.stl"/>
      </geometry>
    </collision>
    <!-- Part hex_thin_nut_grade_a___b_m3__1f32078b7141c356c1ef5a853a7893b2_6 -->
    <visual>
      <origin xyz="0 6.93889e-18 -0.0085" rpy="3.14159 2.50939e-14 6.60272e-15"/>
      <geometry>
        <mesh filename="package://assets/hex_thin_nut_grade_a___b_m3__1f32078b7141c356c1ef5a853a7893b2.stl"/>
      </geometry>
      <material name="hex_thin_nut_grade_a___b_m3__1f32078b7141c356c1ef5a853a7893b2_6_material">
        <color rgba="0.603922 0.647059 0.686275 1.0"/>
      </material>
    </visual>
  </link>
  <!-- Frame closing_m1_p2_1 (dummy link + fixed joint) -->
  <link name="closing_m1_p2_1">
    <origin xyz="0 0 0" rpy="0 -0 0"/>
    <inertial>
      <origin xyz="0 0 0" rpy="0 0 0"/>
      <mass value="1e-9"/>
      <inertia ixx="0" ixy="0" ixz="0" iyy="0" iyz="0" izz="0"/>
    </inertial>
  </link>
  <joint name="closing_m1_p2_1_frame" type="fixed">
    <origin xyz="0.0279738 2.02616e-15 -0.0497913" rpy="-3.14159 -1.31812 -1.62357e-15"/>
    <parent link="3_lien2_3"/>
    <child link="closing_m1_p2_1"/>
    <axis xyz="0 0 0"/>
  </joint>
  <!-- Joint from 2_arbremoteur3_3 to 3_lien2_3 -->
  <joint name="m3_p1" type="revolute">
    <origin xyz="-0.0260678 0.0319264 -0.0619264" rpy="1.31313 0.19488 -2.50786"/>
    <parent link="2_arbremoteur3_3"/>
    <child link="3_lien2_3"/>
    <axis xyz="0 0 1"/>
    <limit effort="10" velocity="10" lower="-3.141592653589793" upper="3.141592653589793"/>
  </joint>
  <!-- Joint from moteur_bati_v2 to 2_arbremoteur3_3 -->
  <joint name="m3" type="revolute">
    <origin xyz="0.0256569 0.044439 0.0612132" rpy="-2.35619 3.18634e-14 -0.523599"/>
    <parent link="moteur_bati_v2"/>
    <child link="2_arbremoteur3_3"/>
    <axis xyz="0 0 1"/>
    <limit effort="10" velocity="10" lower="-3.141592653589793" upper="3.141592653589793"/>
  </joint>
</robot>
